WARNING:django.request:Not Found: /favicon.ico
DEBUG:root:user loged
WARNING:django.request:Not Found: /cart/cart_status/games/games/
WARNING:django.request:Not Found: /cart/cart_status/games/games/
WARNING:django.request:Not Found: /cart/cart_status/games/games/
DEBUG:root:user loged
ERROR:django.request:Internal Server Error: /cart/sale/
Traceback (most recent call last):
  File "/usr/local/lib/python3.6/site-packages/django/core/handlers/exception.py", line 41, in inner
    response = get_response(request)
  File "/usr/local/lib/python3.6/site-packages/django/core/handlers/base.py", line 187, in _get_response
    response = self.process_exception_by_middleware(e, request)
  File "/usr/local/lib/python3.6/site-packages/django/core/handlers/base.py", line 185, in _get_response
    response = wrapped_callback(request, *callback_args, **callback_kwargs)
  File "/Users/emirozbir/Desktop/test2/gamer_trnet/epin/epinmain/views.py", line 174, in sale_finish
    add_sale_to_the_sale_table(main_template,user_id)
  File "/Users/emirozbir/Desktop/test2/gamer_trnet/epin/epinmain/views.py", line 154, in add_sale_to_the_sale_table
    conn.commit()
psycopg2.IntegrityError: insert or update on table "epinmain_sale" violates foreign key constraint "epinmain_sale_user_id_e4e7df32_fk_epinmain_profile_id"
DETAIL:  Key (user_id)=(8) is not present in table "epinmain_profile".

ERROR:django.request:Internal Server Error: /cart/sale/
Traceback (most recent call last):
  File "/usr/local/lib/python3.6/site-packages/django/core/handlers/exception.py", line 41, in inner
    response = get_response(request)
  File "/usr/local/lib/python3.6/site-packages/django/core/handlers/base.py", line 187, in _get_response
    response = self.process_exception_by_middleware(e, request)
  File "/usr/local/lib/python3.6/site-packages/django/core/handlers/base.py", line 185, in _get_response
    response = wrapped_callback(request, *callback_args, **callback_kwargs)
  File "/Users/emirozbir/Desktop/test2/gamer_trnet/epin/epinmain/views.py", line 174, in sale_finish
    add_sale_to_the_sale_table(main_template,user_id)
  File "/Users/emirozbir/Desktop/test2/gamer_trnet/epin/epinmain/views.py", line 154, in add_sale_to_the_sale_table
    conn.commit()
psycopg2.IntegrityError: insert or update on table "epinmain_sale" violates foreign key constraint "epinmain_sale_user_id_e4e7df32_fk_epinmain_profile_id"
DETAIL:  Key (user_id)=(8) is not present in table "epinmain_profile".

ERROR:django.request:Internal Server Error: /cart/sale/
Traceback (most recent call last):
  File "/usr/local/lib/python3.6/site-packages/django/core/handlers/exception.py", line 41, in inner
    response = get_response(request)
  File "/usr/local/lib/python3.6/site-packages/django/core/handlers/base.py", line 187, in _get_response
    response = self.process_exception_by_middleware(e, request)
  File "/usr/local/lib/python3.6/site-packages/django/core/handlers/base.py", line 185, in _get_response
    response = wrapped_callback(request, *callback_args, **callback_kwargs)
  File "/Users/emirozbir/Desktop/test2/gamer_trnet/epin/epinmain/views.py", line 174, in sale_finish
    add_sale_to_the_sale_table(main_template,user_id)
  File "/Users/emirozbir/Desktop/test2/gamer_trnet/epin/epinmain/views.py", line 154, in add_sale_to_the_sale_table
    conn.commit()
psycopg2.IntegrityError: insert or update on table "epinmain_sale" violates foreign key constraint "epinmain_sale_user_id_e4e7df32_fk_epinmain_profile_id"
DETAIL:  Key (user_id)=(8) is not present in table "epinmain_profile".

ERROR:django.request:Internal Server Error: /cart/sale/
Traceback (most recent call last):
  File "/usr/local/lib/python3.6/site-packages/django/core/handlers/exception.py", line 41, in inner
    response = get_response(request)
  File "/usr/local/lib/python3.6/site-packages/django/core/handlers/base.py", line 187, in _get_response
    response = self.process_exception_by_middleware(e, request)
  File "/usr/local/lib/python3.6/site-packages/django/core/handlers/base.py", line 185, in _get_response
    response = wrapped_callback(request, *callback_args, **callback_kwargs)
  File "/Users/emirozbir/Desktop/test2/gamer_trnet/epin/epinmain/views.py", line 174, in sale_finish
    add_sale_to_the_sale_table(main_template,user_id)
  File "/Users/emirozbir/Desktop/test2/gamer_trnet/epin/epinmain/views.py", line 154, in add_sale_to_the_sale_table
    conn.commit()
psycopg2.IntegrityError: insert or update on table "epinmain_sale" violates foreign key constraint "epinmain_sale_user_id_e4e7df32_fk_epinmain_profile_id"
DETAIL:  Key (user_id)=(8) is not present in table "epinmain_profile".

WARNING:django.request:Not Found: /favicon.ico
WARNING:django.request:Not Found: /accounts/logout
WARNING:django.request:Not Found: /accounts/invalid/
WARNING:django.request:Not Found: /accounts/login
WARNING:django.request:Not Found: /accounts/login
DEBUG:django.db.backends:(0.003) 
            SELECT c.relname, c.relkind
            FROM pg_catalog.pg_class c
            LEFT JOIN pg_catalog.pg_namespace n ON n.oid = c.relnamespace
            WHERE c.relkind IN ('r', 'v')
                AND n.nspname NOT IN ('pg_catalog', 'pg_toast')
                AND pg_catalog.pg_table_is_visible(c.oid); args=None
DEBUG:django.db.backends:(0.000) SELECT "django_migrations"."app", "django_migrations"."name" FROM "django_migrations"; args=()
DEBUG:django.db.backends:(0.004) 
            SELECT c.relname, c.relkind
            FROM pg_catalog.pg_class c
            LEFT JOIN pg_catalog.pg_namespace n ON n.oid = c.relnamespace
            WHERE c.relkind IN ('r', 'v')
                AND n.nspname NOT IN ('pg_catalog', 'pg_toast')
                AND pg_catalog.pg_table_is_visible(c.oid); args=None
DEBUG:django.db.backends:(0.001) SELECT "django_migrations"."app", "django_migrations"."name" FROM "django_migrations"; args=()
DEBUG:django.template:Exception while resolving variable 'form' in template 'login.html'.
Traceback (most recent call last):
  File "/usr/local/lib/python3.6/site-packages/django/template/base.py", line 882, in _resolve_lookup
    current = current[bit]
  File "/usr/local/lib/python3.6/site-packages/django/template/context.py", line 87, in __getitem__
    raise KeyError(key)
KeyError: 'form'

During handling of the above exception, another exception occurred:

Traceback (most recent call last):
  File "/usr/local/lib/python3.6/site-packages/django/template/base.py", line 888, in _resolve_lookup
    if isinstance(current, BaseContext) and getattr(type(current), bit):
AttributeError: type object 'Context' has no attribute 'form'

During handling of the above exception, another exception occurred:

Traceback (most recent call last):
  File "/usr/local/lib/python3.6/site-packages/django/template/base.py", line 896, in _resolve_lookup
    current = current[int(bit)]
ValueError: invalid literal for int() with base 10: 'form'

During handling of the above exception, another exception occurred:

Traceback (most recent call last):
  File "/usr/local/lib/python3.6/site-packages/django/template/base.py", line 903, in _resolve_lookup
    (bit, current))  # missing attribute
django.template.base.VariableDoesNotExist: Failed lookup for key [form] in "[{'True': True, 'False': False, 'None': None}, {'csrf_token': <SimpleLazyObject: <function csrf.<locals>._get_val at 0x1058c4950>>}]"
INFO:django.server:"GET /accounts/login/ HTTP/1.1" 200 419
DEBUG:django.db.backends:(0.004) 
            SELECT c.relname, c.relkind
            FROM pg_catalog.pg_class c
            LEFT JOIN pg_catalog.pg_namespace n ON n.oid = c.relnamespace
            WHERE c.relkind IN ('r', 'v')
                AND n.nspname NOT IN ('pg_catalog', 'pg_toast')
                AND pg_catalog.pg_table_is_visible(c.oid); args=None
DEBUG:django.db.backends:(0.001) SELECT "django_migrations"."app", "django_migrations"."name" FROM "django_migrations"; args=()
ERROR:django.request:Internal Server Error: /accounts/login/
Traceback (most recent call last):
  File "/usr/local/lib/python3.6/site-packages/django/core/handlers/exception.py", line 41, in inner
    response = get_response(request)
  File "/usr/local/lib/python3.6/site-packages/django/core/handlers/base.py", line 187, in _get_response
    response = self.process_exception_by_middleware(e, request)
  File "/usr/local/lib/python3.6/site-packages/django/core/handlers/base.py", line 185, in _get_response
    response = wrapped_callback(request, *callback_args, **callback_kwargs)
  File "/Users/emirozbir/Desktop/gamer_trnet/epin/epinmain/views.py", line 96, in login
    return render('games.html', c)
  File "/usr/local/lib/python3.6/site-packages/django/shortcuts.py", line 30, in render
    content = loader.render_to_string(template_name, context, request, using=using)
  File "/usr/local/lib/python3.6/site-packages/django/template/loader.py", line 67, in render_to_string
    template = get_template(template_name, using=using)
  File "/usr/local/lib/python3.6/site-packages/django/template/loader.py", line 25, in get_template
    raise TemplateDoesNotExist(template_name, chain=chain)
django.template.exceptions.TemplateDoesNotExist: {'csrf_token': <SimpleLazyObject: <function csrf.<locals>._get_val at 0x1087709d8>>}
ERROR:django.request:Internal Server Error: /games/games/
Traceback (most recent call last):
  File "/usr/local/lib/python3.6/site-packages/django/core/handlers/exception.py", line 41, in inner
    response = get_response(request)
  File "/usr/local/lib/python3.6/site-packages/django/core/handlers/base.py", line 187, in _get_response
    response = self.process_exception_by_middleware(e, request)
  File "/usr/local/lib/python3.6/site-packages/django/core/handlers/base.py", line 185, in _get_response
    response = wrapped_callback(request, *callback_args, **callback_kwargs)
  File "/Users/emirozbir/Desktop/gamer_trnet/epin/epinmain/views.py", line 80, in games
    my_keys = request.session['game']
  File "/usr/local/lib/python3.6/site-packages/django/contrib/sessions/backends/base.py", line 57, in __getitem__
    return self._session[key]
KeyError: 'game'
ERROR:django.request:Internal Server Error: /games/games/
Traceback (most recent call last):
  File "/usr/local/lib/python3.6/site-packages/django/core/handlers/exception.py", line 41, in inner
    response = get_response(request)
  File "/usr/local/lib/python3.6/site-packages/django/core/handlers/base.py", line 187, in _get_response
    response = self.process_exception_by_middleware(e, request)
  File "/usr/local/lib/python3.6/site-packages/django/core/handlers/base.py", line 185, in _get_response
    response = wrapped_callback(request, *callback_args, **callback_kwargs)
  File "/Users/emirozbir/Desktop/gamer_trnet/epin/epinmain/views.py", line 80, in games
    my_keys = request.session['game']
  File "/usr/local/lib/python3.6/site-packages/django/contrib/sessions/backends/base.py", line 57, in __getitem__
    return self._session[key]
KeyError: 'game'
ERROR:django.request:Internal Server Error: /games/games/
Traceback (most recent call last):
  File "/usr/local/lib/python3.6/site-packages/django/core/handlers/exception.py", line 41, in inner
    response = get_response(request)
  File "/usr/local/lib/python3.6/site-packages/django/core/handlers/base.py", line 187, in _get_response
    response = self.process_exception_by_middleware(e, request)
  File "/usr/local/lib/python3.6/site-packages/django/core/handlers/base.py", line 185, in _get_response
    response = wrapped_callback(request, *callback_args, **callback_kwargs)
  File "/Users/emirozbir/Desktop/gamer_trnet/epin/epinmain/views.py", line 80, in games
    my_keys = request.session['game']
  File "/usr/local/lib/python3.6/site-packages/django/contrib/sessions/backends/base.py", line 57, in __getitem__
    return self._session[key]
KeyError: 'game'
DEBUG:root:user loged
ERROR:epinmain.views:Something went wrong!
INFO:epinmain.views:hello
WARNING:django.request:Not Found: /cart/cart_status/games/games/
DEBUG:root:user loged
INFO:epinmain.views:CART CREATED by test1 Tue Jun 20 14:00:07 2017
WARNING:django.request:Not Found: /cart/cart_status/games/games/
INFO:epinmain.views:CART CREATED by test1 Tue Jun 20 14:04:11 2017
WARNING:django.request:Not Found: /cart/cart_status/games/games/
ERROR:django.request:Internal Server Error: /accounts/login/
Traceback (most recent call last):
  File "/usr/local/lib/python3.6/site-packages/django/core/handlers/exception.py", line 41, in inner
    response = get_response(request)
  File "/usr/local/lib/python3.6/site-packages/django/core/handlers/base.py", line 187, in _get_response
    response = self.process_exception_by_middleware(e, request)
  File "/usr/local/lib/python3.6/site-packages/django/core/handlers/base.py", line 185, in _get_response
    response = wrapped_callback(request, *callback_args, **callback_kwargs)
  File "/Users/emirozbir/Desktop/gamer_trnet/epin/epinmain/views.py", line 100, in login
    return render('games.html', c)
  File "/usr/local/lib/python3.6/site-packages/django/shortcuts.py", line 30, in render
    content = loader.render_to_string(template_name, context, request, using=using)
  File "/usr/local/lib/python3.6/site-packages/django/template/loader.py", line 67, in render_to_string
    template = get_template(template_name, using=using)
  File "/usr/local/lib/python3.6/site-packages/django/template/loader.py", line 25, in get_template
    raise TemplateDoesNotExist(template_name, chain=chain)
django.template.exceptions.TemplateDoesNotExist: {'csrf_token': <SimpleLazyObject: <function csrf.<locals>._get_val at 0x10c5ac950>>}
ERROR:django.request:Internal Server Error: /accounts/login/
Traceback (most recent call last):
  File "/usr/local/lib/python3.6/site-packages/django/core/handlers/exception.py", line 41, in inner
    response = get_response(request)
  File "/usr/local/lib/python3.6/site-packages/django/core/handlers/base.py", line 187, in _get_response
    response = self.process_exception_by_middleware(e, request)
  File "/usr/local/lib/python3.6/site-packages/django/core/handlers/base.py", line 185, in _get_response
    response = wrapped_callback(request, *callback_args, **callback_kwargs)
  File "/Users/emirozbir/Desktop/gamer_trnet/epin/epinmain/views.py", line 100, in login
    return render('games.html', c)
  File "/usr/local/lib/python3.6/site-packages/django/shortcuts.py", line 30, in render
    content = loader.render_to_string(template_name, context, request, using=using)
  File "/usr/local/lib/python3.6/site-packages/django/template/loader.py", line 67, in render_to_string
    template = get_template(template_name, using=using)
  File "/usr/local/lib/python3.6/site-packages/django/template/loader.py", line 25, in get_template
    raise TemplateDoesNotExist(template_name, chain=chain)
django.template.exceptions.TemplateDoesNotExist: {'csrf_token': <SimpleLazyObject: <function csrf.<locals>._get_val at 0x10d000c80>>}
ERROR:django.request:Internal Server Error: /accounts/login/
Traceback (most recent call last):
  File "/usr/local/lib/python3.6/site-packages/django/core/handlers/exception.py", line 41, in inner
    response = get_response(request)
  File "/usr/local/lib/python3.6/site-packages/django/core/handlers/base.py", line 187, in _get_response
    response = self.process_exception_by_middleware(e, request)
  File "/usr/local/lib/python3.6/site-packages/django/core/handlers/base.py", line 185, in _get_response
    response = wrapped_callback(request, *callback_args, **callback_kwargs)
  File "/Users/emirozbir/Desktop/gamer_trnet/epin/epinmain/views.py", line 100, in login
    return render('games.html', c)
  File "/usr/local/lib/python3.6/site-packages/django/shortcuts.py", line 30, in render
    content = loader.render_to_string(template_name, context, request, using=using)
  File "/usr/local/lib/python3.6/site-packages/django/template/loader.py", line 67, in render_to_string
    template = get_template(template_name, using=using)
  File "/usr/local/lib/python3.6/site-packages/django/template/loader.py", line 25, in get_template
    raise TemplateDoesNotExist(template_name, chain=chain)
django.template.exceptions.TemplateDoesNotExist: {'csrf_token': <SimpleLazyObject: <function csrf.<locals>._get_val at 0x10d000ae8>>}
WARNING:django.request:Not Found: /accounts/login
ERROR:django.request:Internal Server Error: /accounts/login/
Traceback (most recent call last):
  File "/usr/local/lib/python3.6/site-packages/django/core/handlers/exception.py", line 41, in inner
    response = get_response(request)
  File "/usr/local/lib/python3.6/site-packages/django/core/handlers/base.py", line 187, in _get_response
    response = self.process_exception_by_middleware(e, request)
  File "/usr/local/lib/python3.6/site-packages/django/core/handlers/base.py", line 185, in _get_response
    response = wrapped_callback(request, *callback_args, **callback_kwargs)
  File "/Users/emirozbir/Desktop/gamer_trnet/epin/epinmain/views.py", line 105, in login
    return render('login.html',c)##look to the source code.
  File "/usr/local/lib/python3.6/site-packages/django/shortcuts.py", line 30, in render
    content = loader.render_to_string(template_name, context, request, using=using)
  File "/usr/local/lib/python3.6/site-packages/django/template/loader.py", line 67, in render_to_string
    template = get_template(template_name, using=using)
  File "/usr/local/lib/python3.6/site-packages/django/template/loader.py", line 25, in get_template
    raise TemplateDoesNotExist(template_name, chain=chain)
django.template.exceptions.TemplateDoesNotExist: {'csrf_token': <SimpleLazyObject: <function csrf.<locals>._get_val at 0x10d000d90>>}
ERROR:django.request:Internal Server Error: /accounts/login/
Traceback (most recent call last):
  File "/usr/local/lib/python3.6/site-packages/django/core/handlers/exception.py", line 41, in inner
    response = get_response(request)
  File "/usr/local/lib/python3.6/site-packages/django/core/handlers/base.py", line 187, in _get_response
    response = self.process_exception_by_middleware(e, request)
  File "/usr/local/lib/python3.6/site-packages/django/core/handlers/base.py", line 185, in _get_response
    response = wrapped_callback(request, *callback_args, **callback_kwargs)
  File "/Users/emirozbir/Desktop/gamer_trnet/epin/epinmain/views.py", line 104, in login
    return render('login.html',c)##look to the source code.
  File "/usr/local/lib/python3.6/site-packages/django/shortcuts.py", line 30, in render
    content = loader.render_to_string(template_name, context, request, using=using)
  File "/usr/local/lib/python3.6/site-packages/django/template/loader.py", line 67, in render_to_string
    template = get_template(template_name, using=using)
  File "/usr/local/lib/python3.6/site-packages/django/template/loader.py", line 25, in get_template
    raise TemplateDoesNotExist(template_name, chain=chain)
django.template.exceptions.TemplateDoesNotExist: {'csrf_token': <SimpleLazyObject: <function csrf.<locals>._get_val at 0x103be51e0>>}
ERROR:django.request:Internal Server Error: /accounts/login/
Traceback (most recent call last):
  File "/usr/local/lib/python3.6/site-packages/django/core/handlers/exception.py", line 41, in inner
    response = get_response(request)
  File "/usr/local/lib/python3.6/site-packages/django/core/handlers/base.py", line 187, in _get_response
    response = self.process_exception_by_middleware(e, request)
  File "/usr/local/lib/python3.6/site-packages/django/core/handlers/base.py", line 185, in _get_response
    response = wrapped_callback(request, *callback_args, **callback_kwargs)
  File "/Users/emirozbir/Desktop/gamer_trnet/epin/epinmain/views.py", line 105, in login
    return render('login.html',c)##look to the source code.
  File "/usr/local/lib/python3.6/site-packages/django/shortcuts.py", line 30, in render
    content = loader.render_to_string(template_name, context, request, using=using)
  File "/usr/local/lib/python3.6/site-packages/django/template/loader.py", line 67, in render_to_string
    template = get_template(template_name, using=using)
  File "/usr/local/lib/python3.6/site-packages/django/template/loader.py", line 25, in get_template
    raise TemplateDoesNotExist(template_name, chain=chain)
django.template.exceptions.TemplateDoesNotExist: {'csrf_token': <SimpleLazyObject: <function csrf.<locals>._get_val at 0x10a707950>>}
ERROR:django.request:Internal Server Error: /accounts/login/
Traceback (most recent call last):
  File "/usr/local/lib/python3.6/site-packages/django/core/handlers/exception.py", line 41, in inner
    response = get_response(request)
  File "/usr/local/lib/python3.6/site-packages/django/core/handlers/base.py", line 187, in _get_response
    response = self.process_exception_by_middleware(e, request)
  File "/usr/local/lib/python3.6/site-packages/django/core/handlers/base.py", line 185, in _get_response
    response = wrapped_callback(request, *callback_args, **callback_kwargs)
  File "/Users/emirozbir/Desktop/gamer_trnet/epin/epinmain/views.py", line 105, in login
    return render('login.html',c)##look to the source code.
  File "/usr/local/lib/python3.6/site-packages/django/shortcuts.py", line 30, in render
    content = loader.render_to_string(template_name, context, request, using=using)
  File "/usr/local/lib/python3.6/site-packages/django/template/loader.py", line 67, in render_to_string
    template = get_template(template_name, using=using)
  File "/usr/local/lib/python3.6/site-packages/django/template/loader.py", line 25, in get_template
    raise TemplateDoesNotExist(template_name, chain=chain)
django.template.exceptions.TemplateDoesNotExist: {'csrf_token': <SimpleLazyObject: <function csrf.<locals>._get_val at 0x10b15ab70>>}
DEBUG:root:CANNOT LOGGED  : 
ERROR:django.request:Internal Server Error: /accounts/login/
Traceback (most recent call last):
  File "/usr/local/lib/python3.6/site-packages/django/core/handlers/exception.py", line 41, in inner
    response = get_response(request)
  File "/usr/local/lib/python3.6/site-packages/django/core/handlers/base.py", line 187, in _get_response
    response = self.process_exception_by_middleware(e, request)
  File "/usr/local/lib/python3.6/site-packages/django/core/handlers/base.py", line 185, in _get_response
    response = wrapped_callback(request, *callback_args, **callback_kwargs)
  File "/Users/emirozbir/Desktop/gamer_trnet/epin/epinmain/views.py", line 105, in login
    return render('login.html',c)##look to the source code.
  File "/usr/local/lib/python3.6/site-packages/django/shortcuts.py", line 30, in render
    content = loader.render_to_string(template_name, context, request, using=using)
  File "/usr/local/lib/python3.6/site-packages/django/template/loader.py", line 67, in render_to_string
    template = get_template(template_name, using=using)
  File "/usr/local/lib/python3.6/site-packages/django/template/loader.py", line 25, in get_template
    raise TemplateDoesNotExist(template_name, chain=chain)
django.template.exceptions.TemplateDoesNotExist: {'csrf_token': <SimpleLazyObject: <function csrf.<locals>._get_val at 0x1109a4158>>}
ERROR:django.request:Internal Server Error: /accounts/login/
Traceback (most recent call last):
  File "/usr/local/lib/python3.6/site-packages/django/core/handlers/exception.py", line 41, in inner
    response = get_response(request)
  File "/usr/local/lib/python3.6/site-packages/django/core/handlers/base.py", line 187, in _get_response
    response = self.process_exception_by_middleware(e, request)
  File "/usr/local/lib/python3.6/site-packages/django/core/handlers/base.py", line 185, in _get_response
    response = wrapped_callback(request, *callback_args, **callback_kwargs)
  File "/Users/emirozbir/Desktop/gamer_trnet/epin/epinmain/views.py", line 105, in login
    return render('login.html',c)##look to the source code.
  File "/usr/local/lib/python3.6/site-packages/django/shortcuts.py", line 30, in render
    content = loader.render_to_string(template_name, context, request, using=using)
  File "/usr/local/lib/python3.6/site-packages/django/template/loader.py", line 67, in render_to_string
    template = get_template(template_name, using=using)
  File "/usr/local/lib/python3.6/site-packages/django/template/loader.py", line 25, in get_template
    raise TemplateDoesNotExist(template_name, chain=chain)
django.template.exceptions.TemplateDoesNotExist: {'csrf_token': <SimpleLazyObject: <function csrf.<locals>._get_val at 0x111448a60>>}
ERROR:django.request:Internal Server Error: /accounts/login/
Traceback (most recent call last):
  File "/usr/local/lib/python3.6/site-packages/django/core/handlers/exception.py", line 41, in inner
    response = get_response(request)
  File "/usr/local/lib/python3.6/site-packages/django/core/handlers/base.py", line 187, in _get_response
    response = self.process_exception_by_middleware(e, request)
  File "/usr/local/lib/python3.6/site-packages/django/core/handlers/base.py", line 185, in _get_response
    response = wrapped_callback(request, *callback_args, **callback_kwargs)
  File "/Users/emirozbir/Desktop/gamer_trnet/epin/epinmain/views.py", line 105, in login
    return render('login.html')##look to the source code.
TypeError: render() missing 1 required positional argument: 'template_name'
ERROR:django.request:Internal Server Error: /accounts/login/
Traceback (most recent call last):
  File "/usr/local/lib/python3.6/site-packages/django/core/handlers/exception.py", line 41, in inner
    response = get_response(request)
  File "/usr/local/lib/python3.6/site-packages/django/core/handlers/base.py", line 187, in _get_response
    response = self.process_exception_by_middleware(e, request)
  File "/usr/local/lib/python3.6/site-packages/django/core/handlers/base.py", line 185, in _get_response
    response = wrapped_callback(request, *callback_args, **callback_kwargs)
  File "/Users/emirozbir/Desktop/gamer_trnet/epin/epinmain/views.py", line 105, in login
    return render('login.html')##look to the source code.
TypeError: render() missing 1 required positional argument: 'template_name'
ERROR:django.request:Internal Server Error: /accounts/login/
Traceback (most recent call last):
  File "/usr/local/lib/python3.6/site-packages/django/core/handlers/exception.py", line 41, in inner
    response = get_response(request)
  File "/usr/local/lib/python3.6/site-packages/django/core/handlers/base.py", line 187, in _get_response
    response = self.process_exception_by_middleware(e, request)
  File "/usr/local/lib/python3.6/site-packages/django/core/handlers/base.py", line 185, in _get_response
    response = wrapped_callback(request, *callback_args, **callback_kwargs)
  File "/Users/emirozbir/Desktop/gamer_trnet/epin/epinmain/views.py", line 105, in login
    return render('login.html',c)##look to the source code.
  File "/usr/local/lib/python3.6/site-packages/django/shortcuts.py", line 30, in render
    content = loader.render_to_string(template_name, context, request, using=using)
  File "/usr/local/lib/python3.6/site-packages/django/template/loader.py", line 67, in render_to_string
    template = get_template(template_name, using=using)
  File "/usr/local/lib/python3.6/site-packages/django/template/loader.py", line 25, in get_template
    raise TemplateDoesNotExist(template_name, chain=chain)
django.template.exceptions.TemplateDoesNotExist: {'csrf_token': <SimpleLazyObject: <function csrf.<locals>._get_val at 0x103bb5950>>}
ERROR:django.request:Internal Server Error: /accounts/login/
Traceback (most recent call last):
  File "/usr/local/lib/python3.6/site-packages/django/core/handlers/exception.py", line 41, in inner
    response = get_response(request)
  File "/usr/local/lib/python3.6/site-packages/django/core/handlers/base.py", line 187, in _get_response
    response = self.process_exception_by_middleware(e, request)
  File "/usr/local/lib/python3.6/site-packages/django/core/handlers/base.py", line 185, in _get_response
    response = wrapped_callback(request, *callback_args, **callback_kwargs)
  File "/Users/emirozbir/Desktop/gamer_trnet/epin/epinmain/views.py", line 105, in login
    return render('login.html',c)##look to the source code.
  File "/usr/local/lib/python3.6/site-packages/django/shortcuts.py", line 30, in render
    content = loader.render_to_string(template_name, context, request, using=using)
  File "/usr/local/lib/python3.6/site-packages/django/template/loader.py", line 67, in render_to_string
    template = get_template(template_name, using=using)
  File "/usr/local/lib/python3.6/site-packages/django/template/loader.py", line 25, in get_template
    raise TemplateDoesNotExist(template_name, chain=chain)
django.template.exceptions.TemplateDoesNotExist: {'csrf_token': <SimpleLazyObject: <function csrf.<locals>._get_val at 0x104615b70>>}
ERROR:django.request:Internal Server Error: /accounts/login/
Traceback (most recent call last):
  File "/usr/local/lib/python3.6/site-packages/django/core/handlers/exception.py", line 41, in inner
    response = get_response(request)
  File "/usr/local/lib/python3.6/site-packages/django/core/handlers/base.py", line 187, in _get_response
    response = self.process_exception_by_middleware(e, request)
  File "/usr/local/lib/python3.6/site-packages/django/core/handlers/base.py", line 185, in _get_response
    response = wrapped_callback(request, *callback_args, **callback_kwargs)
  File "/Users/emirozbir/Desktop/gamer_trnet/epin/epinmain/views.py", line 105, in login
    return render('login.html',c)##look to the source code.
  File "/usr/local/lib/python3.6/site-packages/django/shortcuts.py", line 30, in render
    content = loader.render_to_string(template_name, context, request, using=using)
  File "/usr/local/lib/python3.6/site-packages/django/template/loader.py", line 67, in render_to_string
    template = get_template(template_name, using=using)
  File "/usr/local/lib/python3.6/site-packages/django/template/loader.py", line 25, in get_template
    raise TemplateDoesNotExist(template_name, chain=chain)
django.template.exceptions.TemplateDoesNotExist: {'csrf_token': <SimpleLazyObject: <function csrf.<locals>._get_val at 0x1046159d8>>}
ERROR:django.request:Internal Server Error: /accounts/login/
Traceback (most recent call last):
  File "/usr/local/lib/python3.6/site-packages/django/core/handlers/exception.py", line 41, in inner
    response = get_response(request)
  File "/usr/local/lib/python3.6/site-packages/django/core/handlers/base.py", line 187, in _get_response
    response = self.process_exception_by_middleware(e, request)
  File "/usr/local/lib/python3.6/site-packages/django/core/handlers/base.py", line 185, in _get_response
    response = wrapped_callback(request, *callback_args, **callback_kwargs)
  File "/Users/emirozbir/Desktop/gamer_trnet/epin/epinmain/views.py", line 105, in login
    return render('login.html',c)##look to the source code.
  File "/usr/local/lib/python3.6/site-packages/django/shortcuts.py", line 30, in render
    content = loader.render_to_string(template_name, context, request, using=using)
  File "/usr/local/lib/python3.6/site-packages/django/template/loader.py", line 67, in render_to_string
    template = get_template(template_name, using=using)
  File "/usr/local/lib/python3.6/site-packages/django/template/loader.py", line 25, in get_template
    raise TemplateDoesNotExist(template_name, chain=chain)
django.template.exceptions.TemplateDoesNotExist: {'csrf_token': <SimpleLazyObject: <function csrf.<locals>._get_val at 0x104615c80>>}
ERROR:django.request:Internal Server Error: /accounts/login/
Traceback (most recent call last):
  File "/usr/local/lib/python3.6/site-packages/django/core/handlers/exception.py", line 41, in inner
    response = get_response(request)
  File "/usr/local/lib/python3.6/site-packages/django/core/handlers/base.py", line 187, in _get_response
    response = self.process_exception_by_middleware(e, request)
  File "/usr/local/lib/python3.6/site-packages/django/core/handlers/base.py", line 185, in _get_response
    response = wrapped_callback(request, *callback_args, **callback_kwargs)
  File "/Users/emirozbir/Desktop/gamer_trnet/epin/epinmain/views.py", line 105, in login
    return render('login.html',c)##look to the source code.
  File "/usr/local/lib/python3.6/site-packages/django/shortcuts.py", line 30, in render
    content = loader.render_to_string(template_name, context, request, using=using)
  File "/usr/local/lib/python3.6/site-packages/django/template/loader.py", line 67, in render_to_string
    template = get_template(template_name, using=using)
  File "/usr/local/lib/python3.6/site-packages/django/template/loader.py", line 25, in get_template
    raise TemplateDoesNotExist(template_name, chain=chain)
django.template.exceptions.TemplateDoesNotExist: {'csrf_token': <SimpleLazyObject: <function csrf.<locals>._get_val at 0x104615d90>>}
ERROR:django.request:Internal Server Error: /accounts/login/
Traceback (most recent call last):
  File "/usr/local/lib/python3.6/site-packages/django/core/handlers/exception.py", line 41, in inner
    response = get_response(request)
  File "/usr/local/lib/python3.6/site-packages/django/core/handlers/base.py", line 187, in _get_response
    response = self.process_exception_by_middleware(e, request)
  File "/usr/local/lib/python3.6/site-packages/django/core/handlers/base.py", line 185, in _get_response
    response = wrapped_callback(request, *callback_args, **callback_kwargs)
  File "/Users/emirozbir/Desktop/gamer_trnet/epin/epinmain/views.py", line 105, in login
    return render('login.html',c)##look to the source code.
  File "/usr/local/lib/python3.6/site-packages/django/shortcuts.py", line 30, in render
    content = loader.render_to_string(template_name, context, request, using=using)
  File "/usr/local/lib/python3.6/site-packages/django/template/loader.py", line 67, in render_to_string
    template = get_template(template_name, using=using)
  File "/usr/local/lib/python3.6/site-packages/django/template/loader.py", line 25, in get_template
    raise TemplateDoesNotExist(template_name, chain=chain)
django.template.exceptions.TemplateDoesNotExist: {'csrf_token': <SimpleLazyObject: <function csrf.<locals>._get_val at 0x104615bf8>>}
ERROR:django.request:Internal Server Error: /accounts/login/
Traceback (most recent call last):
  File "/usr/local/lib/python3.6/site-packages/django/core/handlers/exception.py", line 41, in inner
    response = get_response(request)
  File "/usr/local/lib/python3.6/site-packages/django/core/handlers/base.py", line 187, in _get_response
    response = self.process_exception_by_middleware(e, request)
  File "/usr/local/lib/python3.6/site-packages/django/core/handlers/base.py", line 185, in _get_response
    response = wrapped_callback(request, *callback_args, **callback_kwargs)
  File "/Users/emirozbir/Desktop/gamer_trnet/epin/epinmain/views.py", line 105, in login
    return render('login.html',c)##look to the source code.
  File "/usr/local/lib/python3.6/site-packages/django/shortcuts.py", line 30, in render
    content = loader.render_to_string(template_name, context, request, using=using)
  File "/usr/local/lib/python3.6/site-packages/django/template/loader.py", line 67, in render_to_string
    template = get_template(template_name, using=using)
  File "/usr/local/lib/python3.6/site-packages/django/template/loader.py", line 25, in get_template
    raise TemplateDoesNotExist(template_name, chain=chain)
django.template.exceptions.TemplateDoesNotExist: {'csrf_token': <SimpleLazyObject: <function csrf.<locals>._get_val at 0x104615d08>>}
ERROR:django.request:Internal Server Error: /accounts/login/
Traceback (most recent call last):
  File "/usr/local/lib/python3.6/site-packages/django/core/handlers/exception.py", line 41, in inner
    response = get_response(request)
  File "/usr/local/lib/python3.6/site-packages/django/core/handlers/base.py", line 187, in _get_response
    response = self.process_exception_by_middleware(e, request)
  File "/usr/local/lib/python3.6/site-packages/django/core/handlers/base.py", line 185, in _get_response
    response = wrapped_callback(request, *callback_args, **callback_kwargs)
  File "/Users/emirozbir/Desktop/gamer_trnet/epin/epinmain/views.py", line 105, in login
    return render('login.html',c)##look to the source code.
  File "/usr/local/lib/python3.6/site-packages/django/shortcuts.py", line 30, in render
    content = loader.render_to_string(template_name, context, request, using=using)
  File "/usr/local/lib/python3.6/site-packages/django/template/loader.py", line 67, in render_to_string
    template = get_template(template_name, using=using)
  File "/usr/local/lib/python3.6/site-packages/django/template/loader.py", line 25, in get_template
    raise TemplateDoesNotExist(template_name, chain=chain)
django.template.exceptions.TemplateDoesNotExist: {'csrf_token': <SimpleLazyObject: <function csrf.<locals>._get_val at 0x104615ea0>>}
ERROR:django.request:Internal Server Error: /accounts/login/
Traceback (most recent call last):
  File "/usr/local/lib/python3.6/site-packages/django/core/handlers/exception.py", line 41, in inner
    response = get_response(request)
  File "/usr/local/lib/python3.6/site-packages/django/core/handlers/base.py", line 187, in _get_response
    response = self.process_exception_by_middleware(e, request)
  File "/usr/local/lib/python3.6/site-packages/django/core/handlers/base.py", line 185, in _get_response
    response = wrapped_callback(request, *callback_args, **callback_kwargs)
  File "/Users/emirozbir/Desktop/gamer_trnet/epin/epinmain/views.py", line 105, in login
    return render('login.html',c)##look to the source code.
  File "/usr/local/lib/python3.6/site-packages/django/shortcuts.py", line 30, in render
    content = loader.render_to_string(template_name, context, request, using=using)
  File "/usr/local/lib/python3.6/site-packages/django/template/loader.py", line 67, in render_to_string
    template = get_template(template_name, using=using)
  File "/usr/local/lib/python3.6/site-packages/django/template/loader.py", line 25, in get_template
    raise TemplateDoesNotExist(template_name, chain=chain)
django.template.exceptions.TemplateDoesNotExist: {'csrf_token': <SimpleLazyObject: <function csrf.<locals>._get_val at 0x1046159d8>>}
ERROR:django.request:Internal Server Error: /accounts/login/
Traceback (most recent call last):
  File "/usr/local/lib/python3.6/site-packages/django/core/handlers/exception.py", line 41, in inner
    response = get_response(request)
  File "/usr/local/lib/python3.6/site-packages/django/core/handlers/base.py", line 187, in _get_response
    response = self.process_exception_by_middleware(e, request)
  File "/usr/local/lib/python3.6/site-packages/django/core/handlers/base.py", line 185, in _get_response
    response = wrapped_callback(request, *callback_args, **callback_kwargs)
  File "/Users/emirozbir/Desktop/gamer_trnet/epin/epinmain/views.py", line 105, in login
    return render('login.html',c)##look to the source code.
  File "/usr/local/lib/python3.6/site-packages/django/shortcuts.py", line 30, in render
    content = loader.render_to_string(template_name, context, request, using=using)
  File "/usr/local/lib/python3.6/site-packages/django/template/loader.py", line 67, in render_to_string
    template = get_template(template_name, using=using)
  File "/usr/local/lib/python3.6/site-packages/django/template/loader.py", line 25, in get_template
    raise TemplateDoesNotExist(template_name, chain=chain)
django.template.exceptions.TemplateDoesNotExist: {'csrf_token': <SimpleLazyObject: <function csrf.<locals>._get_val at 0x104615e18>>}
ERROR:django.request:Internal Server Error: /accounts/login/
Traceback (most recent call last):
  File "/usr/local/lib/python3.6/site-packages/django/core/handlers/exception.py", line 41, in inner
    response = get_response(request)
  File "/usr/local/lib/python3.6/site-packages/django/core/handlers/base.py", line 187, in _get_response
    response = self.process_exception_by_middleware(e, request)
  File "/usr/local/lib/python3.6/site-packages/django/core/handlers/base.py", line 185, in _get_response
    response = wrapped_callback(request, *callback_args, **callback_kwargs)
  File "/Users/emirozbir/Desktop/gamer_trnet/epin/epinmain/views.py", line 105, in login
    return render('login.html',c)##look to the source code.
  File "/usr/local/lib/python3.6/site-packages/django/shortcuts.py", line 30, in render
    content = loader.render_to_string(template_name, context, request, using=using)
  File "/usr/local/lib/python3.6/site-packages/django/template/loader.py", line 67, in render_to_string
    template = get_template(template_name, using=using)
  File "/usr/local/lib/python3.6/site-packages/django/template/loader.py", line 25, in get_template
    raise TemplateDoesNotExist(template_name, chain=chain)
django.template.exceptions.TemplateDoesNotExist: {'csrf_token': <SimpleLazyObject: <function csrf.<locals>._get_val at 0x104615f28>>}
ERROR:django.request:Internal Server Error: /accounts/login/
Traceback (most recent call last):
  File "/usr/local/lib/python3.6/site-packages/django/core/handlers/exception.py", line 41, in inner
    response = get_response(request)
  File "/usr/local/lib/python3.6/site-packages/django/core/handlers/base.py", line 187, in _get_response
    response = self.process_exception_by_middleware(e, request)
  File "/usr/local/lib/python3.6/site-packages/django/core/handlers/base.py", line 185, in _get_response
    response = wrapped_callback(request, *callback_args, **callback_kwargs)
  File "/Users/emirozbir/Desktop/gamer_trnet/epin/epinmain/views.py", line 105, in login
    return render('login.html',c)##look to the source code.
  File "/usr/local/lib/python3.6/site-packages/django/shortcuts.py", line 30, in render
    content = loader.render_to_string(template_name, context, request, using=using)
  File "/usr/local/lib/python3.6/site-packages/django/template/loader.py", line 67, in render_to_string
    template = get_template(template_name, using=using)
  File "/usr/local/lib/python3.6/site-packages/django/template/loader.py", line 25, in get_template
    raise TemplateDoesNotExist(template_name, chain=chain)
django.template.exceptions.TemplateDoesNotExist: {'csrf_token': <SimpleLazyObject: <function csrf.<locals>._get_val at 0x1046159d8>>}
ERROR:django.request:Internal Server Error: /accounts/login/
Traceback (most recent call last):
  File "/usr/local/lib/python3.6/site-packages/django/core/handlers/exception.py", line 41, in inner
    response = get_response(request)
  File "/usr/local/lib/python3.6/site-packages/django/core/handlers/base.py", line 187, in _get_response
    response = self.process_exception_by_middleware(e, request)
  File "/usr/local/lib/python3.6/site-packages/django/core/handlers/base.py", line 185, in _get_response
    response = wrapped_callback(request, *callback_args, **callback_kwargs)
  File "/Users/emirozbir/Desktop/gamer_trnet/epin/epinmain/views.py", line 105, in login
    return render('login.html',c)##look to the source code.
  File "/usr/local/lib/python3.6/site-packages/django/shortcuts.py", line 30, in render
    content = loader.render_to_string(template_name, context, request, using=using)
  File "/usr/local/lib/python3.6/site-packages/django/template/loader.py", line 67, in render_to_string
    template = get_template(template_name, using=using)
  File "/usr/local/lib/python3.6/site-packages/django/template/loader.py", line 25, in get_template
    raise TemplateDoesNotExist(template_name, chain=chain)
django.template.exceptions.TemplateDoesNotExist: {'csrf_token': <SimpleLazyObject: <function csrf.<locals>._get_val at 0x104615e18>>}
ERROR:django.request:Internal Server Error: /accounts/login/
Traceback (most recent call last):
  File "/usr/local/lib/python3.6/site-packages/django/core/handlers/exception.py", line 41, in inner
    response = get_response(request)
  File "/usr/local/lib/python3.6/site-packages/django/core/handlers/base.py", line 187, in _get_response
    response = self.process_exception_by_middleware(e, request)
  File "/usr/local/lib/python3.6/site-packages/django/core/handlers/base.py", line 185, in _get_response
    response = wrapped_callback(request, *callback_args, **callback_kwargs)
  File "/Users/emirozbir/Desktop/gamer_trnet/epin/epinmain/views.py", line 105, in login
    return render('login.html',c)##look to the source code.
  File "/usr/local/lib/python3.6/site-packages/django/shortcuts.py", line 30, in render
    content = loader.render_to_string(template_name, context, request, using=using)
  File "/usr/local/lib/python3.6/site-packages/django/template/loader.py", line 67, in render_to_string
    template = get_template(template_name, using=using)
  File "/usr/local/lib/python3.6/site-packages/django/template/loader.py", line 25, in get_template
    raise TemplateDoesNotExist(template_name, chain=chain)
django.template.exceptions.TemplateDoesNotExist: {'csrf_token': <SimpleLazyObject: <function csrf.<locals>._get_val at 0x1046a2048>>}
ERROR:django.request:Internal Server Error: /accounts/login/
Traceback (most recent call last):
  File "/usr/local/lib/python3.6/site-packages/django/core/handlers/exception.py", line 41, in inner
    response = get_response(request)
  File "/usr/local/lib/python3.6/site-packages/django/core/handlers/base.py", line 187, in _get_response
    response = self.process_exception_by_middleware(e, request)
  File "/usr/local/lib/python3.6/site-packages/django/core/handlers/base.py", line 185, in _get_response
    response = wrapped_callback(request, *callback_args, **callback_kwargs)
  File "/Users/emirozbir/Desktop/gamer_trnet/epin/epinmain/views.py", line 105, in login
    return render('login.html',c)##look to the source code.
  File "/usr/local/lib/python3.6/site-packages/django/shortcuts.py", line 30, in render
    content = loader.render_to_string(template_name, context, request, using=using)
  File "/usr/local/lib/python3.6/site-packages/django/template/loader.py", line 67, in render_to_string
    template = get_template(template_name, using=using)
  File "/usr/local/lib/python3.6/site-packages/django/template/loader.py", line 25, in get_template
    raise TemplateDoesNotExist(template_name, chain=chain)
django.template.exceptions.TemplateDoesNotExist: {'csrf_token': <SimpleLazyObject: <function csrf.<locals>._get_val at 0x1046159d8>>}
ERROR:django.request:Internal Server Error: /accounts/login/
Traceback (most recent call last):
  File "/usr/local/lib/python3.6/site-packages/django/core/handlers/exception.py", line 41, in inner
    response = get_response(request)
  File "/usr/local/lib/python3.6/site-packages/django/core/handlers/base.py", line 187, in _get_response
    response = self.process_exception_by_middleware(e, request)
  File "/usr/local/lib/python3.6/site-packages/django/core/handlers/base.py", line 185, in _get_response
    response = wrapped_callback(request, *callback_args, **callback_kwargs)
  File "/Users/emirozbir/Desktop/gamer_trnet/epin/epinmain/views.py", line 105, in login
    return render('login.html',c)##look to the source code.
  File "/usr/local/lib/python3.6/site-packages/django/shortcuts.py", line 30, in render
    content = loader.render_to_string(template_name, context, request, using=using)
  File "/usr/local/lib/python3.6/site-packages/django/template/loader.py", line 67, in render_to_string
    template = get_template(template_name, using=using)
  File "/usr/local/lib/python3.6/site-packages/django/template/loader.py", line 25, in get_template
    raise TemplateDoesNotExist(template_name, chain=chain)
django.template.exceptions.TemplateDoesNotExist: {'csrf_token': <SimpleLazyObject: <function csrf.<locals>._get_val at 0x104615e18>>}
ERROR:django.request:Internal Server Error: /accounts/login/
Traceback (most recent call last):
  File "/usr/local/lib/python3.6/site-packages/django/core/handlers/exception.py", line 41, in inner
    response = get_response(request)
  File "/usr/local/lib/python3.6/site-packages/django/core/handlers/base.py", line 187, in _get_response
    response = self.process_exception_by_middleware(e, request)
  File "/usr/local/lib/python3.6/site-packages/django/core/handlers/base.py", line 185, in _get_response
    response = wrapped_callback(request, *callback_args, **callback_kwargs)
  File "/Users/emirozbir/Desktop/gamer_trnet/epin/epinmain/views.py", line 105, in login
    return render('login.html',c)##look to the source code.
  File "/usr/local/lib/python3.6/site-packages/django/shortcuts.py", line 30, in render
    content = loader.render_to_string(template_name, context, request, using=using)
  File "/usr/local/lib/python3.6/site-packages/django/template/loader.py", line 67, in render_to_string
    template = get_template(template_name, using=using)
  File "/usr/local/lib/python3.6/site-packages/django/template/loader.py", line 25, in get_template
    raise TemplateDoesNotExist(template_name, chain=chain)
django.template.exceptions.TemplateDoesNotExist: {'csrf_token': <SimpleLazyObject: <function csrf.<locals>._get_val at 0x1046a2840>>}
ERROR:django.request:Internal Server Error: /accounts/login/
Traceback (most recent call last):
  File "/usr/local/lib/python3.6/site-packages/django/core/handlers/exception.py", line 41, in inner
    response = get_response(request)
  File "/usr/local/lib/python3.6/site-packages/django/core/handlers/base.py", line 187, in _get_response
    response = self.process_exception_by_middleware(e, request)
  File "/usr/local/lib/python3.6/site-packages/django/core/handlers/base.py", line 185, in _get_response
    response = wrapped_callback(request, *callback_args, **callback_kwargs)
  File "/Users/emirozbir/Desktop/gamer_trnet/epin/epinmain/views.py", line 105, in login
    return render('login.html',c)##look to the source code.
  File "/usr/local/lib/python3.6/site-packages/django/shortcuts.py", line 30, in render
    content = loader.render_to_string(template_name, context, request, using=using)
  File "/usr/local/lib/python3.6/site-packages/django/template/loader.py", line 67, in render_to_string
    template = get_template(template_name, using=using)
  File "/usr/local/lib/python3.6/site-packages/django/template/loader.py", line 25, in get_template
    raise TemplateDoesNotExist(template_name, chain=chain)
django.template.exceptions.TemplateDoesNotExist: {'csrf_token': <SimpleLazyObject: <function csrf.<locals>._get_val at 0x104615e18>>}
ERROR:django.request:Internal Server Error: /accounts/login/
Traceback (most recent call last):
  File "/usr/local/lib/python3.6/site-packages/django/core/handlers/exception.py", line 41, in inner
    response = get_response(request)
  File "/usr/local/lib/python3.6/site-packages/django/core/handlers/base.py", line 187, in _get_response
    response = self.process_exception_by_middleware(e, request)
  File "/usr/local/lib/python3.6/site-packages/django/core/handlers/base.py", line 185, in _get_response
    response = wrapped_callback(request, *callback_args, **callback_kwargs)
  File "/Users/emirozbir/Desktop/gamer_trnet/epin/epinmain/views.py", line 105, in login
    return render('login.html',c)##look to the source code.
  File "/usr/local/lib/python3.6/site-packages/django/shortcuts.py", line 30, in render
    content = loader.render_to_string(template_name, context, request, using=using)
  File "/usr/local/lib/python3.6/site-packages/django/template/loader.py", line 67, in render_to_string
    template = get_template(template_name, using=using)
  File "/usr/local/lib/python3.6/site-packages/django/template/loader.py", line 25, in get_template
    raise TemplateDoesNotExist(template_name, chain=chain)
django.template.exceptions.TemplateDoesNotExist: {'csrf_token': <SimpleLazyObject: <function csrf.<locals>._get_val at 0x1046a27b8>>}
ERROR:django.request:Internal Server Error: /accounts/login/
Traceback (most recent call last):
  File "/usr/local/lib/python3.6/site-packages/django/core/handlers/exception.py", line 41, in inner
    response = get_response(request)
  File "/usr/local/lib/python3.6/site-packages/django/core/handlers/base.py", line 187, in _get_response
    response = self.process_exception_by_middleware(e, request)
  File "/usr/local/lib/python3.6/site-packages/django/core/handlers/base.py", line 185, in _get_response
    response = wrapped_callback(request, *callback_args, **callback_kwargs)
  File "/Users/emirozbir/Desktop/gamer_trnet/epin/epinmain/views.py", line 105, in login
    return render('login.html',c)##look to the source code.
  File "/usr/local/lib/python3.6/site-packages/django/shortcuts.py", line 30, in render
    content = loader.render_to_string(template_name, context, request, using=using)
  File "/usr/local/lib/python3.6/site-packages/django/template/loader.py", line 67, in render_to_string
    template = get_template(template_name, using=using)
  File "/usr/local/lib/python3.6/site-packages/django/template/loader.py", line 25, in get_template
    raise TemplateDoesNotExist(template_name, chain=chain)
django.template.exceptions.TemplateDoesNotExist: {'csrf_token': <SimpleLazyObject: <function csrf.<locals>._get_val at 0x1046a2950>>}
ERROR:django.request:Internal Server Error: /accounts/login/
Traceback (most recent call last):
  File "/usr/local/lib/python3.6/site-packages/django/core/handlers/exception.py", line 41, in inner
    response = get_response(request)
  File "/usr/local/lib/python3.6/site-packages/django/core/handlers/base.py", line 187, in _get_response
    response = self.process_exception_by_middleware(e, request)
  File "/usr/local/lib/python3.6/site-packages/django/core/handlers/base.py", line 185, in _get_response
    response = wrapped_callback(request, *callback_args, **callback_kwargs)
  File "/Users/emirozbir/Desktop/gamer_trnet/epin/epinmain/views.py", line 105, in login
    return render('login.html',c)##look to the source code.
  File "/usr/local/lib/python3.6/site-packages/django/shortcuts.py", line 30, in render
    content = loader.render_to_string(template_name, context, request, using=using)
  File "/usr/local/lib/python3.6/site-packages/django/template/loader.py", line 67, in render_to_string
    template = get_template(template_name, using=using)
  File "/usr/local/lib/python3.6/site-packages/django/template/loader.py", line 25, in get_template
    raise TemplateDoesNotExist(template_name, chain=chain)
django.template.exceptions.TemplateDoesNotExist: {'csrf_token': <SimpleLazyObject: <function csrf.<locals>._get_val at 0x104615e18>>}
ERROR:django.request:Internal Server Error: /accounts/login/
Traceback (most recent call last):
  File "/usr/local/lib/python3.6/site-packages/django/core/handlers/exception.py", line 41, in inner
    response = get_response(request)
  File "/usr/local/lib/python3.6/site-packages/django/core/handlers/base.py", line 187, in _get_response
    response = self.process_exception_by_middleware(e, request)
  File "/usr/local/lib/python3.6/site-packages/django/core/handlers/base.py", line 185, in _get_response
    response = wrapped_callback(request, *callback_args, **callback_kwargs)
  File "/Users/emirozbir/Desktop/gamer_trnet/epin/epinmain/views.py", line 105, in login
    return render('login.html',c)##look to the source code.
  File "/usr/local/lib/python3.6/site-packages/django/shortcuts.py", line 30, in render
    content = loader.render_to_string(template_name, context, request, using=using)
  File "/usr/local/lib/python3.6/site-packages/django/template/loader.py", line 67, in render_to_string
    template = get_template(template_name, using=using)
  File "/usr/local/lib/python3.6/site-packages/django/template/loader.py", line 25, in get_template
    raise TemplateDoesNotExist(template_name, chain=chain)
django.template.exceptions.TemplateDoesNotExist: {'csrf_token': <SimpleLazyObject: <function csrf.<locals>._get_val at 0x1046a22f0>>}
ERROR:django.request:Internal Server Error: /accounts/login/
Traceback (most recent call last):
  File "/usr/local/lib/python3.6/site-packages/django/core/handlers/exception.py", line 41, in inner
    response = get_response(request)
  File "/usr/local/lib/python3.6/site-packages/django/core/handlers/base.py", line 187, in _get_response
    response = self.process_exception_by_middleware(e, request)
  File "/usr/local/lib/python3.6/site-packages/django/core/handlers/base.py", line 185, in _get_response
    response = wrapped_callback(request, *callback_args, **callback_kwargs)
  File "/Users/emirozbir/Desktop/gamer_trnet/epin/epinmain/views.py", line 105, in login
    return render('login.html',c)##look to the source code.
  File "/usr/local/lib/python3.6/site-packages/django/shortcuts.py", line 30, in render
    content = loader.render_to_string(template_name, context, request, using=using)
  File "/usr/local/lib/python3.6/site-packages/django/template/loader.py", line 67, in render_to_string
    template = get_template(template_name, using=using)
  File "/usr/local/lib/python3.6/site-packages/django/template/loader.py", line 25, in get_template
    raise TemplateDoesNotExist(template_name, chain=chain)
django.template.exceptions.TemplateDoesNotExist: {'csrf_token': <SimpleLazyObject: <function csrf.<locals>._get_val at 0x1046a2a60>>}
ERROR:django.request:Internal Server Error: /accounts/login/
Traceback (most recent call last):
  File "/usr/local/lib/python3.6/site-packages/django/core/handlers/exception.py", line 41, in inner
    response = get_response(request)
  File "/usr/local/lib/python3.6/site-packages/django/core/handlers/base.py", line 187, in _get_response
    response = self.process_exception_by_middleware(e, request)
  File "/usr/local/lib/python3.6/site-packages/django/core/handlers/base.py", line 185, in _get_response
    response = wrapped_callback(request, *callback_args, **callback_kwargs)
  File "/Users/emirozbir/Desktop/gamer_trnet/epin/epinmain/views.py", line 105, in login
    return render('login.html',c)##look to the source code.
  File "/usr/local/lib/python3.6/site-packages/django/shortcuts.py", line 30, in render
    content = loader.render_to_string(template_name, context, request, using=using)
  File "/usr/local/lib/python3.6/site-packages/django/template/loader.py", line 67, in render_to_string
    template = get_template(template_name, using=using)
  File "/usr/local/lib/python3.6/site-packages/django/template/loader.py", line 25, in get_template
    raise TemplateDoesNotExist(template_name, chain=chain)
django.template.exceptions.TemplateDoesNotExist: {'csrf_token': <SimpleLazyObject: <function csrf.<locals>._get_val at 0x104615e18>>}
ERROR:django.request:Internal Server Error: /accounts/login/
Traceback (most recent call last):
  File "/usr/local/lib/python3.6/site-packages/django/core/handlers/exception.py", line 41, in inner
    response = get_response(request)
  File "/usr/local/lib/python3.6/site-packages/django/core/handlers/base.py", line 187, in _get_response
    response = self.process_exception_by_middleware(e, request)
  File "/usr/local/lib/python3.6/site-packages/django/core/handlers/base.py", line 185, in _get_response
    response = wrapped_callback(request, *callback_args, **callback_kwargs)
  File "/Users/emirozbir/Desktop/gamer_trnet/epin/epinmain/views.py", line 105, in login
    return render('login.html',c)##look to the source code.
  File "/usr/local/lib/python3.6/site-packages/django/shortcuts.py", line 30, in render
    content = loader.render_to_string(template_name, context, request, using=using)
  File "/usr/local/lib/python3.6/site-packages/django/template/loader.py", line 67, in render_to_string
    template = get_template(template_name, using=using)
  File "/usr/local/lib/python3.6/site-packages/django/template/loader.py", line 25, in get_template
    raise TemplateDoesNotExist(template_name, chain=chain)
django.template.exceptions.TemplateDoesNotExist: {'csrf_token': <SimpleLazyObject: <function csrf.<locals>._get_val at 0x1046a20d0>>}
ERROR:django.request:Internal Server Error: /accounts/login/
Traceback (most recent call last):
  File "/usr/local/lib/python3.6/site-packages/django/core/handlers/exception.py", line 41, in inner
    response = get_response(request)
  File "/usr/local/lib/python3.6/site-packages/django/core/handlers/base.py", line 187, in _get_response
    response = self.process_exception_by_middleware(e, request)
  File "/usr/local/lib/python3.6/site-packages/django/core/handlers/base.py", line 185, in _get_response
    response = wrapped_callback(request, *callback_args, **callback_kwargs)
  File "/Users/emirozbir/Desktop/gamer_trnet/epin/epinmain/views.py", line 105, in login
    return render('login.html',c)##look to the source code.
  File "/usr/local/lib/python3.6/site-packages/django/shortcuts.py", line 30, in render
    content = loader.render_to_string(template_name, context, request, using=using)
  File "/usr/local/lib/python3.6/site-packages/django/template/loader.py", line 67, in render_to_string
    template = get_template(template_name, using=using)
  File "/usr/local/lib/python3.6/site-packages/django/template/loader.py", line 25, in get_template
    raise TemplateDoesNotExist(template_name, chain=chain)
django.template.exceptions.TemplateDoesNotExist: {'csrf_token': <SimpleLazyObject: <function csrf.<locals>._get_val at 0x1046a2b70>>}
ERROR:django.request:Internal Server Error: /accounts/login/
Traceback (most recent call last):
  File "/usr/local/lib/python3.6/site-packages/django/core/handlers/exception.py", line 41, in inner
    response = get_response(request)
  File "/usr/local/lib/python3.6/site-packages/django/core/handlers/base.py", line 187, in _get_response
    response = self.process_exception_by_middleware(e, request)
  File "/usr/local/lib/python3.6/site-packages/django/core/handlers/base.py", line 185, in _get_response
    response = wrapped_callback(request, *callback_args, **callback_kwargs)
  File "/Users/emirozbir/Desktop/gamer_trnet/epin/epinmain/views.py", line 105, in login
    return render('login.html',c)##look to the source code.
  File "/usr/local/lib/python3.6/site-packages/django/shortcuts.py", line 30, in render
    content = loader.render_to_string(template_name, context, request, using=using)
  File "/usr/local/lib/python3.6/site-packages/django/template/loader.py", line 67, in render_to_string
    template = get_template(template_name, using=using)
  File "/usr/local/lib/python3.6/site-packages/django/template/loader.py", line 25, in get_template
    raise TemplateDoesNotExist(template_name, chain=chain)
django.template.exceptions.TemplateDoesNotExist: {'csrf_token': <SimpleLazyObject: <function csrf.<locals>._get_val at 0x103bb5c80>>}
ERROR:django.request:Internal Server Error: /accounts/login/
Traceback (most recent call last):
  File "/usr/local/lib/python3.6/site-packages/django/core/handlers/exception.py", line 41, in inner
    response = get_response(request)
  File "/usr/local/lib/python3.6/site-packages/django/core/handlers/base.py", line 187, in _get_response
    response = self.process_exception_by_middleware(e, request)
  File "/usr/local/lib/python3.6/site-packages/django/core/handlers/base.py", line 185, in _get_response
    response = wrapped_callback(request, *callback_args, **callback_kwargs)
  File "/Users/emirozbir/Desktop/gamer_trnet/epin/epinmain/views.py", line 105, in login
    return render('login.html',c)##look to the source code.
  File "/usr/local/lib/python3.6/site-packages/django/shortcuts.py", line 30, in render
    content = loader.render_to_string(template_name, context, request, using=using)
  File "/usr/local/lib/python3.6/site-packages/django/template/loader.py", line 67, in render_to_string
    template = get_template(template_name, using=using)
  File "/usr/local/lib/python3.6/site-packages/django/template/loader.py", line 25, in get_template
    raise TemplateDoesNotExist(template_name, chain=chain)
django.template.exceptions.TemplateDoesNotExist: {'csrf_token': <SimpleLazyObject: <function csrf.<locals>._get_val at 0x103bb5a60>>}
ERROR:django.request:Internal Server Error: /accounts/login/
Traceback (most recent call last):
  File "/usr/local/lib/python3.6/site-packages/django/core/handlers/exception.py", line 41, in inner
    response = get_response(request)
  File "/usr/local/lib/python3.6/site-packages/django/core/handlers/base.py", line 187, in _get_response
    response = self.process_exception_by_middleware(e, request)
  File "/usr/local/lib/python3.6/site-packages/django/core/handlers/base.py", line 185, in _get_response
    response = wrapped_callback(request, *callback_args, **callback_kwargs)
  File "/Users/emirozbir/Desktop/gamer_trnet/epin/epinmain/views.py", line 105, in login
    return render('login.html',c)##look to the source code.
  File "/usr/local/lib/python3.6/site-packages/django/shortcuts.py", line 30, in render
    content = loader.render_to_string(template_name, context, request, using=using)
  File "/usr/local/lib/python3.6/site-packages/django/template/loader.py", line 67, in render_to_string
    template = get_template(template_name, using=using)
  File "/usr/local/lib/python3.6/site-packages/django/template/loader.py", line 25, in get_template
    raise TemplateDoesNotExist(template_name, chain=chain)
django.template.exceptions.TemplateDoesNotExist: {'csrf_token': <SimpleLazyObject: <function csrf.<locals>._get_val at 0x104615ae8>>}
ERROR:django.request:Internal Server Error: /accounts/login/
Traceback (most recent call last):
  File "/usr/local/lib/python3.6/site-packages/django/core/handlers/exception.py", line 41, in inner
    response = get_response(request)
  File "/usr/local/lib/python3.6/site-packages/django/core/handlers/base.py", line 187, in _get_response
    response = self.process_exception_by_middleware(e, request)
  File "/usr/local/lib/python3.6/site-packages/django/core/handlers/base.py", line 185, in _get_response
    response = wrapped_callback(request, *callback_args, **callback_kwargs)
  File "/Users/emirozbir/Desktop/gamer_trnet/epin/epinmain/views.py", line 105, in login
    return render('login.html',c)##look to the source code.
  File "/usr/local/lib/python3.6/site-packages/django/shortcuts.py", line 30, in render
    content = loader.render_to_string(template_name, context, request, using=using)
  File "/usr/local/lib/python3.6/site-packages/django/template/loader.py", line 67, in render_to_string
    template = get_template(template_name, using=using)
  File "/usr/local/lib/python3.6/site-packages/django/template/loader.py", line 25, in get_template
    raise TemplateDoesNotExist(template_name, chain=chain)
django.template.exceptions.TemplateDoesNotExist: {'csrf_token': <SimpleLazyObject: <function csrf.<locals>._get_val at 0x103bb5c80>>}
ERROR:django.request:Internal Server Error: /accounts/login/
Traceback (most recent call last):
  File "/usr/local/lib/python3.6/site-packages/django/core/handlers/exception.py", line 41, in inner
    response = get_response(request)
  File "/usr/local/lib/python3.6/site-packages/django/core/handlers/base.py", line 187, in _get_response
    response = self.process_exception_by_middleware(e, request)
  File "/usr/local/lib/python3.6/site-packages/django/core/handlers/base.py", line 185, in _get_response
    response = wrapped_callback(request, *callback_args, **callback_kwargs)
  File "/Users/emirozbir/Desktop/gamer_trnet/epin/epinmain/views.py", line 105, in login
    return render('login.html',c)##look to the source code.
  File "/usr/local/lib/python3.6/site-packages/django/shortcuts.py", line 30, in render
    content = loader.render_to_string(template_name, context, request, using=using)
  File "/usr/local/lib/python3.6/site-packages/django/template/loader.py", line 67, in render_to_string
    template = get_template(template_name, using=using)
  File "/usr/local/lib/python3.6/site-packages/django/template/loader.py", line 25, in get_template
    raise TemplateDoesNotExist(template_name, chain=chain)
django.template.exceptions.TemplateDoesNotExist: {'csrf_token': <SimpleLazyObject: <function csrf.<locals>._get_val at 0x103bb5a60>>}
ERROR:django.request:Internal Server Error: /accounts/login/
Traceback (most recent call last):
  File "/usr/local/lib/python3.6/site-packages/django/core/handlers/exception.py", line 41, in inner
    response = get_response(request)
  File "/usr/local/lib/python3.6/site-packages/django/core/handlers/base.py", line 187, in _get_response
    response = self.process_exception_by_middleware(e, request)
  File "/usr/local/lib/python3.6/site-packages/django/core/handlers/base.py", line 185, in _get_response
    response = wrapped_callback(request, *callback_args, **callback_kwargs)
  File "/Users/emirozbir/Desktop/gamer_trnet/epin/epinmain/views.py", line 105, in login
    return render('login.html',c)##look to the source code.
  File "/usr/local/lib/python3.6/site-packages/django/shortcuts.py", line 30, in render
    content = loader.render_to_string(template_name, context, request, using=using)
  File "/usr/local/lib/python3.6/site-packages/django/template/loader.py", line 67, in render_to_string
    template = get_template(template_name, using=using)
  File "/usr/local/lib/python3.6/site-packages/django/template/loader.py", line 25, in get_template
    raise TemplateDoesNotExist(template_name, chain=chain)
django.template.exceptions.TemplateDoesNotExist: {'csrf_token': <SimpleLazyObject: <function csrf.<locals>._get_val at 0x104615f28>>}
ERROR:django.request:Internal Server Error: /accounts/login/
Traceback (most recent call last):
  File "/usr/local/lib/python3.6/site-packages/django/core/handlers/exception.py", line 41, in inner
    response = get_response(request)
  File "/usr/local/lib/python3.6/site-packages/django/core/handlers/base.py", line 187, in _get_response
    response = self.process_exception_by_middleware(e, request)
  File "/usr/local/lib/python3.6/site-packages/django/core/handlers/base.py", line 185, in _get_response
    response = wrapped_callback(request, *callback_args, **callback_kwargs)
  File "/Users/emirozbir/Desktop/gamer_trnet/epin/epinmain/views.py", line 105, in login
    return render('login.html',c)##look to the source code.
  File "/usr/local/lib/python3.6/site-packages/django/shortcuts.py", line 30, in render
    content = loader.render_to_string(template_name, context, request, using=using)
  File "/usr/local/lib/python3.6/site-packages/django/template/loader.py", line 67, in render_to_string
    template = get_template(template_name, using=using)
  File "/usr/local/lib/python3.6/site-packages/django/template/loader.py", line 25, in get_template
    raise TemplateDoesNotExist(template_name, chain=chain)
django.template.exceptions.TemplateDoesNotExist: {'csrf_token': <SimpleLazyObject: <function csrf.<locals>._get_val at 0x103bb5a60>>}
ERROR:django.request:Internal Server Error: /accounts/login/
Traceback (most recent call last):
  File "/usr/local/lib/python3.6/site-packages/django/core/handlers/exception.py", line 41, in inner
    response = get_response(request)
  File "/usr/local/lib/python3.6/site-packages/django/core/handlers/base.py", line 187, in _get_response
    response = self.process_exception_by_middleware(e, request)
  File "/usr/local/lib/python3.6/site-packages/django/core/handlers/base.py", line 185, in _get_response
    response = wrapped_callback(request, *callback_args, **callback_kwargs)
  File "/Users/emirozbir/Desktop/gamer_trnet/epin/epinmain/views.py", line 104, in login
    return render('login.html',c)##look to the source code.
  File "/usr/local/lib/python3.6/site-packages/django/shortcuts.py", line 30, in render
    content = loader.render_to_string(template_name, context, request, using=using)
  File "/usr/local/lib/python3.6/site-packages/django/template/loader.py", line 67, in render_to_string
    template = get_template(template_name, using=using)
  File "/usr/local/lib/python3.6/site-packages/django/template/loader.py", line 25, in get_template
    raise TemplateDoesNotExist(template_name, chain=chain)
django.template.exceptions.TemplateDoesNotExist: {'csrf_token': <SimpleLazyObject: <function csrf.<locals>._get_val at 0x10def89d8>>}
ERROR:django.request:Internal Server Error: /accounts/login/
Traceback (most recent call last):
  File "/usr/local/lib/python3.6/site-packages/django/core/handlers/exception.py", line 41, in inner
    response = get_response(request)
  File "/usr/local/lib/python3.6/site-packages/django/core/handlers/base.py", line 187, in _get_response
    response = self.process_exception_by_middleware(e, request)
  File "/usr/local/lib/python3.6/site-packages/django/core/handlers/base.py", line 185, in _get_response
    response = wrapped_callback(request, *callback_args, **callback_kwargs)
  File "/Users/emirozbir/Desktop/gamer_trnet/epin/epinmain/views.py", line 104, in login
    return render('login.html',c)##look to the source code.
  File "/usr/local/lib/python3.6/site-packages/django/shortcuts.py", line 30, in render
    content = loader.render_to_string(template_name, context, request, using=using)
  File "/usr/local/lib/python3.6/site-packages/django/template/loader.py", line 67, in render_to_string
    template = get_template(template_name, using=using)
  File "/usr/local/lib/python3.6/site-packages/django/template/loader.py", line 25, in get_template
    raise TemplateDoesNotExist(template_name, chain=chain)
django.template.exceptions.TemplateDoesNotExist: {'csrf_token': <SimpleLazyObject: <function csrf.<locals>._get_val at 0x10e4599d8>>}
ERROR:django.request:Internal Server Error: /accounts/login/
Traceback (most recent call last):
  File "/usr/local/lib/python3.6/site-packages/django/core/handlers/exception.py", line 41, in inner
    response = get_response(request)
  File "/usr/local/lib/python3.6/site-packages/django/core/handlers/base.py", line 187, in _get_response
    response = self.process_exception_by_middleware(e, request)
  File "/usr/local/lib/python3.6/site-packages/django/core/handlers/base.py", line 185, in _get_response
    response = wrapped_callback(request, *callback_args, **callback_kwargs)
  File "/Users/emirozbir/Desktop/gamer_trnet/epin/epinmain/views.py", line 104, in login
    return render('login.html',c)##look to the source code.
  File "/usr/local/lib/python3.6/site-packages/django/shortcuts.py", line 30, in render
    content = loader.render_to_string(template_name, context, request, using=using)
  File "/usr/local/lib/python3.6/site-packages/django/template/loader.py", line 67, in render_to_string
    template = get_template(template_name, using=using)
  File "/usr/local/lib/python3.6/site-packages/django/template/loader.py", line 25, in get_template
    raise TemplateDoesNotExist(template_name, chain=chain)
django.template.exceptions.TemplateDoesNotExist: {'csrf_token': <SimpleLazyObject: <function csrf.<locals>._get_val at 0x1072210d0>>}
ERROR:django.request:Internal Server Error: /accounts/login/
Traceback (most recent call last):
  File "/usr/local/lib/python3.6/site-packages/django/core/handlers/exception.py", line 41, in inner
    response = get_response(request)
  File "/usr/local/lib/python3.6/site-packages/django/core/handlers/base.py", line 187, in _get_response
    response = self.process_exception_by_middleware(e, request)
  File "/usr/local/lib/python3.6/site-packages/django/core/handlers/base.py", line 185, in _get_response
    response = wrapped_callback(request, *callback_args, **callback_kwargs)
  File "/Users/emirozbir/Desktop/gamer_trnet/epin/epinmain/views.py", line 104, in login
    return render('login.html',c)##look to the source code.
  File "/usr/local/lib/python3.6/site-packages/django/shortcuts.py", line 30, in render
    content = loader.render_to_string(template_name, context, request, using=using)
  File "/usr/local/lib/python3.6/site-packages/django/template/loader.py", line 67, in render_to_string
    template = get_template(template_name, using=using)
  File "/usr/local/lib/python3.6/site-packages/django/template/loader.py", line 25, in get_template
    raise TemplateDoesNotExist(template_name, chain=chain)
django.template.exceptions.TemplateDoesNotExist: {'csrf_token': <SimpleLazyObject: <function csrf.<locals>._get_val at 0x1106d4950>>}
ERROR:django.request:Internal Server Error: /accounts/login/
Traceback (most recent call last):
  File "/usr/local/lib/python3.6/site-packages/django/core/handlers/exception.py", line 41, in inner
    response = get_response(request)
  File "/usr/local/lib/python3.6/site-packages/django/core/handlers/base.py", line 187, in _get_response
    response = self.process_exception_by_middleware(e, request)
  File "/usr/local/lib/python3.6/site-packages/django/core/handlers/base.py", line 185, in _get_response
    response = wrapped_callback(request, *callback_args, **callback_kwargs)
  File "/Users/emirozbir/Desktop/gamer_trnet/epin/epinmain/views.py", line 107, in login
    return render('login.html',c)##look to the source code.
  File "/usr/local/lib/python3.6/site-packages/django/shortcuts.py", line 30, in render
    content = loader.render_to_string(template_name, context, request, using=using)
  File "/usr/local/lib/python3.6/site-packages/django/template/loader.py", line 67, in render_to_string
    template = get_template(template_name, using=using)
  File "/usr/local/lib/python3.6/site-packages/django/template/loader.py", line 25, in get_template
    raise TemplateDoesNotExist(template_name, chain=chain)
django.template.exceptions.TemplateDoesNotExist: {'csrf_token': <SimpleLazyObject: <function csrf.<locals>._get_val at 0x10cdd6950>>}
ERROR:django.request:Internal Server Error: /accounts/login/
Traceback (most recent call last):
  File "/Users/emirozbir/Desktop/gamer_trnet/epin/epinmain/views.py", line 108, in login
    return render('login.html',c)##look to the source code.
  File "/usr/local/lib/python3.6/site-packages/django/shortcuts.py", line 30, in render
    content = loader.render_to_string(template_name, context, request, using=using)
  File "/usr/local/lib/python3.6/site-packages/django/template/loader.py", line 67, in render_to_string
    template = get_template(template_name, using=using)
  File "/usr/local/lib/python3.6/site-packages/django/template/loader.py", line 25, in get_template
    raise TemplateDoesNotExist(template_name, chain=chain)
django.template.exceptions.TemplateDoesNotExist: {'csrf_token': <SimpleLazyObject: <function csrf.<locals>._get_val at 0x107d28a60>>}

During handling of the above exception, another exception occurred:

Traceback (most recent call last):
  File "/usr/local/lib/python3.6/site-packages/django/core/handlers/exception.py", line 41, in inner
    response = get_response(request)
  File "/usr/local/lib/python3.6/site-packages/django/core/handlers/base.py", line 187, in _get_response
    response = self.process_exception_by_middleware(e, request)
  File "/usr/local/lib/python3.6/site-packages/django/core/handlers/base.py", line 185, in _get_response
    response = wrapped_callback(request, *callback_args, **callback_kwargs)
  File "/Users/emirozbir/Desktop/gamer_trnet/epin/epinmain/views.py", line 111, in login
    loggers.info("USER {} CANNOT LOGED TO THE SYSTEM ".format(request.user.username))
NameError: name 'loggers' is not defined
ERROR:django.request:Internal Server Error: /accounts/login/
Traceback (most recent call last):
  File "/Users/emirozbir/Desktop/gamer_trnet/epin/epinmain/views.py", line 108, in login
    return render('login.html',c)##look to the source code.
  File "/usr/local/lib/python3.6/site-packages/django/shortcuts.py", line 30, in render
    content = loader.render_to_string(template_name, context, request, using=using)
  File "/usr/local/lib/python3.6/site-packages/django/template/loader.py", line 67, in render_to_string
    template = get_template(template_name, using=using)
  File "/usr/local/lib/python3.6/site-packages/django/template/loader.py", line 25, in get_template
    raise TemplateDoesNotExist(template_name, chain=chain)
django.template.exceptions.TemplateDoesNotExist: {'csrf_token': <SimpleLazyObject: <function csrf.<locals>._get_val at 0x108268ae8>>}

During handling of the above exception, another exception occurred:

Traceback (most recent call last):
  File "/usr/local/lib/python3.6/site-packages/django/core/handlers/exception.py", line 41, in inner
    response = get_response(request)
  File "/usr/local/lib/python3.6/site-packages/django/core/handlers/base.py", line 187, in _get_response
    response = self.process_exception_by_middleware(e, request)
  File "/usr/local/lib/python3.6/site-packages/django/core/handlers/base.py", line 185, in _get_response
    response = wrapped_callback(request, *callback_args, **callback_kwargs)
  File "/Users/emirozbir/Desktop/gamer_trnet/epin/epinmain/views.py", line 111, in login
    loggers.info("USER {} CANNOT LOGED TO THE SYSTEM ".format(request.user.username))
NameError: name 'loggers' is not defined
INFO:epinmain.views:USER  CANNOT LOGED TO THE SYSTEM 
ERROR:django.request:Internal Server Error: /accounts/login/
Traceback (most recent call last):
  File "/usr/local/lib/python3.6/site-packages/django/core/handlers/exception.py", line 41, in inner
    response = get_response(request)
  File "/usr/local/lib/python3.6/site-packages/django/core/handlers/base.py", line 198, in _get_response
    "returned None instead." % (callback.__module__, view_name)
ValueError: The view epinmain.views.login didn't return an HttpResponse object. It returned None instead.
INFO:epinmain.views:USER  CANNOT LOGED TO THE SYSTEM 
ERROR:django.request:Internal Server Error: /accounts/login/
Traceback (most recent call last):
  File "/usr/local/lib/python3.6/site-packages/django/core/handlers/exception.py", line 41, in inner
    response = get_response(request)
  File "/usr/local/lib/python3.6/site-packages/django/core/handlers/base.py", line 198, in _get_response
    "returned None instead." % (callback.__module__, view_name)
ValueError: The view epinmain.views.login didn't return an HttpResponse object. It returned None instead.
INFO:epinmain.views:USER  CANNOT LOGED TO THE SYSTEM 
ERROR:django.request:Internal Server Error: /accounts/login/
Traceback (most recent call last):
  File "/usr/local/lib/python3.6/site-packages/django/core/handlers/exception.py", line 41, in inner
    response = get_response(request)
  File "/usr/local/lib/python3.6/site-packages/django/core/handlers/base.py", line 198, in _get_response
    "returned None instead." % (callback.__module__, view_name)
ValueError: The view epinmain.views.login didn't return an HttpResponse object. It returned None instead.
INFO:epinmain.views:USER  CANNOT have a template TO THE SYSTEM 
ERROR:django.request:Internal Server Error: /accounts/login/
Traceback (most recent call last):
  File "/usr/local/lib/python3.6/site-packages/django/core/handlers/exception.py", line 41, in inner
    response = get_response(request)
  File "/usr/local/lib/python3.6/site-packages/django/core/handlers/base.py", line 198, in _get_response
    "returned None instead." % (callback.__module__, view_name)
ValueError: The view epinmain.views.login didn't return an HttpResponse object. It returned None instead.
WARNING:django.request:Not Found: /
WARNING:django.request:Not Found: /
WARNING:django.request:Not Found: /favicon.ico
WARNING:django.request:Not Found: /accounts/login
INFO:epinmain.views:USER  CANNOT have a template TO THE SYSTEM 
ERROR:django.request:Internal Server Error: /accounts/login/
Traceback (most recent call last):
  File "/usr/local/lib/python3.6/site-packages/django/core/handlers/exception.py", line 41, in inner
    response = get_response(request)
  File "/usr/local/lib/python3.6/site-packages/django/core/handlers/base.py", line 198, in _get_response
    "returned None instead." % (callback.__module__, view_name)
ValueError: The view epinmain.views.login didn't return an HttpResponse object. It returned None instead.
INFO:epinmain.views:USER  CANNOT have a template TO THE SYSTEM 
ERROR:django.request:Internal Server Error: /accounts/login/
Traceback (most recent call last):
  File "/usr/local/lib/python3.6/site-packages/django/core/handlers/exception.py", line 41, in inner
    response = get_response(request)
  File "/usr/local/lib/python3.6/site-packages/django/core/handlers/base.py", line 198, in _get_response
    "returned None instead." % (callback.__module__, view_name)
ValueError: The view epinmain.views.login didn't return an HttpResponse object. It returned None instead.
INFO:epinmain.views:USER  CANNOT have a template TO THE SYSTEM 
ERROR:django.request:Internal Server Error: /accounts/login/
Traceback (most recent call last):
  File "/usr/local/lib/python3.6/site-packages/django/core/handlers/exception.py", line 41, in inner
    response = get_response(request)
  File "/usr/local/lib/python3.6/site-packages/django/core/handlers/base.py", line 198, in _get_response
    "returned None instead." % (callback.__module__, view_name)
ValueError: The view epinmain.views.login didn't return an HttpResponse object. It returned None instead.
ERROR:django.request:Internal Server Error: /accounts/login/
Traceback (most recent call last):
  File "/usr/local/lib/python3.6/site-packages/django/core/handlers/exception.py", line 41, in inner
    response = get_response(request)
  File "/usr/local/lib/python3.6/site-packages/django/core/handlers/base.py", line 187, in _get_response
    response = self.process_exception_by_middleware(e, request)
  File "/usr/local/lib/python3.6/site-packages/django/core/handlers/base.py", line 185, in _get_response
    response = wrapped_callback(request, *callback_args, **callback_kwargs)
  File "/Users/emirozbir/Desktop/gamer_trnet/epin/epinmain/views.py", line 106, in login
    return render('login.html',c)##look to the source code.
  File "/usr/local/lib/python3.6/site-packages/django/shortcuts.py", line 30, in render
    content = loader.render_to_string(template_name, context, request, using=using)
  File "/usr/local/lib/python3.6/site-packages/django/template/loader.py", line 67, in render_to_string
    template = get_template(template_name, using=using)
  File "/usr/local/lib/python3.6/site-packages/django/template/loader.py", line 25, in get_template
    raise TemplateDoesNotExist(template_name, chain=chain)
django.template.exceptions.TemplateDoesNotExist: {'csrf_token': <SimpleLazyObject: <function csrf.<locals>._get_val at 0x105cfb9d8>>}
ERROR:django.request:Internal Server Error: /accounts/login/
Traceback (most recent call last):
  File "/usr/local/lib/python3.6/site-packages/django/core/handlers/exception.py", line 41, in inner
    response = get_response(request)
  File "/usr/local/lib/python3.6/site-packages/django/core/handlers/base.py", line 187, in _get_response
    response = self.process_exception_by_middleware(e, request)
  File "/usr/local/lib/python3.6/site-packages/django/core/handlers/base.py", line 185, in _get_response
    response = wrapped_callback(request, *callback_args, **callback_kwargs)
  File "/Users/emirozbir/Desktop/gamer_trnet/epin/epinmain/views.py", line 106, in login
    return render('signup.html',c)##look to the source code.
  File "/usr/local/lib/python3.6/site-packages/django/shortcuts.py", line 30, in render
    content = loader.render_to_string(template_name, context, request, using=using)
  File "/usr/local/lib/python3.6/site-packages/django/template/loader.py", line 67, in render_to_string
    template = get_template(template_name, using=using)
  File "/usr/local/lib/python3.6/site-packages/django/template/loader.py", line 25, in get_template
    raise TemplateDoesNotExist(template_name, chain=chain)
django.template.exceptions.TemplateDoesNotExist: {'csrf_token': <SimpleLazyObject: <function csrf.<locals>._get_val at 0x11159c9d8>>}
ERROR:django.request:Internal Server Error: /accounts/login/
Traceback (most recent call last):
  File "/usr/local/lib/python3.6/site-packages/django/core/handlers/exception.py", line 41, in inner
    response = get_response(request)
  File "/usr/local/lib/python3.6/site-packages/django/core/handlers/base.py", line 187, in _get_response
    response = self.process_exception_by_middleware(e, request)
  File "/usr/local/lib/python3.6/site-packages/django/core/handlers/base.py", line 185, in _get_response
    response = wrapped_callback(request, *callback_args, **callback_kwargs)
  File "/Users/emirozbir/Desktop/gamer_trnet/epin/epinmain/views.py", line 106, in login
    return render('signup.html',c)##look to the source code.
  File "/usr/local/lib/python3.6/site-packages/django/shortcuts.py", line 30, in render
    content = loader.render_to_string(template_name, context, request, using=using)
  File "/usr/local/lib/python3.6/site-packages/django/template/loader.py", line 67, in render_to_string
    template = get_template(template_name, using=using)
  File "/usr/local/lib/python3.6/site-packages/django/template/loader.py", line 25, in get_template
    raise TemplateDoesNotExist(template_name, chain=chain)
django.template.exceptions.TemplateDoesNotExist: {'csrf_token': <SimpleLazyObject: <function csrf.<locals>._get_val at 0x111afcbf8>>}
ERROR:django.request:Internal Server Error: /accounts/login/
Traceback (most recent call last):
  File "/usr/local/lib/python3.6/site-packages/django/core/handlers/exception.py", line 41, in inner
    response = get_response(request)
  File "/usr/local/lib/python3.6/site-packages/django/core/handlers/base.py", line 187, in _get_response
    response = self.process_exception_by_middleware(e, request)
  File "/usr/local/lib/python3.6/site-packages/django/core/handlers/base.py", line 185, in _get_response
    response = wrapped_callback(request, *callback_args, **callback_kwargs)
  File "/Users/emirozbir/Desktop/gamer_trnet/epin/epinmain/views.py", line 107, in login
    return render('login.html', c)  ##look to the source code.
  File "/usr/local/lib/python3.6/site-packages/django/shortcuts.py", line 30, in render
    content = loader.render_to_string(template_name, context, request, using=using)
  File "/usr/local/lib/python3.6/site-packages/django/template/loader.py", line 67, in render_to_string
    template = get_template(template_name, using=using)
  File "/usr/local/lib/python3.6/site-packages/django/template/loader.py", line 25, in get_template
    raise TemplateDoesNotExist(template_name, chain=chain)
django.template.exceptions.TemplateDoesNotExist: {'csrf_token': <SimpleLazyObject: <function csrf.<locals>._get_val at 0x1068b8a60>>}
ERROR:django.request:Internal Server Error: /accounts/login/
Traceback (most recent call last):
  File "/usr/local/lib/python3.6/site-packages/django/core/handlers/exception.py", line 41, in inner
    response = get_response(request)
  File "/usr/local/lib/python3.6/site-packages/django/core/handlers/base.py", line 187, in _get_response
    response = self.process_exception_by_middleware(e, request)
  File "/usr/local/lib/python3.6/site-packages/django/core/handlers/base.py", line 185, in _get_response
    response = wrapped_callback(request, *callback_args, **callback_kwargs)
  File "/Users/emirozbir/Desktop/gamer_trnet/epin/epinmain/views.py", line 107, in login
    return render('game.html')  ##look to the source code.
TypeError: render() missing 1 required positional argument: 'template_name'
ERROR:django.request:Internal Server Error: /accounts/login/
Traceback (most recent call last):
  File "/usr/local/lib/python3.6/site-packages/django/core/handlers/exception.py", line 41, in inner
    response = get_response(request)
  File "/usr/local/lib/python3.6/site-packages/django/core/handlers/base.py", line 187, in _get_response
    response = self.process_exception_by_middleware(e, request)
  File "/usr/local/lib/python3.6/site-packages/django/core/handlers/base.py", line 185, in _get_response
    response = wrapped_callback(request, *callback_args, **callback_kwargs)
  File "/Users/emirozbir/Desktop/gamer_trnet/epin/epinmain/views.py", line 107, in login
    return render('game.html')  ##look to the source code.
TypeError: render() missing 1 required positional argument: 'template_name'
ERROR:django.request:Internal Server Error: /accounts/login/
Traceback (most recent call last):
  File "/usr/local/lib/python3.6/site-packages/django/core/handlers/exception.py", line 41, in inner
    response = get_response(request)
  File "/usr/local/lib/python3.6/site-packages/django/core/handlers/base.py", line 187, in _get_response
    response = self.process_exception_by_middleware(e, request)
  File "/usr/local/lib/python3.6/site-packages/django/core/handlers/base.py", line 185, in _get_response
    response = wrapped_callback(request, *callback_args, **callback_kwargs)
  File "/Users/emirozbir/Desktop/gamer_trnet/epin/epinmain/views.py", line 107, in login
    return render('game.html')  ##look to the source code.
TypeError: render() missing 1 required positional argument: 'template_name'
ERROR:django.request:Internal Server Error: /accounts/login/
Traceback (most recent call last):
  File "/usr/local/lib/python3.6/site-packages/django/core/handlers/exception.py", line 41, in inner
    response = get_response(request)
  File "/usr/local/lib/python3.6/site-packages/django/core/handlers/base.py", line 187, in _get_response
    response = self.process_exception_by_middleware(e, request)
  File "/usr/local/lib/python3.6/site-packages/django/core/handlers/base.py", line 185, in _get_response
    response = wrapped_callback(request, *callback_args, **callback_kwargs)
  File "/Users/emirozbir/Desktop/gamer_trnet/epin/epinmain/views.py", line 107, in login
    return render('game.html',c)  ##look to the source code.
  File "/usr/local/lib/python3.6/site-packages/django/shortcuts.py", line 30, in render
    content = loader.render_to_string(template_name, context, request, using=using)
  File "/usr/local/lib/python3.6/site-packages/django/template/loader.py", line 67, in render_to_string
    template = get_template(template_name, using=using)
  File "/usr/local/lib/python3.6/site-packages/django/template/loader.py", line 25, in get_template
    raise TemplateDoesNotExist(template_name, chain=chain)
django.template.exceptions.TemplateDoesNotExist: {'csrf_token': <SimpleLazyObject: <function csrf.<locals>._get_val at 0x1082cd950>>}
ERROR:django.request:Internal Server Error: /accounts/login/
Traceback (most recent call last):
  File "/usr/local/lib/python3.6/site-packages/django/core/handlers/exception.py", line 41, in inner
    response = get_response(request)
  File "/usr/local/lib/python3.6/site-packages/django/core/handlers/base.py", line 187, in _get_response
    response = self.process_exception_by_middleware(e, request)
  File "/usr/local/lib/python3.6/site-packages/django/core/handlers/base.py", line 185, in _get_response
    response = wrapped_callback(request, *callback_args, **callback_kwargs)
  File "/Users/emirozbir/Desktop/gamer_trnet/epin/epinmain/views.py", line 107, in login
    return render_to_response('game.html')  ##look to the source code.
  File "/usr/local/lib/python3.6/site-packages/django/shortcuts.py", line 21, in render_to_response
    content = loader.render_to_string(template_name, context, using=using)
  File "/usr/local/lib/python3.6/site-packages/django/template/loader.py", line 67, in render_to_string
    template = get_template(template_name, using=using)
  File "/usr/local/lib/python3.6/site-packages/django/template/loader.py", line 25, in get_template
    raise TemplateDoesNotExist(template_name, chain=chain)
django.template.exceptions.TemplateDoesNotExist: game.html
ERROR:django.request:Internal Server Error: /accounts/loggedin/
Traceback (most recent call last):
  File "/usr/local/lib/python3.6/site-packages/django/core/handlers/exception.py", line 41, in inner
    response = get_response(request)
  File "/usr/local/lib/python3.6/site-packages/django/core/handlers/base.py", line 187, in _get_response
    response = self.process_exception_by_middleware(e, request)
  File "/usr/local/lib/python3.6/site-packages/django/core/handlers/base.py", line 185, in _get_response
    response = wrapped_callback(request, *callback_args, **callback_kwargs)
  File "/Users/emirozbir/Desktop/gamer_trnet/epin/epinmain/views.py", line 224, in loggedin
    return render('loggedin.html',{'full_name':request.user.username})
  File "/usr/local/lib/python3.6/site-packages/django/shortcuts.py", line 30, in render
    content = loader.render_to_string(template_name, context, request, using=using)
  File "/usr/local/lib/python3.6/site-packages/django/template/loader.py", line 67, in render_to_string
    template = get_template(template_name, using=using)
  File "/usr/local/lib/python3.6/site-packages/django/template/loader.py", line 25, in get_template
    raise TemplateDoesNotExist(template_name, chain=chain)
django.template.exceptions.TemplateDoesNotExist: {'full_name': 'test1'}
ERROR:django.request:Internal Server Error: /accounts/loggedin/
Traceback (most recent call last):
  File "/usr/local/lib/python3.6/site-packages/django/core/handlers/exception.py", line 41, in inner
    response = get_response(request)
  File "/usr/local/lib/python3.6/site-packages/django/core/handlers/base.py", line 187, in _get_response
    response = self.process_exception_by_middleware(e, request)
  File "/usr/local/lib/python3.6/site-packages/django/core/handlers/base.py", line 185, in _get_response
    response = wrapped_callback(request, *callback_args, **callback_kwargs)
  File "/Users/emirozbir/Desktop/gamer_trnet/epin/epinmain/views.py", line 224, in loggedin
    return render('games.html',{'full_name':request.user.username})
  File "/usr/local/lib/python3.6/site-packages/django/shortcuts.py", line 30, in render
    content = loader.render_to_string(template_name, context, request, using=using)
  File "/usr/local/lib/python3.6/site-packages/django/template/loader.py", line 67, in render_to_string
    template = get_template(template_name, using=using)
  File "/usr/local/lib/python3.6/site-packages/django/template/loader.py", line 25, in get_template
    raise TemplateDoesNotExist(template_name, chain=chain)
django.template.exceptions.TemplateDoesNotExist: {'full_name': 'test1'}
WARNING:django.request:Not Found: /shop/cart
WARNING:django.request:Not Found: /shop/cart/
WARNING:django.request:Not Found: /shop/carts/
WARNING:django.request:Not Found: /shops/carts/
WARNING:django.request:Not Found: /cart_status/carts/
WARNING:django.request:Not Found: /shop/carts/
WARNING:django.request:Not Found: /shop/cart/
WARNING:django.request:Not Found: /buy/cart/
DEBUG:root:USER : test1
ERROR:epinmain.views:SESSION KEYS CREATED !
WARNING:django.request:Not Found: /cart/cart_status/games/games/
ERROR:django.request:Internal Server Error: /games/games/
Traceback (most recent call last):
  File "/usr/local/lib/python3.6/site-packages/django/core/handlers/exception.py", line 41, in inner
    response = get_response(request)
  File "/usr/local/lib/python3.6/site-packages/django/core/handlers/base.py", line 187, in _get_response
    response = self.process_exception_by_middleware(e, request)
  File "/usr/local/lib/python3.6/site-packages/django/core/handlers/base.py", line 185, in _get_response
    response = wrapped_callback(request, *callback_args, **callback_kwargs)
  File "/Users/emirozbir/Desktop/gamer_trnet/epin/epinmain/views.py", line 91, in games
    return render('index.html',{'cart_datas':json_converter(my_keys.split(','),my_vals.split(','))})
  File "/usr/local/lib/python3.6/site-packages/django/shortcuts.py", line 30, in render
    content = loader.render_to_string(template_name, context, request, using=using)
  File "/usr/local/lib/python3.6/site-packages/django/template/loader.py", line 67, in render_to_string
    template = get_template(template_name, using=using)
  File "/usr/local/lib/python3.6/site-packages/django/template/loader.py", line 25, in get_template
    raise TemplateDoesNotExist(template_name, chain=chain)
django.template.exceptions.TemplateDoesNotExist: {'cart_datas': '{ " ":" ", "mw3":"123"}'}
ERROR:django.request:Internal Server Error: /cart/sale/
Traceback (most recent call last):
  File "/usr/local/lib/python3.6/site-packages/django/core/handlers/exception.py", line 41, in inner
    response = get_response(request)
  File "/usr/local/lib/python3.6/site-packages/django/core/handlers/base.py", line 187, in _get_response
    response = self.process_exception_by_middleware(e, request)
  File "/usr/local/lib/python3.6/site-packages/django/core/handlers/base.py", line 185, in _get_response
    response = wrapped_callback(request, *callback_args, **callback_kwargs)
  File "/Users/emirozbir/Desktop/gamer_trnet/epin/epinmain/views.py", line 190, in sale_finish
    add_sale_to_the_sale_table(main_template,user_id)
  File "/Users/emirozbir/Desktop/gamer_trnet/epin/epinmain/views.py", line 170, in add_sale_to_the_sale_table
    conn.commit()
psycopg2.IntegrityError: insert or update on table "epinmain_sale" violates foreign key constraint "epinmain_sale_user_id_e4e7df32_fk_epinmain_profile_id"
DETAIL:  Key (user_id)=(8) is not present in table "epinmain_profile".

ERROR:django.request:Internal Server Error: /cart/cart_status/
Traceback (most recent call last):
  File "/Users/emirozbir/Desktop/gamer_trnet/epin/epinmain/views.py", line 58, in cart_status
    request.session["game"] += ',' + request.POST.get("game")
TypeError: must be str, not NoneType

During handling of the above exception, another exception occurred:

Traceback (most recent call last):
  File "/usr/local/lib/python3.6/site-packages/django/core/handlers/exception.py", line 41, in inner
    response = get_response(request)
  File "/usr/local/lib/python3.6/site-packages/django/core/handlers/base.py", line 187, in _get_response
    response = self.process_exception_by_middleware(e, request)
  File "/usr/local/lib/python3.6/site-packages/django/core/handlers/base.py", line 185, in _get_response
    response = wrapped_callback(request, *callback_args, **callback_kwargs)
  File "/Users/emirozbir/Desktop/gamer_trnet/epin/epinmain/views.py", line 67, in cart_status
    request.session["game"] += ',' + request.POST.get("game")
TypeError: must be str, not NoneType
DEBUG:root:USER : test1
INFO:epinmain.views:CART CREATED by test1 Wed Jun 28 07:36:34 2017
WARNING:django.request:Not Found: /cart/cart_status/games/games/
DEBUG:root:USER : test1
DEBUG:root:USER : test1
INFO:epinmain.views:CART CREATED by test1 Wed Jun 28 07:36:57 2017
INFO:epinmain.views:CART CREATED by test1 Wed Jun 28 07:37:46 2017
INFO:epinmain.views:CART CREATED by test1 Wed Jun 28 07:37:48 2017
DEBUG:root:USER : test1
INFO:epinmain.views:CART CREATED by test1 Wed Jun 28 07:38:00 2017
WARNING:django.request:Not Found: /
WARNING:django.request:Not Found: /
WARNING:django.request:Not Found: /
WARNING:django.request:Not Found: /
WARNING:django.request:Not Found: /main
WARNING:django.request:Not Found: /games
WARNING:django.request:Not Found: /games/
WARNING:django.request:Not Found: /games/games
ERROR:django.request:Internal Server Error: /games/games/
Traceback (most recent call last):
  File "/usr/local/lib/python3.6/site-packages/django/core/handlers/exception.py", line 41, in inner
    response = get_response(request)
  File "/usr/local/lib/python3.6/site-packages/django/core/handlers/base.py", line 187, in _get_response
    response = self.process_exception_by_middleware(e, request)
  File "/usr/local/lib/python3.6/site-packages/django/core/handlers/base.py", line 185, in _get_response
    response = wrapped_callback(request, *callback_args, **callback_kwargs)
  File "/Users/emirozbir/Desktop/gamer_trnet/epin/epinmain/views.py", line 93, in games
    return render('index.html',{'cart_datas':json_converter(my_keys.split(','),my_vals.split(','))})
  File "/usr/local/lib/python3.6/site-packages/django/shortcuts.py", line 30, in render
    content = loader.render_to_string(template_name, context, request, using=using)
  File "/usr/local/lib/python3.6/site-packages/django/template/loader.py", line 67, in render_to_string
    template = get_template(template_name, using=using)
  File "/usr/local/lib/python3.6/site-packages/django/template/loader.py", line 25, in get_template
    raise TemplateDoesNotExist(template_name, chain=chain)
django.template.exceptions.TemplateDoesNotExist: {'cart_datas': '{ " ":" ", "mw3":"123", "mw3":"123", "mw4":"123", "mw4":"123", "mw4":"123", "mw3":"123"}'}
ERROR:django.request:Internal Server Error: /games/games/
Traceback (most recent call last):
  File "/usr/local/lib/python3.6/site-packages/django/core/handlers/exception.py", line 41, in inner
    response = get_response(request)
  File "/usr/local/lib/python3.6/site-packages/django/core/handlers/base.py", line 187, in _get_response
    response = self.process_exception_by_middleware(e, request)
  File "/usr/local/lib/python3.6/site-packages/django/core/handlers/base.py", line 185, in _get_response
    response = wrapped_callback(request, *callback_args, **callback_kwargs)
  File "/Users/emirozbir/Desktop/gamer_trnet/epin/epinmain/views.py", line 93, in games
    return render('index.html',{'cart_datas':json_converter(my_keys.split(','),my_vals.split(','))})
  File "/usr/local/lib/python3.6/site-packages/django/shortcuts.py", line 30, in render
    content = loader.render_to_string(template_name, context, request, using=using)
  File "/usr/local/lib/python3.6/site-packages/django/template/loader.py", line 67, in render_to_string
    template = get_template(template_name, using=using)
  File "/usr/local/lib/python3.6/site-packages/django/template/loader.py", line 25, in get_template
    raise TemplateDoesNotExist(template_name, chain=chain)
django.template.exceptions.TemplateDoesNotExist: {'cart_datas': '{ " ":" ", "mw3":"123", "mw3":"123", "mw4":"123", "mw4":"123", "mw4":"123", "mw3":"123"}'}
WARNING:django.request:Not Found: /main/games/
WARNING:django.request:Not Found: /main/
WARNING:django.request:Not Found: /main
WARNING:django.request:Not Found: /main
WARNING:django.request:Not Found: /main
WARNING:django.request:Not Found: /main
WARNING:django.request:Not Found: /main/
ERROR:django.request:Internal Server Error: /accounts/main/
Traceback (most recent call last):
  File "/usr/local/lib/python3.6/site-packages/django/core/handlers/exception.py", line 41, in inner
    response = get_response(request)
  File "/usr/local/lib/python3.6/site-packages/django/core/handlers/base.py", line 198, in _get_response
    "returned None instead." % (callback.__module__, view_name)
ValueError: The view epinmain.views.main didn't return an HttpResponse object. It returned None instead.
ERROR:django.request:Internal Server Error: /accounts/main/
Traceback (most recent call last):
  File "/usr/local/lib/python3.6/site-packages/django/core/handlers/exception.py", line 41, in inner
    response = get_response(request)
  File "/usr/local/lib/python3.6/site-packages/django/core/handlers/base.py", line 187, in _get_response
    response = self.process_exception_by_middleware(e, request)
  File "/usr/local/lib/python3.6/site-packages/django/core/handlers/base.py", line 185, in _get_response
    response = wrapped_callback(request, *callback_args, **callback_kwargs)
  File "/Users/emirozbir/Desktop/gamer_trnet/epin/epinmain/views.py", line 72, in main
    return render('index.html', {'cart_datas': request.session['game']})
  File "/usr/local/lib/python3.6/site-packages/django/shortcuts.py", line 30, in render
    content = loader.render_to_string(template_name, context, request, using=using)
  File "/usr/local/lib/python3.6/site-packages/django/template/loader.py", line 67, in render_to_string
    template = get_template(template_name, using=using)
  File "/usr/local/lib/python3.6/site-packages/django/template/loader.py", line 25, in get_template
    raise TemplateDoesNotExist(template_name, chain=chain)
django.template.exceptions.TemplateDoesNotExist: {'cart_datas': ' ,mw3,mw3,mw4,mw4,mw4,mw3'}
ERROR:django.request:Internal Server Error: /accounts/main/
Traceback (most recent call last):
  File "/usr/local/lib/python3.6/site-packages/django/core/handlers/exception.py", line 41, in inner
    response = get_response(request)
  File "/usr/local/lib/python3.6/site-packages/django/core/handlers/base.py", line 187, in _get_response
    response = self.process_exception_by_middleware(e, request)
  File "/usr/local/lib/python3.6/site-packages/django/core/handlers/base.py", line 185, in _get_response
    response = wrapped_callback(request, *callback_args, **callback_kwargs)
  File "/Users/emirozbir/Desktop/gamer_trnet/epin/epinmain/views.py", line 72, in main
    return render('index.html', {'cart_datas': str(request.session['game'])})
  File "/usr/local/lib/python3.6/site-packages/django/shortcuts.py", line 30, in render
    content = loader.render_to_string(template_name, context, request, using=using)
  File "/usr/local/lib/python3.6/site-packages/django/template/loader.py", line 67, in render_to_string
    template = get_template(template_name, using=using)
  File "/usr/local/lib/python3.6/site-packages/django/template/loader.py", line 25, in get_template
    raise TemplateDoesNotExist(template_name, chain=chain)
django.template.exceptions.TemplateDoesNotExist: {'cart_datas': ' ,mw3,mw3,mw4,mw4,mw4,mw3'}
ERROR:django.request:Internal Server Error: /accounts/main/
Traceback (most recent call last):
  File "/usr/local/lib/python3.6/site-packages/django/core/handlers/exception.py", line 41, in inner
    response = get_response(request)
  File "/usr/local/lib/python3.6/site-packages/django/core/handlers/base.py", line 187, in _get_response
    response = self.process_exception_by_middleware(e, request)
  File "/usr/local/lib/python3.6/site-packages/django/core/handlers/base.py", line 185, in _get_response
    response = wrapped_callback(request, *callback_args, **callback_kwargs)
  File "/Users/emirozbir/Desktop/gamer_trnet/epin/epinmain/views.py", line 72, in main
    return render('index.html', {'cart_datas': str(request.session['game'])})
  File "/usr/local/lib/python3.6/site-packages/django/shortcuts.py", line 30, in render
    content = loader.render_to_string(template_name, context, request, using=using)
  File "/usr/local/lib/python3.6/site-packages/django/template/loader.py", line 67, in render_to_string
    template = get_template(template_name, using=using)
  File "/usr/local/lib/python3.6/site-packages/django/template/loader.py", line 25, in get_template
    raise TemplateDoesNotExist(template_name, chain=chain)
django.template.exceptions.TemplateDoesNotExist: {'cart_datas': ' ,mw3,mw3,mw4,mw4,mw4,mw3'}
ERROR:django.request:Internal Server Error: /accounts/main/
Traceback (most recent call last):
  File "/usr/local/lib/python3.6/site-packages/django/core/handlers/exception.py", line 41, in inner
    response = get_response(request)
  File "/usr/local/lib/python3.6/site-packages/django/core/handlers/base.py", line 187, in _get_response
    response = self.process_exception_by_middleware(e, request)
  File "/usr/local/lib/python3.6/site-packages/django/core/handlers/base.py", line 185, in _get_response
    response = wrapped_callback(request, *callback_args, **callback_kwargs)
  File "/Users/emirozbir/Desktop/gamer_trnet/epin/epinmain/views.py", line 75, in main
    return render('index.html' )
TypeError: render() missing 1 required positional argument: 'template_name'
ERROR:django.request:Internal Server Error: /accounts/main/
Traceback (most recent call last):
  File "/usr/local/lib/python3.6/site-packages/django/core/handlers/exception.py", line 41, in inner
    response = get_response(request)
  File "/usr/local/lib/python3.6/site-packages/django/core/handlers/base.py", line 187, in _get_response
    response = self.process_exception_by_middleware(e, request)
  File "/usr/local/lib/python3.6/site-packages/django/core/handlers/base.py", line 185, in _get_response
    response = wrapped_callback(request, *callback_args, **callback_kwargs)
  File "/Users/emirozbir/Desktop/gamer_trnet/epin/epinmain/views.py", line 76, in main
    return render('index.html')
TypeError: render() missing 1 required positional argument: 'template_name'
ERROR:django.request:Internal Server Error: /accounts/main/
Traceback (most recent call last):
  File "/usr/local/lib/python3.6/site-packages/django/core/handlers/exception.py", line 41, in inner
    response = get_response(request)
  File "/usr/local/lib/python3.6/site-packages/django/core/handlers/base.py", line 187, in _get_response
    response = self.process_exception_by_middleware(e, request)
  File "/usr/local/lib/python3.6/site-packages/django/core/handlers/base.py", line 185, in _get_response
    response = wrapped_callback(request, *callback_args, **callback_kwargs)
  File "/Users/emirozbir/Desktop/gamer_trnet/epin/epinmain/views.py", line 76, in main
    return render("index.html")
TypeError: render() missing 2 required positional arguments: 'request' and 'template_name'
ERROR:django.request:Internal Server Error: /accounts/main/
Traceback (most recent call last):
  File "/usr/local/lib/python3.6/site-packages/django/core/handlers/exception.py", line 41, in inner
    response = get_response(request)
  File "/usr/local/lib/python3.6/site-packages/django/core/handlers/base.py", line 187, in _get_response
    response = self.process_exception_by_middleware(e, request)
  File "/usr/local/lib/python3.6/site-packages/django/core/handlers/base.py", line 185, in _get_response
    response = wrapped_callback(request, *callback_args, **callback_kwargs)
  File "/Users/emirozbir/Desktop/gamer_trnet/epin/epinmain/views.py", line 76, in main
    return render("index.html")
TypeError: render() missing 2 required positional arguments: 'request' and 'template_name'
ERROR:django.request:Internal Server Error: /accounts/main/
Traceback (most recent call last):
  File "/usr/local/lib/python3.6/site-packages/django/core/handlers/exception.py", line 41, in inner
    response = get_response(request)
  File "/usr/local/lib/python3.6/site-packages/django/core/handlers/base.py", line 187, in _get_response
    response = self.process_exception_by_middleware(e, request)
  File "/usr/local/lib/python3.6/site-packages/django/core/handlers/base.py", line 185, in _get_response
    response = wrapped_callback(request, *callback_args, **callback_kwargs)
  File "/Users/emirozbir/Desktop/gamer_trnet/epin/epinmain/views.py", line 76, in main
    return render(request,"index.html",{'cart_datas': request.session['games']})
  File "/usr/local/lib/python3.6/site-packages/django/contrib/sessions/backends/base.py", line 57, in __getitem__
    return self._session[key]
KeyError: 'games'
DEBUG:root:USER : test1
INFO:epinmain.views:CART CREATED by test1 Wed Jun 28 07:57:22 2017
INFO:epinmain.views:CART CREATED by test1 Wed Jun 28 07:57:43 2017
WARNING:django.request:Not Found: /cart/finis
WARNING:django.request:Not Found: /cart/finish
WARNING:django.request:Not Found: /cart/finish_sale
ERROR:django.request:Internal Server Error: /cart/sale/
Traceback (most recent call last):
  File "/usr/local/lib/python3.6/site-packages/django/core/handlers/exception.py", line 41, in inner
    response = get_response(request)
  File "/usr/local/lib/python3.6/site-packages/django/core/handlers/base.py", line 187, in _get_response
    response = self.process_exception_by_middleware(e, request)
  File "/usr/local/lib/python3.6/site-packages/django/core/handlers/base.py", line 185, in _get_response
    response = wrapped_callback(request, *callback_args, **callback_kwargs)
  File "/Users/emirozbir/Desktop/gamer_trnet/epin/epinmain/views.py", line 178, in sale_finish
    add_sale_to_the_sale_table(main_template, user_id)
  File "/Users/emirozbir/Desktop/gamer_trnet/epin/epinmain/views.py", line 161, in add_sale_to_the_sale_table
    conn.commit()
psycopg2.IntegrityError: insert or update on table "epinmain_sale" violates foreign key constraint "epinmain_sale_user_id_e4e7df32_fk_epinmain_profile_id"
DETAIL:  Key (user_id)=(8) is not present in table "epinmain_profile".

WARNING:django.request:Not Found: /admin
WARNING:django.request:Not Found: /cart/finish_sale
WARNING:django.request:Not Found: /cart/finish_sale/
ERROR:django.request:Internal Server Error: /cart/sale/
Traceback (most recent call last):
  File "/usr/local/lib/python3.6/site-packages/django/core/handlers/exception.py", line 41, in inner
    response = get_response(request)
  File "/usr/local/lib/python3.6/site-packages/django/core/handlers/base.py", line 187, in _get_response
    response = self.process_exception_by_middleware(e, request)
  File "/usr/local/lib/python3.6/site-packages/django/core/handlers/base.py", line 185, in _get_response
    response = wrapped_callback(request, *callback_args, **callback_kwargs)
  File "/Users/emirozbir/Desktop/gamer_trnet/epin/epinmain/views.py", line 165, in sale_finish
    my_keys = request.session['game']
  File "/usr/local/lib/python3.6/site-packages/django/contrib/sessions/backends/base.py", line 57, in __getitem__
    return self._session[key]
KeyError: 'game'
ERROR:django.request:Internal Server Error: /cart/sale/
Traceback (most recent call last):
  File "/usr/local/lib/python3.6/site-packages/django/core/handlers/exception.py", line 41, in inner
    response = get_response(request)
  File "/usr/local/lib/python3.6/site-packages/django/core/handlers/base.py", line 187, in _get_response
    response = self.process_exception_by_middleware(e, request)
  File "/usr/local/lib/python3.6/site-packages/django/core/handlers/base.py", line 185, in _get_response
    response = wrapped_callback(request, *callback_args, **callback_kwargs)
  File "/Users/emirozbir/Desktop/gamer_trnet/epin/epinmain/views.py", line 165, in sale_finish
    my_vals = request.session['count']
  File "/usr/local/lib/python3.6/site-packages/django/contrib/sessions/backends/base.py", line 57, in __getitem__
    return self._session[key]
KeyError: 'count'
ERROR:django.request:Internal Server Error: /cart/sale/
Traceback (most recent call last):
  File "/usr/local/lib/python3.6/site-packages/django/core/handlers/exception.py", line 41, in inner
    response = get_response(request)
  File "/usr/local/lib/python3.6/site-packages/django/core/handlers/base.py", line 187, in _get_response
    response = self.process_exception_by_middleware(e, request)
  File "/usr/local/lib/python3.6/site-packages/django/core/handlers/base.py", line 185, in _get_response
    response = wrapped_callback(request, *callback_args, **callback_kwargs)
  File "/Users/emirozbir/Desktop/gamer_trnet/epin/epinmain/views.py", line 166, in sale_finish
    my_keys = request.session['game']
  File "/usr/local/lib/python3.6/site-packages/django/contrib/sessions/backends/base.py", line 57, in __getitem__
    return self._session[key]
KeyError: 'game'
ERROR:django.request:Internal Server Error: /cart/sale/
Traceback (most recent call last):
  File "/usr/local/lib/python3.6/site-packages/django/core/handlers/exception.py", line 41, in inner
    response = get_response(request)
  File "/usr/local/lib/python3.6/site-packages/django/core/handlers/base.py", line 187, in _get_response
    response = self.process_exception_by_middleware(e, request)
  File "/usr/local/lib/python3.6/site-packages/django/core/handlers/base.py", line 185, in _get_response
    response = wrapped_callback(request, *callback_args, **callback_kwargs)
  File "/Users/emirozbir/Desktop/gamer_trnet/epin/epinmain/views.py", line 167, in sale_finish
    my_keys = request.session['game']
  File "/usr/local/lib/python3.6/site-packages/django/contrib/sessions/backends/base.py", line 57, in __getitem__
    return self._session[key]
KeyError: 'game'
ERROR:django.request:Internal Server Error: /cart/sale/
Traceback (most recent call last):
  File "/usr/local/lib/python3.6/site-packages/django/core/handlers/exception.py", line 41, in inner
    response = get_response(request)
  File "/usr/local/lib/python3.6/site-packages/django/core/handlers/base.py", line 187, in _get_response
    response = self.process_exception_by_middleware(e, request)
  File "/usr/local/lib/python3.6/site-packages/django/core/handlers/base.py", line 185, in _get_response
    response = wrapped_callback(request, *callback_args, **callback_kwargs)
  File "/Users/emirozbir/Desktop/gamer_trnet/epin/epinmain/views.py", line 166, in sale_finish
    print(request.session['game'])
  File "/usr/local/lib/python3.6/site-packages/django/contrib/sessions/backends/base.py", line 57, in __getitem__
    return self._session[key]
KeyError: 'game'
ERROR:django.request:Internal Server Error: /cart/sale/
Traceback (most recent call last):
  File "/usr/local/lib/python3.6/site-packages/django/core/handlers/exception.py", line 41, in inner
    response = get_response(request)
  File "/usr/local/lib/python3.6/site-packages/django/core/handlers/base.py", line 187, in _get_response
    response = self.process_exception_by_middleware(e, request)
  File "/usr/local/lib/python3.6/site-packages/django/core/handlers/base.py", line 185, in _get_response
    response = wrapped_callback(request, *callback_args, **callback_kwargs)
  File "/Users/emirozbir/Desktop/gamer_trnet/epin/epinmain/views.py", line 167, in sale_finish
    my_keys = request.session['game']
  File "/usr/local/lib/python3.6/site-packages/django/contrib/sessions/backends/base.py", line 57, in __getitem__
    return self._session[key]
KeyError: 'game'
ERROR:django.request:Internal Server Error: /cart/sale/
Traceback (most recent call last):
  File "/usr/local/lib/python3.6/site-packages/django/core/handlers/exception.py", line 41, in inner
    response = get_response(request)
  File "/usr/local/lib/python3.6/site-packages/django/core/handlers/base.py", line 187, in _get_response
    response = self.process_exception_by_middleware(e, request)
  File "/usr/local/lib/python3.6/site-packages/django/core/handlers/base.py", line 185, in _get_response
    response = wrapped_callback(request, *callback_args, **callback_kwargs)
  File "/Users/emirozbir/Desktop/gamer_trnet/epin/epinmain/views.py", line 166, in sale_finish
    my_keys = request.session['game']
  File "/usr/local/lib/python3.6/site-packages/django/contrib/sessions/backends/base.py", line 57, in __getitem__
    return self._session[key]
KeyError: 'game'
ERROR:django.request:Internal Server Error: /cart/sale/
Traceback (most recent call last):
  File "/usr/local/lib/python3.6/site-packages/django/core/handlers/exception.py", line 41, in inner
    response = get_response(request)
  File "/usr/local/lib/python3.6/site-packages/django/core/handlers/base.py", line 187, in _get_response
    response = self.process_exception_by_middleware(e, request)
  File "/usr/local/lib/python3.6/site-packages/django/core/handlers/base.py", line 185, in _get_response
    response = wrapped_callback(request, *callback_args, **callback_kwargs)
  File "/Users/emirozbir/Desktop/gamer_trnet/epin/epinmain/views.py", line 166, in sale_finish
    my_keys = request.session['game']
  File "/usr/local/lib/python3.6/site-packages/django/contrib/sessions/backends/base.py", line 57, in __getitem__
    return self._session[key]
KeyError: 'game'
WARNING:django.request:Not Found: /account/index/
ERROR:django.request:Internal Server Error: /accounts/login/
Traceback (most recent call last):
  File "/usr/local/lib/python3.6/site-packages/django/core/handlers/exception.py", line 41, in inner
    response = get_response(request)
  File "/usr/local/lib/python3.6/site-packages/django/core/handlers/base.py", line 187, in _get_response
    response = self.process_exception_by_middleware(e, request)
  File "/usr/local/lib/python3.6/site-packages/django/core/handlers/base.py", line 185, in _get_response
    response = wrapped_callback(request, *callback_args, **callback_kwargs)
  File "/Users/emirozbir/Desktop/desktop/gamer_trnet-yedek/epin/epinmain/views.py", line 31, in login
    render_to_response(request,"login.html",c)
  File "/usr/local/lib/python3.6/site-packages/django/shortcuts.py", line 21, in render_to_response
    content = loader.render_to_string(template_name, context, using=using)
  File "/usr/local/lib/python3.6/site-packages/django/template/loader.py", line 67, in render_to_string
    template = get_template(template_name, using=using)
  File "/usr/local/lib/python3.6/site-packages/django/template/loader.py", line 25, in get_template
    raise TemplateDoesNotExist(template_name, chain=chain)
django.template.exceptions.TemplateDoesNotExist: <WSGIRequest: GET '/accounts/login/'>
ERROR:django.request:Internal Server Error: /accounts/login/
Traceback (most recent call last):
  File "/usr/local/lib/python3.6/site-packages/django/core/handlers/exception.py", line 41, in inner
    response = get_response(request)
  File "/usr/local/lib/python3.6/site-packages/django/core/handlers/base.py", line 187, in _get_response
    response = self.process_exception_by_middleware(e, request)
  File "/usr/local/lib/python3.6/site-packages/django/core/handlers/base.py", line 185, in _get_response
    response = wrapped_callback(request, *callback_args, **callback_kwargs)
  File "/Users/emirozbir/Desktop/desktop/gamer_trnet-yedek/epin/epinmain/views.py", line 37, in login
    render_to_response(request,"login.html",c)
  File "/usr/local/lib/python3.6/site-packages/django/shortcuts.py", line 21, in render_to_response
    content = loader.render_to_string(template_name, context, using=using)
  File "/usr/local/lib/python3.6/site-packages/django/template/loader.py", line 67, in render_to_string
    template = get_template(template_name, using=using)
  File "/usr/local/lib/python3.6/site-packages/django/template/loader.py", line 25, in get_template
    raise TemplateDoesNotExist(template_name, chain=chain)
django.template.exceptions.TemplateDoesNotExist: <WSGIRequest: GET '/accounts/login/'>
ERROR:django.request:Internal Server Error: /accounts/login/
Traceback (most recent call last):
  File "/usr/local/lib/python3.6/site-packages/django/core/handlers/exception.py", line 41, in inner
    response = get_response(request)
  File "/usr/local/lib/python3.6/site-packages/django/core/handlers/base.py", line 187, in _get_response
    response = self.process_exception_by_middleware(e, request)
  File "/usr/local/lib/python3.6/site-packages/django/core/handlers/base.py", line 185, in _get_response
    response = wrapped_callback(request, *callback_args, **callback_kwargs)
  File "/Users/emirozbir/Desktop/desktop/gamer_trnet-yedek/epin/epinmain/views.py", line 37, in login
    render_to_response(request,"login.html",c)
  File "/usr/local/lib/python3.6/site-packages/django/shortcuts.py", line 21, in render_to_response
    content = loader.render_to_string(template_name, context, using=using)
  File "/usr/local/lib/python3.6/site-packages/django/template/loader.py", line 67, in render_to_string
    template = get_template(template_name, using=using)
  File "/usr/local/lib/python3.6/site-packages/django/template/loader.py", line 25, in get_template
    raise TemplateDoesNotExist(template_name, chain=chain)
django.template.exceptions.TemplateDoesNotExist: <WSGIRequest: GET '/accounts/login/'>
ERROR:django.request:Internal Server Error: /accounts/login/
Traceback (most recent call last):
  File "/usr/local/lib/python3.6/site-packages/django/core/handlers/exception.py", line 41, in inner
    response = get_response(request)
  File "/usr/local/lib/python3.6/site-packages/django/core/handlers/base.py", line 198, in _get_response
    "returned None instead." % (callback.__module__, view_name)
ValueError: The view epinmain.views.login didn't return an HttpResponse object. It returned None instead.
ERROR:django.request:Internal Server Error: /accounts/login/
Traceback (most recent call last):
  File "/usr/local/lib/python3.6/site-packages/django/core/handlers/exception.py", line 41, in inner
    response = get_response(request)
  File "/usr/local/lib/python3.6/site-packages/django/core/handlers/base.py", line 187, in _get_response
    response = self.process_exception_by_middleware(e, request)
  File "/usr/local/lib/python3.6/site-packages/django/core/handlers/base.py", line 185, in _get_response
    response = wrapped_callback(request, *callback_args, **callback_kwargs)
  File "/Users/emirozbir/Desktop/desktop/gamer_trnet-yedek/epin/epinmain/views.py", line 38, in login
    render_to_response(request, "login.html")
  File "/usr/local/lib/python3.6/site-packages/django/shortcuts.py", line 21, in render_to_response
    content = loader.render_to_string(template_name, context, using=using)
  File "/usr/local/lib/python3.6/site-packages/django/template/loader.py", line 67, in render_to_string
    template = get_template(template_name, using=using)
  File "/usr/local/lib/python3.6/site-packages/django/template/loader.py", line 25, in get_template
    raise TemplateDoesNotExist(template_name, chain=chain)
django.template.exceptions.TemplateDoesNotExist: <WSGIRequest: GET '/accounts/login/'>
ERROR:django.request:Internal Server Error: /accounts/login/
Traceback (most recent call last):
  File "/usr/local/lib/python3.6/site-packages/django/core/handlers/exception.py", line 41, in inner
    response = get_response(request)
  File "/usr/local/lib/python3.6/site-packages/django/core/handlers/base.py", line 187, in _get_response
    response = self.process_exception_by_middleware(e, request)
  File "/usr/local/lib/python3.6/site-packages/django/core/handlers/base.py", line 185, in _get_response
    response = wrapped_callback(request, *callback_args, **callback_kwargs)
  File "/Users/emirozbir/Desktop/desktop/gamer_trnet-yedek/epin/epinmain/views.py", line 39, in login
    render_to_response(request, "login.html")
  File "/usr/local/lib/python3.6/site-packages/django/shortcuts.py", line 21, in render_to_response
    content = loader.render_to_string(template_name, context, using=using)
  File "/usr/local/lib/python3.6/site-packages/django/template/loader.py", line 67, in render_to_string
    template = get_template(template_name, using=using)
  File "/usr/local/lib/python3.6/site-packages/django/template/loader.py", line 25, in get_template
    raise TemplateDoesNotExist(template_name, chain=chain)
django.template.exceptions.TemplateDoesNotExist: <WSGIRequest: GET '/accounts/login/'>
ERROR:django.request:Internal Server Error: /accounts/login/
Traceback (most recent call last):
  File "/usr/local/lib/python3.6/site-packages/django/core/handlers/exception.py", line 41, in inner
    response = get_response(request)
  File "/usr/local/lib/python3.6/site-packages/django/core/handlers/base.py", line 187, in _get_response
    response = self.process_exception_by_middleware(e, request)
  File "/usr/local/lib/python3.6/site-packages/django/core/handlers/base.py", line 185, in _get_response
    response = wrapped_callback(request, *callback_args, **callback_kwargs)
  File "/Users/emirozbir/Desktop/desktop/gamer_trnet-yedek/epin/epinmain/views.py", line 39, in login
    render_to_response(request, "login.html")
  File "/usr/local/lib/python3.6/site-packages/django/shortcuts.py", line 21, in render_to_response
    content = loader.render_to_string(template_name, context, using=using)
  File "/usr/local/lib/python3.6/site-packages/django/template/loader.py", line 67, in render_to_string
    template = get_template(template_name, using=using)
  File "/usr/local/lib/python3.6/site-packages/django/template/loader.py", line 25, in get_template
    raise TemplateDoesNotExist(template_name, chain=chain)
django.template.exceptions.TemplateDoesNotExist: <WSGIRequest: GET '/accounts/login/'>
ERROR:django.request:Internal Server Error: /accounts/login/
Traceback (most recent call last):
  File "/usr/local/lib/python3.6/site-packages/django/core/handlers/exception.py", line 41, in inner
    response = get_response(request)
  File "/usr/local/lib/python3.6/site-packages/django/core/handlers/base.py", line 187, in _get_response
    response = self.process_exception_by_middleware(e, request)
  File "/usr/local/lib/python3.6/site-packages/django/core/handlers/base.py", line 185, in _get_response
    response = wrapped_callback(request, *callback_args, **callback_kwargs)
  File "/Users/emirozbir/Desktop/desktop/gamer_trnet-yedek/epin/epinmain/views.py", line 39, in login
    render_to_response(request, "login.html")
  File "/usr/local/lib/python3.6/site-packages/django/shortcuts.py", line 21, in render_to_response
    content = loader.render_to_string(template_name, context, using=using)
  File "/usr/local/lib/python3.6/site-packages/django/template/loader.py", line 67, in render_to_string
    template = get_template(template_name, using=using)
  File "/usr/local/lib/python3.6/site-packages/django/template/loader.py", line 25, in get_template
    raise TemplateDoesNotExist(template_name, chain=chain)
django.template.exceptions.TemplateDoesNotExist: <WSGIRequest: GET '/accounts/login/'>
ERROR:django.request:Internal Server Error: /accounts/login/
Traceback (most recent call last):
  File "/usr/local/lib/python3.6/site-packages/django/core/handlers/exception.py", line 41, in inner
    response = get_response(request)
  File "/usr/local/lib/python3.6/site-packages/django/core/handlers/base.py", line 187, in _get_response
    response = self.process_exception_by_middleware(e, request)
  File "/usr/local/lib/python3.6/site-packages/django/core/handlers/base.py", line 185, in _get_response
    response = wrapped_callback(request, *callback_args, **callback_kwargs)
  File "/Users/emirozbir/Desktop/desktop/gamer_trnet-yedek/epin/epinmain/views.py", line 39, in login
    render_to_response(request, "login.html")
  File "/usr/local/lib/python3.6/site-packages/django/shortcuts.py", line 21, in render_to_response
    content = loader.render_to_string(template_name, context, using=using)
  File "/usr/local/lib/python3.6/site-packages/django/template/loader.py", line 67, in render_to_string
    template = get_template(template_name, using=using)
  File "/usr/local/lib/python3.6/site-packages/django/template/loader.py", line 25, in get_template
    raise TemplateDoesNotExist(template_name, chain=chain)
django.template.exceptions.TemplateDoesNotExist: <WSGIRequest: GET '/accounts/login/'>
ERROR:django.request:Internal Server Error: /accounts/login/
Traceback (most recent call last):
  File "/usr/local/lib/python3.6/site-packages/django/core/handlers/exception.py", line 41, in inner
    response = get_response(request)
  File "/usr/local/lib/python3.6/site-packages/django/core/handlers/base.py", line 187, in _get_response
    response = self.process_exception_by_middleware(e, request)
  File "/usr/local/lib/python3.6/site-packages/django/core/handlers/base.py", line 185, in _get_response
    response = wrapped_callback(request, *callback_args, **callback_kwargs)
  File "/Users/emirozbir/Desktop/desktop/gamer_trnet-yedek/epin/epinmain/views.py", line 39, in login
    render_to_response(request, "login.html")
  File "/usr/local/lib/python3.6/site-packages/django/shortcuts.py", line 21, in render_to_response
    content = loader.render_to_string(template_name, context, using=using)
  File "/usr/local/lib/python3.6/site-packages/django/template/loader.py", line 67, in render_to_string
    template = get_template(template_name, using=using)
  File "/usr/local/lib/python3.6/site-packages/django/template/loader.py", line 25, in get_template
    raise TemplateDoesNotExist(template_name, chain=chain)
django.template.exceptions.TemplateDoesNotExist: <WSGIRequest: GET '/accounts/login/'>
ERROR:django.request:Internal Server Error: /accounts/login/
Traceback (most recent call last):
  File "/usr/local/lib/python3.6/site-packages/django/core/handlers/exception.py", line 41, in inner
    response = get_response(request)
  File "/usr/local/lib/python3.6/site-packages/django/core/handlers/base.py", line 187, in _get_response
    response = self.process_exception_by_middleware(e, request)
  File "/usr/local/lib/python3.6/site-packages/django/core/handlers/base.py", line 185, in _get_response
    response = wrapped_callback(request, *callback_args, **callback_kwargs)
  File "/Users/emirozbir/Desktop/desktop/gamer_trnet-yedek/epin/epinmain/views.py", line 39, in login
    render_to_response(request, "login.html")
  File "/usr/local/lib/python3.6/site-packages/django/shortcuts.py", line 21, in render_to_response
    content = loader.render_to_string(template_name, context, using=using)
  File "/usr/local/lib/python3.6/site-packages/django/template/loader.py", line 67, in render_to_string
    template = get_template(template_name, using=using)
  File "/usr/local/lib/python3.6/site-packages/django/template/loader.py", line 25, in get_template
    raise TemplateDoesNotExist(template_name, chain=chain)
django.template.exceptions.TemplateDoesNotExist: <WSGIRequest: GET '/accounts/login/'>
ERROR:django.request:Internal Server Error: /accounts/login/
Traceback (most recent call last):
  File "/usr/local/lib/python3.6/site-packages/django/core/handlers/exception.py", line 41, in inner
    response = get_response(request)
  File "/usr/local/lib/python3.6/site-packages/django/core/handlers/base.py", line 187, in _get_response
    response = self.process_exception_by_middleware(e, request)
  File "/usr/local/lib/python3.6/site-packages/django/core/handlers/base.py", line 185, in _get_response
    response = wrapped_callback(request, *callback_args, **callback_kwargs)
  File "/Users/emirozbir/Desktop/desktop/gamer_trnet-yedek/epin/epinmain/views.py", line 39, in login
    render_to_response(request, "login.html")
  File "/usr/local/lib/python3.6/site-packages/django/shortcuts.py", line 21, in render_to_response
    content = loader.render_to_string(template_name, context, using=using)
  File "/usr/local/lib/python3.6/site-packages/django/template/loader.py", line 67, in render_to_string
    template = get_template(template_name, using=using)
  File "/usr/local/lib/python3.6/site-packages/django/template/loader.py", line 25, in get_template
    raise TemplateDoesNotExist(template_name, chain=chain)
django.template.exceptions.TemplateDoesNotExist: <WSGIRequest: GET '/accounts/login/'>
ERROR:django.request:Internal Server Error: /accounts/login/
Traceback (most recent call last):
  File "/usr/local/lib/python3.6/site-packages/django/core/handlers/exception.py", line 41, in inner
    response = get_response(request)
  File "/usr/local/lib/python3.6/site-packages/django/core/handlers/base.py", line 187, in _get_response
    response = self.process_exception_by_middleware(e, request)
  File "/usr/local/lib/python3.6/site-packages/django/core/handlers/base.py", line 185, in _get_response
    response = wrapped_callback(request, *callback_args, **callback_kwargs)
  File "/Users/emirozbir/Desktop/desktop/gamer_trnet-yedek/epin/epinmain/views.py", line 39, in login
    render_to_response(request, "login.html")
  File "/usr/local/lib/python3.6/site-packages/django/shortcuts.py", line 21, in render_to_response
    content = loader.render_to_string(template_name, context, using=using)
  File "/usr/local/lib/python3.6/site-packages/django/template/loader.py", line 67, in render_to_string
    template = get_template(template_name, using=using)
  File "/usr/local/lib/python3.6/site-packages/django/template/loader.py", line 25, in get_template
    raise TemplateDoesNotExist(template_name, chain=chain)
django.template.exceptions.TemplateDoesNotExist: <WSGIRequest: GET '/accounts/login/'>
WARNING:django.request:Not Found: /accounts/login
ERROR:django.request:Internal Server Error: /accounts/login/
Traceback (most recent call last):
  File "/usr/local/lib/python3.6/site-packages/django/core/handlers/exception.py", line 41, in inner
    response = get_response(request)
  File "/usr/local/lib/python3.6/site-packages/django/core/handlers/base.py", line 187, in _get_response
    response = self.process_exception_by_middleware(e, request)
  File "/usr/local/lib/python3.6/site-packages/django/core/handlers/base.py", line 185, in _get_response
    response = wrapped_callback(request, *callback_args, **callback_kwargs)
  File "/Users/emirozbir/Desktop/desktop/gamer_trnet-yedek/epin/epinmain/views.py", line 39, in login
    render_to_response(request, "login.html")
  File "/usr/local/lib/python3.6/site-packages/django/shortcuts.py", line 21, in render_to_response
    content = loader.render_to_string(template_name, context, using=using)
  File "/usr/local/lib/python3.6/site-packages/django/template/loader.py", line 67, in render_to_string
    template = get_template(template_name, using=using)
  File "/usr/local/lib/python3.6/site-packages/django/template/loader.py", line 25, in get_template
    raise TemplateDoesNotExist(template_name, chain=chain)
django.template.exceptions.TemplateDoesNotExist: <WSGIRequest: GET '/accounts/login/'>
ERROR:django.request:Internal Server Error: /accounts/login/
Traceback (most recent call last):
  File "/usr/local/lib/python3.6/site-packages/django/core/handlers/exception.py", line 41, in inner
    response = get_response(request)
  File "/usr/local/lib/python3.6/site-packages/django/core/handlers/base.py", line 187, in _get_response
    response = self.process_exception_by_middleware(e, request)
  File "/usr/local/lib/python3.6/site-packages/django/core/handlers/base.py", line 185, in _get_response
    response = wrapped_callback(request, *callback_args, **callback_kwargs)
  File "/Users/emirozbir/Desktop/desktop/gamer_trnet-yedek/epin/epinmain/views.py", line 39, in login
    render_to_response(request, "login.html")
  File "/usr/local/lib/python3.6/site-packages/django/shortcuts.py", line 21, in render_to_response
    content = loader.render_to_string(template_name, context, using=using)
  File "/usr/local/lib/python3.6/site-packages/django/template/loader.py", line 67, in render_to_string
    template = get_template(template_name, using=using)
  File "/usr/local/lib/python3.6/site-packages/django/template/loader.py", line 25, in get_template
    raise TemplateDoesNotExist(template_name, chain=chain)
django.template.exceptions.TemplateDoesNotExist: <WSGIRequest: GET '/accounts/login/'>
ERROR:django.request:Internal Server Error: /accounts/login/
Traceback (most recent call last):
  File "/usr/local/lib/python3.6/site-packages/django/core/handlers/exception.py", line 41, in inner
    response = get_response(request)
  File "/usr/local/lib/python3.6/site-packages/django/core/handlers/base.py", line 187, in _get_response
    response = self.process_exception_by_middleware(e, request)
  File "/usr/local/lib/python3.6/site-packages/django/core/handlers/base.py", line 185, in _get_response
    response = wrapped_callback(request, *callback_args, **callback_kwargs)
  File "/Users/emirozbir/Desktop/desktop/gamer_trnet-yedek/epin/epinmain/views.py", line 39, in login
    render_to_response(request, "login.html")
  File "/usr/local/lib/python3.6/site-packages/django/shortcuts.py", line 21, in render_to_response
    content = loader.render_to_string(template_name, context, using=using)
  File "/usr/local/lib/python3.6/site-packages/django/template/loader.py", line 67, in render_to_string
    template = get_template(template_name, using=using)
  File "/usr/local/lib/python3.6/site-packages/django/template/loader.py", line 25, in get_template
    raise TemplateDoesNotExist(template_name, chain=chain)
django.template.exceptions.TemplateDoesNotExist: <WSGIRequest: GET '/accounts/login/'>
ERROR:django.request:Internal Server Error: /accounts/login/
Traceback (most recent call last):
  File "/usr/local/lib/python3.6/site-packages/django/core/handlers/exception.py", line 41, in inner
    response = get_response(request)
  File "/usr/local/lib/python3.6/site-packages/django/core/handlers/base.py", line 187, in _get_response
    response = self.process_exception_by_middleware(e, request)
  File "/usr/local/lib/python3.6/site-packages/django/core/handlers/base.py", line 185, in _get_response
    response = wrapped_callback(request, *callback_args, **callback_kwargs)
  File "/Users/emirozbir/Desktop/desktop/gamer_trnet-yedek/epin/epinmain/views.py", line 39, in login
    render_to_response(request, "login.html")
  File "/usr/local/lib/python3.6/site-packages/django/shortcuts.py", line 21, in render_to_response
    content = loader.render_to_string(template_name, context, using=using)
  File "/usr/local/lib/python3.6/site-packages/django/template/loader.py", line 67, in render_to_string
    template = get_template(template_name, using=using)
  File "/usr/local/lib/python3.6/site-packages/django/template/loader.py", line 25, in get_template
    raise TemplateDoesNotExist(template_name, chain=chain)
django.template.exceptions.TemplateDoesNotExist: <WSGIRequest: GET '/accounts/login/'>
ERROR:django.request:Internal Server Error: /accounts/login/
Traceback (most recent call last):
  File "/usr/local/lib/python3.6/site-packages/django/core/handlers/exception.py", line 41, in inner
    response = get_response(request)
  File "/usr/local/lib/python3.6/site-packages/django/core/handlers/base.py", line 187, in _get_response
    response = self.process_exception_by_middleware(e, request)
  File "/usr/local/lib/python3.6/site-packages/django/core/handlers/base.py", line 185, in _get_response
    response = wrapped_callback(request, *callback_args, **callback_kwargs)
  File "/Users/emirozbir/Desktop/desktop/gamer_trnet-yedek/epin/epinmain/views.py", line 39, in login
    render_to_response(request, "login.html")
  File "/usr/local/lib/python3.6/site-packages/django/shortcuts.py", line 21, in render_to_response
    content = loader.render_to_string(template_name, context, using=using)
  File "/usr/local/lib/python3.6/site-packages/django/template/loader.py", line 67, in render_to_string
    template = get_template(template_name, using=using)
  File "/usr/local/lib/python3.6/site-packages/django/template/loader.py", line 25, in get_template
    raise TemplateDoesNotExist(template_name, chain=chain)
django.template.exceptions.TemplateDoesNotExist: <WSGIRequest: GET '/accounts/login/'>
ERROR:django.request:Internal Server Error: /accounts/login/
Traceback (most recent call last):
  File "/usr/local/lib/python3.6/site-packages/django/core/handlers/exception.py", line 41, in inner
    response = get_response(request)
  File "/usr/local/lib/python3.6/site-packages/django/core/handlers/base.py", line 187, in _get_response
    response = self.process_exception_by_middleware(e, request)
  File "/usr/local/lib/python3.6/site-packages/django/core/handlers/base.py", line 185, in _get_response
    response = wrapped_callback(request, *callback_args, **callback_kwargs)
  File "/Users/emirozbir/Desktop/desktop/gamer_trnet-yedek/epin/epinmain/views.py", line 39, in login
    render_to_response(request, "login.html")
  File "/usr/local/lib/python3.6/site-packages/django/shortcuts.py", line 21, in render_to_response
    content = loader.render_to_string(template_name, context, using=using)
  File "/usr/local/lib/python3.6/site-packages/django/template/loader.py", line 67, in render_to_string
    template = get_template(template_name, using=using)
  File "/usr/local/lib/python3.6/site-packages/django/template/loader.py", line 25, in get_template
    raise TemplateDoesNotExist(template_name, chain=chain)
django.template.exceptions.TemplateDoesNotExist: <WSGIRequest: GET '/accounts/login/'>
ERROR:django.request:Internal Server Error: /accounts/login/
Traceback (most recent call last):
  File "/usr/local/lib/python3.6/site-packages/django/core/handlers/exception.py", line 41, in inner
    response = get_response(request)
  File "/usr/local/lib/python3.6/site-packages/django/core/handlers/base.py", line 187, in _get_response
    response = self.process_exception_by_middleware(e, request)
  File "/usr/local/lib/python3.6/site-packages/django/core/handlers/base.py", line 185, in _get_response
    response = wrapped_callback(request, *callback_args, **callback_kwargs)
  File "/Users/emirozbir/Desktop/desktop/gamer_trnet-yedek/epin/epinmain/views.py", line 39, in login
    render_to_response(request, "login.html")
  File "/usr/local/lib/python3.6/site-packages/django/shortcuts.py", line 21, in render_to_response
    content = loader.render_to_string(template_name, context, using=using)
  File "/usr/local/lib/python3.6/site-packages/django/template/loader.py", line 67, in render_to_string
    template = get_template(template_name, using=using)
  File "/usr/local/lib/python3.6/site-packages/django/template/loader.py", line 25, in get_template
    raise TemplateDoesNotExist(template_name, chain=chain)
django.template.exceptions.TemplateDoesNotExist: <WSGIRequest: GET '/accounts/login/'>
ERROR:django.request:Internal Server Error: /accounts/login/
Traceback (most recent call last):
  File "/usr/local/lib/python3.6/site-packages/django/core/handlers/exception.py", line 41, in inner
    response = get_response(request)
  File "/usr/local/lib/python3.6/site-packages/django/core/handlers/base.py", line 187, in _get_response
    response = self.process_exception_by_middleware(e, request)
  File "/usr/local/lib/python3.6/site-packages/django/core/handlers/base.py", line 185, in _get_response
    response = wrapped_callback(request, *callback_args, **callback_kwargs)
  File "/Users/emirozbir/Desktop/desktop/gamer_trnet-yedek/epin/epinmain/views.py", line 34, in login
    render_to_response(request, "login.html")
  File "/usr/local/lib/python3.6/site-packages/django/shortcuts.py", line 21, in render_to_response
    content = loader.render_to_string(template_name, context, using=using)
  File "/usr/local/lib/python3.6/site-packages/django/template/loader.py", line 67, in render_to_string
    template = get_template(template_name, using=using)
  File "/usr/local/lib/python3.6/site-packages/django/template/loader.py", line 25, in get_template
    raise TemplateDoesNotExist(template_name, chain=chain)
django.template.exceptions.TemplateDoesNotExist: <WSGIRequest: GET '/accounts/login/'>
ERROR:django.request:Internal Server Error: /accounts/login/
Traceback (most recent call last):
  File "/usr/local/lib/python3.6/site-packages/django/core/handlers/exception.py", line 41, in inner
    response = get_response(request)
  File "/usr/local/lib/python3.6/site-packages/django/core/handlers/base.py", line 187, in _get_response
    response = self.process_exception_by_middleware(e, request)
  File "/usr/local/lib/python3.6/site-packages/django/core/handlers/base.py", line 185, in _get_response
    response = wrapped_callback(request, *callback_args, **callback_kwargs)
  File "/Users/emirozbir/Desktop/desktop/gamer_trnet-yedek/epin/epinmain/views.py", line 34, in login
    render_to_response(request, "login.html")
  File "/usr/local/lib/python3.6/site-packages/django/shortcuts.py", line 21, in render_to_response
    content = loader.render_to_string(template_name, context, using=using)
  File "/usr/local/lib/python3.6/site-packages/django/template/loader.py", line 67, in render_to_string
    template = get_template(template_name, using=using)
  File "/usr/local/lib/python3.6/site-packages/django/template/loader.py", line 25, in get_template
    raise TemplateDoesNotExist(template_name, chain=chain)
django.template.exceptions.TemplateDoesNotExist: <WSGIRequest: GET '/accounts/login/'>
WARNING:django.request:Not Found: /accounts/index
ERROR:django.request:Internal Server Error: /accounts/index/
Traceback (most recent call last):
  File "/usr/local/lib/python3.6/site-packages/django/core/handlers/exception.py", line 41, in inner
    response = get_response(request)
  File "/usr/local/lib/python3.6/site-packages/django/core/handlers/base.py", line 187, in _get_response
    response = self.process_exception_by_middleware(e, request)
  File "/usr/local/lib/python3.6/site-packages/django/core/handlers/base.py", line 185, in _get_response
    response = wrapped_callback(request, *callback_args, **callback_kwargs)
  File "/Users/emirozbir/Desktop/desktop/gamer_trnet-yedek/epin/epinmain/views.py", line 25, in index
    render("index.html")
TypeError: render() missing 1 required positional argument: 'template_name'
ERROR:django.request:Internal Server Error: /accounts/index/
Traceback (most recent call last):
  File "/usr/local/lib/python3.6/site-packages/django/core/handlers/exception.py", line 41, in inner
    response = get_response(request)
  File "/usr/local/lib/python3.6/site-packages/django/core/handlers/base.py", line 198, in _get_response
    "returned None instead." % (callback.__module__, view_name)
ValueError: The view epinmain.views.index didn't return an HttpResponse object. It returned None instead.
ERROR:django.request:Internal Server Error: /accounts/index/
Traceback (most recent call last):
  File "/usr/local/lib/python3.6/site-packages/django/core/handlers/exception.py", line 41, in inner
    response = get_response(request)
  File "/usr/local/lib/python3.6/site-packages/django/core/handlers/base.py", line 187, in _get_response
    response = self.process_exception_by_middleware(e, request)
  File "/usr/local/lib/python3.6/site-packages/django/core/handlers/base.py", line 185, in _get_response
    response = wrapped_callback(request, *callback_args, **callback_kwargs)
  File "/Users/emirozbir/Desktop/desktop/gamer_trnet-yedek/epin/epinmain/views.py", line 30, in index
    return render("login.html")
TypeError: render() missing 1 required positional argument: 'template_name'
WARNING:django.request:Not Found: /account/index/
WARNING:django.request:Not Found: /account/index/
WARNING:django.request:Not Found: /account/index/
ERROR:django.request:Internal Server Error: /accounts/login/
Traceback (most recent call last):
  File "/usr/local/lib/python3.6/site-packages/django/core/handlers/exception.py", line 41, in inner
    response = get_response(request)
  File "/usr/local/lib/python3.6/site-packages/django/core/handlers/base.py", line 198, in _get_response
    "returned None instead." % (callback.__module__, view_name)
ValueError: The view epinmain.views.index didn't return an HttpResponse object. It returned None instead.
ERROR:django.request:Internal Server Error: /accounts/login/
Traceback (most recent call last):
  File "/usr/local/lib/python3.6/site-packages/django/core/handlers/exception.py", line 41, in inner
    response = get_response(request)
  File "/usr/local/lib/python3.6/site-packages/django/core/handlers/base.py", line 198, in _get_response
    "returned None instead." % (callback.__module__, view_name)
ValueError: The view epinmain.views.index didn't return an HttpResponse object. It returned None instead.
WARNING:django.request:Not Found: /accounts/index/
WARNING:django.request:Not Found: /accounts/index
WARNING:django.request:Not Found: /accounts/index/
WARNING:django.request:Not Found: /accounts/index/
WARNING:django.request:Not Found: /accounts/index/
WARNING:django.request:Not Found: /account/index/
WARNING:django.request:Not Found: /account/index/
WARNING:django.request:Not Found: /account/login/
ERROR:django.request:Internal Server Error: /accounts/auth/
Traceback (most recent call last):
  File "/usr/local/lib/python3.6/site-packages/django/core/handlers/exception.py", line 41, in inner
    response = get_response(request)
  File "/usr/local/lib/python3.6/site-packages/django/core/handlers/base.py", line 187, in _get_response
    response = self.process_exception_by_middleware(e, request)
  File "/usr/local/lib/python3.6/site-packages/django/core/handlers/base.py", line 185, in _get_response
    response = wrapped_callback(request, *callback_args, **callback_kwargs)
  File "/Users/emirozbir/Desktop/desktop/gamer_trnet-yedek/epin/epinmain/views.py", line 36, in auth
    user = auth._authenticate(username=username,password=password)
AttributeError: 'function' object has no attribute '_authenticate'
ERROR:django.request:Internal Server Error: /accounts/auth/
Traceback (most recent call last):
  File "/usr/local/lib/python3.6/site-packages/django/core/handlers/exception.py", line 41, in inner
    response = get_response(request)
  File "/usr/local/lib/python3.6/site-packages/django/core/handlers/base.py", line 187, in _get_response
    response = self.process_exception_by_middleware(e, request)
  File "/usr/local/lib/python3.6/site-packages/django/core/handlers/base.py", line 185, in _get_response
    response = wrapped_callback(request, *callback_args, **callback_kwargs)
  File "/Users/emirozbir/Desktop/desktop/gamer_trnet-yedek/epin/epinmain/views.py", line 36, in auth
    user = auth.authenticate(username=username,password=password)
AttributeError: 'function' object has no attribute 'authenticate'
ERROR:django.request:Internal Server Error: /accounts/auth/
Traceback (most recent call last):
  File "/usr/local/lib/python3.6/site-packages/django/core/handlers/exception.py", line 41, in inner
    response = get_response(request)
  File "/usr/local/lib/python3.6/site-packages/django/core/handlers/base.py", line 187, in _get_response
    response = self.process_exception_by_middleware(e, request)
  File "/usr/local/lib/python3.6/site-packages/django/core/handlers/base.py", line 185, in _get_response
    response = wrapped_callback(request, *callback_args, **callback_kwargs)
  File "/Users/emirozbir/Desktop/desktop/gamer_trnet-yedek/epin/epinmain/views.py", line 36, in auth
    user = auth.authenticate(username=username,password=password)
AttributeError: 'function' object has no attribute 'authenticate'
ERROR:django.request:Internal Server Error: /accounts/auth/
Traceback (most recent call last):
  File "/usr/local/lib/python3.6/site-packages/django/core/handlers/exception.py", line 41, in inner
    response = get_response(request)
  File "/usr/local/lib/python3.6/site-packages/django/core/handlers/base.py", line 187, in _get_response
    response = self.process_exception_by_middleware(e, request)
  File "/usr/local/lib/python3.6/site-packages/django/core/handlers/base.py", line 185, in _get_response
    response = wrapped_callback(request, *callback_args, **callback_kwargs)
  File "/Users/emirozbir/Desktop/desktop/gamer_trnet-yedek/epin/epinmain/views.py", line 36, in auth
    user = auth.authenticate(username=username,password=password)
AttributeError: 'function' object has no attribute 'authenticate'
ERROR:django.request:Internal Server Error: /accounts/auth/
Traceback (most recent call last):
  File "/usr/local/lib/python3.6/site-packages/django/core/handlers/exception.py", line 41, in inner
    response = get_response(request)
  File "/usr/local/lib/python3.6/site-packages/django/core/handlers/base.py", line 187, in _get_response
    response = self.process_exception_by_middleware(e, request)
  File "/usr/local/lib/python3.6/site-packages/django/core/handlers/base.py", line 185, in _get_response
    response = wrapped_callback(request, *callback_args, **callback_kwargs)
  File "/Users/emirozbir/Desktop/desktop/gamer_trnet-yedek/epin/epinmain/views.py", line 36, in auth
    user = auth.authenticate(username=username,password=password)
AttributeError: 'function' object has no attribute 'authenticate'
ERROR:django.request:Internal Server Error: /accounts/auth/
Traceback (most recent call last):
  File "/usr/local/lib/python3.6/site-packages/django/core/handlers/exception.py", line 41, in inner
    response = get_response(request)
  File "/usr/local/lib/python3.6/site-packages/django/core/handlers/base.py", line 187, in _get_response
    response = self.process_exception_by_middleware(e, request)
  File "/usr/local/lib/python3.6/site-packages/django/core/handlers/base.py", line 185, in _get_response
    response = wrapped_callback(request, *callback_args, **callback_kwargs)
  File "/Users/emirozbir/Desktop/desktop/gamer_trnet-yedek/epin/epinmain/views.py", line 36, in auth
    user = auth.authenticate(username=username,password=password)
AttributeError: 'function' object has no attribute 'authenticate'
ERROR:django.request:Internal Server Error: /accounts/auth/
Traceback (most recent call last):
  File "/usr/local/lib/python3.6/site-packages/django/core/handlers/exception.py", line 41, in inner
    response = get_response(request)
  File "/usr/local/lib/python3.6/site-packages/django/core/handlers/base.py", line 198, in _get_response
    "returned None instead." % (callback.__module__, view_name)
ValueError: The view epinmain.views.auth didn't return an HttpResponse object. It returned None instead.
ERROR:django.request:Internal Server Error: /accounts/auth/
Traceback (most recent call last):
  File "/usr/local/lib/python3.6/site-packages/django/core/handlers/exception.py", line 41, in inner
    response = get_response(request)
  File "/usr/local/lib/python3.6/site-packages/django/core/handlers/base.py", line 187, in _get_response
    response = self.process_exception_by_middleware(e, request)
  File "/usr/local/lib/python3.6/site-packages/django/core/handlers/base.py", line 185, in _get_response
    response = wrapped_callback(request, *callback_args, **callback_kwargs)
  File "/Users/emirozbir/Desktop/desktop/gamer_trnet-yedek/epin/epinmain/views.py", line 41, in auth
    user = auth.authenticate(username=username,password=password)
AttributeError: 'function' object has no attribute 'authenticate'
ERROR:django.request:Internal Server Error: /accounts/auth/
Traceback (most recent call last):
  File "/usr/local/lib/python3.6/site-packages/django/core/handlers/exception.py", line 41, in inner
    response = get_response(request)
  File "/usr/local/lib/python3.6/site-packages/django/core/handlers/base.py", line 187, in _get_response
    response = self.process_exception_by_middleware(e, request)
  File "/usr/local/lib/python3.6/site-packages/django/core/handlers/base.py", line 185, in _get_response
    response = wrapped_callback(request, *callback_args, **callback_kwargs)
  File "/Users/emirozbir/Desktop/desktop/gamer_trnet-yedek/epin/epinmain/views.py", line 39, in auth
    user = auth.authenticate(username=username,password=password)
AttributeError: 'function' object has no attribute 'authenticate'
ERROR:django.request:Internal Server Error: /accounts/auth/
Traceback (most recent call last):
  File "/usr/local/lib/python3.6/site-packages/django/core/handlers/exception.py", line 41, in inner
    response = get_response(request)
  File "/usr/local/lib/python3.6/site-packages/django/core/handlers/base.py", line 187, in _get_response
    response = self.process_exception_by_middleware(e, request)
  File "/usr/local/lib/python3.6/site-packages/django/core/handlers/base.py", line 185, in _get_response
    response = wrapped_callback(request, *callback_args, **callback_kwargs)
  File "/Users/emirozbir/Desktop/desktop/gamer_trnet-yedek/epin/epinmain/views.py", line 39, in auth
    user = auth.authenticate(username=username,password=password)
AttributeError: 'function' object has no attribute 'authenticate'
ERROR:django.request:Internal Server Error: /accounts/auth/
Traceback (most recent call last):
  File "/usr/local/lib/python3.6/site-packages/django/core/handlers/exception.py", line 41, in inner
    response = get_response(request)
  File "/usr/local/lib/python3.6/site-packages/django/core/handlers/base.py", line 187, in _get_response
    response = self.process_exception_by_middleware(e, request)
  File "/usr/local/lib/python3.6/site-packages/django/core/handlers/base.py", line 185, in _get_response
    response = wrapped_callback(request, *callback_args, **callback_kwargs)
  File "/Users/emirozbir/Desktop/desktop/gamer_trnet-yedek/epin/epinmain/views.py", line 39, in auth
    user = auth.authenticate(username=username,password=password)
AttributeError: 'function' object has no attribute 'authenticate'
WARNING:django.security.csrf:Forbidden (CSRF token missing or incorrect.): /accounts/auth/
WARNING:django.request:Not Found: /games/
WARNING:django.request:Not Found: /games
WARNING:django.request:Not Found: /game
WARNING:django.request:Not Found: /games/games/
WARNING:django.request:Not Found: /games/games/
WARNING:django.request:Not Found: /games/games/
WARNING:django.request:Not Found: /accounts/logout/
WARNING:django.request:Not Found: /account/login/
WARNING:django.request:Not Found: /account/login/
WARNING:django.request:Not Found: /account/login/
WARNING:django.request:Not Found: /account/logout/
WARNING:django.request:Not Found: /account/logout/
WARNING:django.request:Not Found: /account/logout/
WARNING:django.request:Not Found: /accounts/login
WARNING:django.request:Not Found: /games/
WARNING:django.request:Not Found: /games/
ERROR:django.request:Internal Server Error: /accounts/signup/
Traceback (most recent call last):
  File "/usr/local/lib/python3.6/site-packages/django/db/backends/utils.py", line 65, in execute
    return self.cursor.execute(sql, params)
psycopg2.IntegrityError: duplicate key value violates unique constraint "auth_user_username_key"
DETAIL:  Key (username)=() already exists.


The above exception was the direct cause of the following exception:

Traceback (most recent call last):
  File "/usr/local/lib/python3.6/site-packages/django/core/handlers/exception.py", line 41, in inner
    response = get_response(request)
  File "/usr/local/lib/python3.6/site-packages/django/core/handlers/base.py", line 187, in _get_response
    response = self.process_exception_by_middleware(e, request)
  File "/usr/local/lib/python3.6/site-packages/django/core/handlers/base.py", line 185, in _get_response
    response = wrapped_callback(request, *callback_args, **callback_kwargs)
  File "/Users/emirozbir/Desktop/desktop/gamer_trnet-yedek/epin/epinmain/views.py", line 73, in createaccounts
    user_obj = User.objects.create(username="{}".format(name), email="{}".format(email), password="{}".format(password))
  File "/usr/local/lib/python3.6/site-packages/django/db/models/manager.py", line 85, in manager_method
    return getattr(self.get_queryset(), name)(*args, **kwargs)
  File "/usr/local/lib/python3.6/site-packages/django/db/models/query.py", line 394, in create
    obj.save(force_insert=True, using=self.db)
  File "/usr/local/lib/python3.6/site-packages/django/contrib/auth/base_user.py", line 80, in save
    super(AbstractBaseUser, self).save(*args, **kwargs)
  File "/usr/local/lib/python3.6/site-packages/django/db/models/base.py", line 806, in save
    force_update=force_update, update_fields=update_fields)
  File "/usr/local/lib/python3.6/site-packages/django/db/models/base.py", line 836, in save_base
    updated = self._save_table(raw, cls, force_insert, force_update, using, update_fields)
  File "/usr/local/lib/python3.6/site-packages/django/db/models/base.py", line 922, in _save_table
    result = self._do_insert(cls._base_manager, using, fields, update_pk, raw)
  File "/usr/local/lib/python3.6/site-packages/django/db/models/base.py", line 961, in _do_insert
    using=using, raw=raw)
  File "/usr/local/lib/python3.6/site-packages/django/db/models/manager.py", line 85, in manager_method
    return getattr(self.get_queryset(), name)(*args, **kwargs)
  File "/usr/local/lib/python3.6/site-packages/django/db/models/query.py", line 1063, in _insert
    return query.get_compiler(using=using).execute_sql(return_id)
  File "/usr/local/lib/python3.6/site-packages/django/db/models/sql/compiler.py", line 1099, in execute_sql
    cursor.execute(sql, params)
  File "/usr/local/lib/python3.6/site-packages/django/db/backends/utils.py", line 80, in execute
    return super(CursorDebugWrapper, self).execute(sql, params)
  File "/usr/local/lib/python3.6/site-packages/django/db/backends/utils.py", line 65, in execute
    return self.cursor.execute(sql, params)
  File "/usr/local/lib/python3.6/site-packages/django/db/utils.py", line 94, in __exit__
    six.reraise(dj_exc_type, dj_exc_value, traceback)
  File "/usr/local/lib/python3.6/site-packages/django/utils/six.py", line 685, in reraise
    raise value.with_traceback(tb)
  File "/usr/local/lib/python3.6/site-packages/django/db/backends/utils.py", line 65, in execute
    return self.cursor.execute(sql, params)
django.db.utils.IntegrityError: duplicate key value violates unique constraint "auth_user_username_key"
DETAIL:  Key (username)=() already exists.

ERROR:django.request:Internal Server Error: /accounts/signup/
Traceback (most recent call last):
  File "/usr/local/lib/python3.6/site-packages/django/db/backends/utils.py", line 65, in execute
    return self.cursor.execute(sql, params)
psycopg2.IntegrityError: duplicate key value violates unique constraint "auth_user_username_key"
DETAIL:  Key (username)=() already exists.


The above exception was the direct cause of the following exception:

Traceback (most recent call last):
  File "/usr/local/lib/python3.6/site-packages/django/core/handlers/exception.py", line 41, in inner
    response = get_response(request)
  File "/usr/local/lib/python3.6/site-packages/django/core/handlers/base.py", line 187, in _get_response
    response = self.process_exception_by_middleware(e, request)
  File "/usr/local/lib/python3.6/site-packages/django/core/handlers/base.py", line 185, in _get_response
    response = wrapped_callback(request, *callback_args, **callback_kwargs)
  File "/Users/emirozbir/Desktop/desktop/gamer_trnet-yedek/epin/epinmain/views.py", line 73, in createaccounts
    user_obj = User.objects.create(username="{}".format(name), email="{}".format(email), password="{}".format(password))
  File "/usr/local/lib/python3.6/site-packages/django/db/models/manager.py", line 85, in manager_method
    return getattr(self.get_queryset(), name)(*args, **kwargs)
  File "/usr/local/lib/python3.6/site-packages/django/db/models/query.py", line 394, in create
    obj.save(force_insert=True, using=self.db)
  File "/usr/local/lib/python3.6/site-packages/django/contrib/auth/base_user.py", line 80, in save
    super(AbstractBaseUser, self).save(*args, **kwargs)
  File "/usr/local/lib/python3.6/site-packages/django/db/models/base.py", line 806, in save
    force_update=force_update, update_fields=update_fields)
  File "/usr/local/lib/python3.6/site-packages/django/db/models/base.py", line 836, in save_base
    updated = self._save_table(raw, cls, force_insert, force_update, using, update_fields)
  File "/usr/local/lib/python3.6/site-packages/django/db/models/base.py", line 922, in _save_table
    result = self._do_insert(cls._base_manager, using, fields, update_pk, raw)
  File "/usr/local/lib/python3.6/site-packages/django/db/models/base.py", line 961, in _do_insert
    using=using, raw=raw)
  File "/usr/local/lib/python3.6/site-packages/django/db/models/manager.py", line 85, in manager_method
    return getattr(self.get_queryset(), name)(*args, **kwargs)
  File "/usr/local/lib/python3.6/site-packages/django/db/models/query.py", line 1063, in _insert
    return query.get_compiler(using=using).execute_sql(return_id)
  File "/usr/local/lib/python3.6/site-packages/django/db/models/sql/compiler.py", line 1099, in execute_sql
    cursor.execute(sql, params)
  File "/usr/local/lib/python3.6/site-packages/django/db/backends/utils.py", line 80, in execute
    return super(CursorDebugWrapper, self).execute(sql, params)
  File "/usr/local/lib/python3.6/site-packages/django/db/backends/utils.py", line 65, in execute
    return self.cursor.execute(sql, params)
  File "/usr/local/lib/python3.6/site-packages/django/db/utils.py", line 94, in __exit__
    six.reraise(dj_exc_type, dj_exc_value, traceback)
  File "/usr/local/lib/python3.6/site-packages/django/utils/six.py", line 685, in reraise
    raise value.with_traceback(tb)
  File "/usr/local/lib/python3.6/site-packages/django/db/backends/utils.py", line 65, in execute
    return self.cursor.execute(sql, params)
django.db.utils.IntegrityError: duplicate key value violates unique constraint "auth_user_username_key"
DETAIL:  Key (username)=() already exists.

ERROR:django.request:Internal Server Error: /accounts/signup/
Traceback (most recent call last):
  File "/usr/local/lib/python3.6/site-packages/django/db/backends/utils.py", line 65, in execute
    return self.cursor.execute(sql, params)
psycopg2.IntegrityError: duplicate key value violates unique constraint "auth_user_username_key"
DETAIL:  Key (username)=() already exists.


The above exception was the direct cause of the following exception:

Traceback (most recent call last):
  File "/usr/local/lib/python3.6/site-packages/django/core/handlers/exception.py", line 41, in inner
    response = get_response(request)
  File "/usr/local/lib/python3.6/site-packages/django/core/handlers/base.py", line 187, in _get_response
    response = self.process_exception_by_middleware(e, request)
  File "/usr/local/lib/python3.6/site-packages/django/core/handlers/base.py", line 185, in _get_response
    response = wrapped_callback(request, *callback_args, **callback_kwargs)
  File "/Users/emirozbir/Desktop/desktop/gamer_trnet-yedek/epin/epinmain/views.py", line 73, in createaccounts
    user_obj = User.objects.create(username="{}".format(name), email="{}".format(email), password="{}".format(password))
  File "/usr/local/lib/python3.6/site-packages/django/db/models/manager.py", line 85, in manager_method
    return getattr(self.get_queryset(), name)(*args, **kwargs)
  File "/usr/local/lib/python3.6/site-packages/django/db/models/query.py", line 394, in create
    obj.save(force_insert=True, using=self.db)
  File "/usr/local/lib/python3.6/site-packages/django/contrib/auth/base_user.py", line 80, in save
    super(AbstractBaseUser, self).save(*args, **kwargs)
  File "/usr/local/lib/python3.6/site-packages/django/db/models/base.py", line 806, in save
    force_update=force_update, update_fields=update_fields)
  File "/usr/local/lib/python3.6/site-packages/django/db/models/base.py", line 836, in save_base
    updated = self._save_table(raw, cls, force_insert, force_update, using, update_fields)
  File "/usr/local/lib/python3.6/site-packages/django/db/models/base.py", line 922, in _save_table
    result = self._do_insert(cls._base_manager, using, fields, update_pk, raw)
  File "/usr/local/lib/python3.6/site-packages/django/db/models/base.py", line 961, in _do_insert
    using=using, raw=raw)
  File "/usr/local/lib/python3.6/site-packages/django/db/models/manager.py", line 85, in manager_method
    return getattr(self.get_queryset(), name)(*args, **kwargs)
  File "/usr/local/lib/python3.6/site-packages/django/db/models/query.py", line 1063, in _insert
    return query.get_compiler(using=using).execute_sql(return_id)
  File "/usr/local/lib/python3.6/site-packages/django/db/models/sql/compiler.py", line 1099, in execute_sql
    cursor.execute(sql, params)
  File "/usr/local/lib/python3.6/site-packages/django/db/backends/utils.py", line 80, in execute
    return super(CursorDebugWrapper, self).execute(sql, params)
  File "/usr/local/lib/python3.6/site-packages/django/db/backends/utils.py", line 65, in execute
    return self.cursor.execute(sql, params)
  File "/usr/local/lib/python3.6/site-packages/django/db/utils.py", line 94, in __exit__
    six.reraise(dj_exc_type, dj_exc_value, traceback)
  File "/usr/local/lib/python3.6/site-packages/django/utils/six.py", line 685, in reraise
    raise value.with_traceback(tb)
  File "/usr/local/lib/python3.6/site-packages/django/db/backends/utils.py", line 65, in execute
    return self.cursor.execute(sql, params)
django.db.utils.IntegrityError: duplicate key value violates unique constraint "auth_user_username_key"
DETAIL:  Key (username)=() already exists.

ERROR:django.request:Internal Server Error: /accounts/signup/
Traceback (most recent call last):
  File "/usr/local/lib/python3.6/site-packages/django/core/handlers/exception.py", line 41, in inner
    response = get_response(request)
  File "/usr/local/lib/python3.6/site-packages/django/core/handlers/base.py", line 187, in _get_response
    response = self.process_exception_by_middleware(e, request)
  File "/usr/local/lib/python3.6/site-packages/django/core/handlers/base.py", line 185, in _get_response
    response = wrapped_callback(request, *callback_args, **callback_kwargs)
  File "/Users/emirozbir/Desktop/desktop/gamer_trnet-yedek/epin/epinmain/views.py", line 62, in signup
    return render('signup.html', c)
  File "/usr/local/lib/python3.6/site-packages/django/shortcuts.py", line 30, in render
    content = loader.render_to_string(template_name, context, request, using=using)
  File "/usr/local/lib/python3.6/site-packages/django/template/loader.py", line 67, in render_to_string
    template = get_template(template_name, using=using)
  File "/usr/local/lib/python3.6/site-packages/django/template/loader.py", line 25, in get_template
    raise TemplateDoesNotExist(template_name, chain=chain)
django.template.exceptions.TemplateDoesNotExist: {'csrf_token': <SimpleLazyObject: <function csrf.<locals>._get_val at 0x104482268>>}
WARNING:django.request:Not Found: /accounts/create_user/
WARNING:django.request:Not Found: /accounts/createaccounts/
ERROR:django.request:Internal Server Error: /accounts/createaccounts/
Traceback (most recent call last):
  File "/usr/local/lib/python3.6/site-packages/django/db/backends/utils.py", line 65, in execute
    return self.cursor.execute(sql, params)
psycopg2.IntegrityError: duplicate key value violates unique constraint "auth_user_username_key"
DETAIL:  Key (username)=(Emir) already exists.


The above exception was the direct cause of the following exception:

Traceback (most recent call last):
  File "/usr/local/lib/python3.6/site-packages/django/core/handlers/exception.py", line 41, in inner
    response = get_response(request)
  File "/usr/local/lib/python3.6/site-packages/django/core/handlers/base.py", line 187, in _get_response
    response = self.process_exception_by_middleware(e, request)
  File "/usr/local/lib/python3.6/site-packages/django/core/handlers/base.py", line 185, in _get_response
    response = wrapped_callback(request, *callback_args, **callback_kwargs)
  File "/Users/emirozbir/Desktop/desktop/gamer_trnet-yedek/epin/epinmain/views.py", line 73, in createaccounts
    user_obj = User.objects.create(username="{}".format(name), email="{}".format(email), password="{}".format(password))
  File "/usr/local/lib/python3.6/site-packages/django/db/models/manager.py", line 85, in manager_method
    return getattr(self.get_queryset(), name)(*args, **kwargs)
  File "/usr/local/lib/python3.6/site-packages/django/db/models/query.py", line 394, in create
    obj.save(force_insert=True, using=self.db)
  File "/usr/local/lib/python3.6/site-packages/django/contrib/auth/base_user.py", line 80, in save
    super(AbstractBaseUser, self).save(*args, **kwargs)
  File "/usr/local/lib/python3.6/site-packages/django/db/models/base.py", line 806, in save
    force_update=force_update, update_fields=update_fields)
  File "/usr/local/lib/python3.6/site-packages/django/db/models/base.py", line 836, in save_base
    updated = self._save_table(raw, cls, force_insert, force_update, using, update_fields)
  File "/usr/local/lib/python3.6/site-packages/django/db/models/base.py", line 922, in _save_table
    result = self._do_insert(cls._base_manager, using, fields, update_pk, raw)
  File "/usr/local/lib/python3.6/site-packages/django/db/models/base.py", line 961, in _do_insert
    using=using, raw=raw)
  File "/usr/local/lib/python3.6/site-packages/django/db/models/manager.py", line 85, in manager_method
    return getattr(self.get_queryset(), name)(*args, **kwargs)
  File "/usr/local/lib/python3.6/site-packages/django/db/models/query.py", line 1063, in _insert
    return query.get_compiler(using=using).execute_sql(return_id)
  File "/usr/local/lib/python3.6/site-packages/django/db/models/sql/compiler.py", line 1099, in execute_sql
    cursor.execute(sql, params)
  File "/usr/local/lib/python3.6/site-packages/django/db/backends/utils.py", line 80, in execute
    return super(CursorDebugWrapper, self).execute(sql, params)
  File "/usr/local/lib/python3.6/site-packages/django/db/backends/utils.py", line 65, in execute
    return self.cursor.execute(sql, params)
  File "/usr/local/lib/python3.6/site-packages/django/db/utils.py", line 94, in __exit__
    six.reraise(dj_exc_type, dj_exc_value, traceback)
  File "/usr/local/lib/python3.6/site-packages/django/utils/six.py", line 685, in reraise
    raise value.with_traceback(tb)
  File "/usr/local/lib/python3.6/site-packages/django/db/backends/utils.py", line 65, in execute
    return self.cursor.execute(sql, params)
django.db.utils.IntegrityError: duplicate key value violates unique constraint "auth_user_username_key"
DETAIL:  Key (username)=(Emir) already exists.

ERROR:django.request:Internal Server Error: /accounts/createaccounts/
Traceback (most recent call last):
  File "/usr/local/lib/python3.6/site-packages/django/db/backends/utils.py", line 65, in execute
    return self.cursor.execute(sql, params)
psycopg2.IntegrityError: duplicate key value violates unique constraint "auth_user_username_key"
DETAIL:  Key (username)=(Emir) already exists.


The above exception was the direct cause of the following exception:

Traceback (most recent call last):
  File "/usr/local/lib/python3.6/site-packages/django/core/handlers/exception.py", line 41, in inner
    response = get_response(request)
  File "/usr/local/lib/python3.6/site-packages/django/core/handlers/base.py", line 187, in _get_response
    response = self.process_exception_by_middleware(e, request)
  File "/usr/local/lib/python3.6/site-packages/django/core/handlers/base.py", line 185, in _get_response
    response = wrapped_callback(request, *callback_args, **callback_kwargs)
  File "/Users/emirozbir/Desktop/desktop/gamer_trnet-yedek/epin/epinmain/views.py", line 73, in createaccounts
    user_obj = User.objects.create(username="{}".format(name), email="{}".format(email), password="{}".format(password))
  File "/usr/local/lib/python3.6/site-packages/django/db/models/manager.py", line 85, in manager_method
    return getattr(self.get_queryset(), name)(*args, **kwargs)
  File "/usr/local/lib/python3.6/site-packages/django/db/models/query.py", line 394, in create
    obj.save(force_insert=True, using=self.db)
  File "/usr/local/lib/python3.6/site-packages/django/contrib/auth/base_user.py", line 80, in save
    super(AbstractBaseUser, self).save(*args, **kwargs)
  File "/usr/local/lib/python3.6/site-packages/django/db/models/base.py", line 806, in save
    force_update=force_update, update_fields=update_fields)
  File "/usr/local/lib/python3.6/site-packages/django/db/models/base.py", line 836, in save_base
    updated = self._save_table(raw, cls, force_insert, force_update, using, update_fields)
  File "/usr/local/lib/python3.6/site-packages/django/db/models/base.py", line 922, in _save_table
    result = self._do_insert(cls._base_manager, using, fields, update_pk, raw)
  File "/usr/local/lib/python3.6/site-packages/django/db/models/base.py", line 961, in _do_insert
    using=using, raw=raw)
  File "/usr/local/lib/python3.6/site-packages/django/db/models/manager.py", line 85, in manager_method
    return getattr(self.get_queryset(), name)(*args, **kwargs)
  File "/usr/local/lib/python3.6/site-packages/django/db/models/query.py", line 1063, in _insert
    return query.get_compiler(using=using).execute_sql(return_id)
  File "/usr/local/lib/python3.6/site-packages/django/db/models/sql/compiler.py", line 1099, in execute_sql
    cursor.execute(sql, params)
  File "/usr/local/lib/python3.6/site-packages/django/db/backends/utils.py", line 80, in execute
    return super(CursorDebugWrapper, self).execute(sql, params)
  File "/usr/local/lib/python3.6/site-packages/django/db/backends/utils.py", line 65, in execute
    return self.cursor.execute(sql, params)
  File "/usr/local/lib/python3.6/site-packages/django/db/utils.py", line 94, in __exit__
    six.reraise(dj_exc_type, dj_exc_value, traceback)
  File "/usr/local/lib/python3.6/site-packages/django/utils/six.py", line 685, in reraise
    raise value.with_traceback(tb)
  File "/usr/local/lib/python3.6/site-packages/django/db/backends/utils.py", line 65, in execute
    return self.cursor.execute(sql, params)
django.db.utils.IntegrityError: duplicate key value violates unique constraint "auth_user_username_key"
DETAIL:  Key (username)=(Emir) already exists.

WARNING:django.request:Not Found: /accounts/logouy/
ERROR:django.request:Internal Server Error: /accounts/createaccounts/
Traceback (most recent call last):
  File "/usr/local/lib/python3.6/site-packages/django/core/handlers/exception.py", line 41, in inner
    response = get_response(request)
  File "/usr/local/lib/python3.6/site-packages/django/core/handlers/base.py", line 187, in _get_response
    response = self.process_exception_by_middleware(e, request)
  File "/usr/local/lib/python3.6/site-packages/django/core/handlers/base.py", line 185, in _get_response
    response = wrapped_callback(request, *callback_args, **callback_kwargs)
  File "/Users/emirozbir/Desktop/desktop/gamer_trnet-yedek/epin/epinmain/views.py", line 79, in createaccounts
    profile_data.save()
  File "/usr/local/lib/python3.6/site-packages/django/db/models/base.py", line 806, in save
    force_update=force_update, update_fields=update_fields)
  File "/usr/local/lib/python3.6/site-packages/django/db/models/base.py", line 836, in save_base
    updated = self._save_table(raw, cls, force_insert, force_update, using, update_fields)
  File "/usr/local/lib/python3.6/site-packages/django/db/models/base.py", line 903, in _save_table
    forced_update)
  File "/usr/local/lib/python3.6/site-packages/django/db/models/base.py", line 953, in _do_update
    return filtered._update(values) > 0
  File "/usr/local/lib/python3.6/site-packages/django/db/models/query.py", line 664, in _update
    return query.get_compiler(self.db).execute_sql(CURSOR)
  File "/usr/local/lib/python3.6/site-packages/django/db/models/sql/compiler.py", line 1191, in execute_sql
    cursor = super(SQLUpdateCompiler, self).execute_sql(result_type)
  File "/usr/local/lib/python3.6/site-packages/django/db/models/sql/compiler.py", line 863, in execute_sql
    sql, params = self.as_sql()
  File "/usr/local/lib/python3.6/site-packages/django/db/models/sql/compiler.py", line 1157, in as_sql
    val = field.get_db_prep_save(val, connection=self.connection)
  File "/usr/local/lib/python3.6/site-packages/django/db/models/fields/__init__.py", line 770, in get_db_prep_save
    prepared=False)
  File "/usr/local/lib/python3.6/site-packages/django/db/models/fields/__init__.py", line 1301, in get_db_prep_value
    value = self.get_prep_value(value)
  File "/usr/local/lib/python3.6/site-packages/django/db/models/fields/__init__.py", line 1296, in get_prep_value
    return self.to_python(value)
  File "/usr/local/lib/python3.6/site-packages/django/db/models/fields/__init__.py", line 1271, in to_python
    params={'value': value},
django.core.exceptions.ValidationError: ["'' value has an invalid date format. It must be in YYYY-MM-DD format."]
ERROR:django.request:Internal Server Error: /accounts/createaccounts/
Traceback (most recent call last):
  File "/usr/local/lib/python3.6/site-packages/django/db/backends/utils.py", line 65, in execute
    return self.cursor.execute(sql, params)
psycopg2.IntegrityError: duplicate key value violates unique constraint "auth_user_username_key"
DETAIL:  Key (username)=(emirozbir22) already exists.


The above exception was the direct cause of the following exception:

Traceback (most recent call last):
  File "/usr/local/lib/python3.6/site-packages/django/core/handlers/exception.py", line 41, in inner
    response = get_response(request)
  File "/usr/local/lib/python3.6/site-packages/django/core/handlers/base.py", line 187, in _get_response
    response = self.process_exception_by_middleware(e, request)
  File "/usr/local/lib/python3.6/site-packages/django/core/handlers/base.py", line 185, in _get_response
    response = wrapped_callback(request, *callback_args, **callback_kwargs)
  File "/Users/emirozbir/Desktop/desktop/gamer_trnet-yedek/epin/epinmain/views.py", line 73, in createaccounts
    user_obj = User.objects.create(username="{}".format(username), email="{}".format(email), password="{}".format(password))
  File "/usr/local/lib/python3.6/site-packages/django/db/models/manager.py", line 85, in manager_method
    return getattr(self.get_queryset(), name)(*args, **kwargs)
  File "/usr/local/lib/python3.6/site-packages/django/db/models/query.py", line 394, in create
    obj.save(force_insert=True, using=self.db)
  File "/usr/local/lib/python3.6/site-packages/django/contrib/auth/base_user.py", line 80, in save
    super(AbstractBaseUser, self).save(*args, **kwargs)
  File "/usr/local/lib/python3.6/site-packages/django/db/models/base.py", line 806, in save
    force_update=force_update, update_fields=update_fields)
  File "/usr/local/lib/python3.6/site-packages/django/db/models/base.py", line 836, in save_base
    updated = self._save_table(raw, cls, force_insert, force_update, using, update_fields)
  File "/usr/local/lib/python3.6/site-packages/django/db/models/base.py", line 922, in _save_table
    result = self._do_insert(cls._base_manager, using, fields, update_pk, raw)
  File "/usr/local/lib/python3.6/site-packages/django/db/models/base.py", line 961, in _do_insert
    using=using, raw=raw)
  File "/usr/local/lib/python3.6/site-packages/django/db/models/manager.py", line 85, in manager_method
    return getattr(self.get_queryset(), name)(*args, **kwargs)
  File "/usr/local/lib/python3.6/site-packages/django/db/models/query.py", line 1063, in _insert
    return query.get_compiler(using=using).execute_sql(return_id)
  File "/usr/local/lib/python3.6/site-packages/django/db/models/sql/compiler.py", line 1099, in execute_sql
    cursor.execute(sql, params)
  File "/usr/local/lib/python3.6/site-packages/django/db/backends/utils.py", line 80, in execute
    return super(CursorDebugWrapper, self).execute(sql, params)
  File "/usr/local/lib/python3.6/site-packages/django/db/backends/utils.py", line 65, in execute
    return self.cursor.execute(sql, params)
  File "/usr/local/lib/python3.6/site-packages/django/db/utils.py", line 94, in __exit__
    six.reraise(dj_exc_type, dj_exc_value, traceback)
  File "/usr/local/lib/python3.6/site-packages/django/utils/six.py", line 685, in reraise
    raise value.with_traceback(tb)
  File "/usr/local/lib/python3.6/site-packages/django/db/backends/utils.py", line 65, in execute
    return self.cursor.execute(sql, params)
django.db.utils.IntegrityError: duplicate key value violates unique constraint "auth_user_username_key"
DETAIL:  Key (username)=(emirozbir22) already exists.

WARNING:django.request:Not Found: /accounts/logi/
WARNING:django.request:Not Found: /account/login/
WARNING:django.request:Not Found: /accounts/logput/
WARNING:django.request:Not Found: /games/logput/
WARNING:django.request:Not Found: /games/logout/
WARNING:django.request:Not Found: /games/logout/
WARNING:django.request:Not Found: /games/logout/
WARNING:django.request:Not Found: /
WARNING:django.security.csrf:Forbidden (CSRF token missing or incorrect.): /accounts/auth/
WARNING:django.request:Not Found: /account/logout/
ERROR:django.request:Internal Server Error: /accounts/createaccounts/
Traceback (most recent call last):
  File "/usr/local/lib/python3.6/site-packages/django/core/handlers/exception.py", line 41, in inner
    response = get_response(request)
  File "/usr/local/lib/python3.6/site-packages/django/core/handlers/base.py", line 187, in _get_response
    response = self.process_exception_by_middleware(e, request)
  File "/usr/local/lib/python3.6/site-packages/django/core/handlers/base.py", line 185, in _get_response
    response = wrapped_callback(request, *callback_args, **callback_kwargs)
  File "/Users/emirozbir/Desktop/desktop/gamer_trnet-yedek/epin/epinmain/views.py", line 75, in createaccounts
    user_obj.set_password(password="{}".format(password))
TypeError: set_password() got an unexpected keyword argument 'password'
ERROR:django.request:Internal Server Error: /accounts/createaccounts/
Traceback (most recent call last):
  File "/usr/local/lib/python3.6/site-packages/django/db/backends/utils.py", line 65, in execute
    return self.cursor.execute(sql, params)
psycopg2.IntegrityError: duplicate key value violates unique constraint "auth_user_username_key"
DETAIL:  Key (username)=(asddeneme) already exists.


The above exception was the direct cause of the following exception:

Traceback (most recent call last):
  File "/usr/local/lib/python3.6/site-packages/django/core/handlers/exception.py", line 41, in inner
    response = get_response(request)
  File "/usr/local/lib/python3.6/site-packages/django/core/handlers/base.py", line 187, in _get_response
    response = self.process_exception_by_middleware(e, request)
  File "/usr/local/lib/python3.6/site-packages/django/core/handlers/base.py", line 185, in _get_response
    response = wrapped_callback(request, *callback_args, **callback_kwargs)
  File "/Users/emirozbir/Desktop/desktop/gamer_trnet-yedek/epin/epinmain/views.py", line 73, in createaccounts
    user_obj = User.objects.create(username="{}".format(username), email="{}".format(email), password="{}".format(password))
  File "/usr/local/lib/python3.6/site-packages/django/db/models/manager.py", line 85, in manager_method
    return getattr(self.get_queryset(), name)(*args, **kwargs)
  File "/usr/local/lib/python3.6/site-packages/django/db/models/query.py", line 394, in create
    obj.save(force_insert=True, using=self.db)
  File "/usr/local/lib/python3.6/site-packages/django/contrib/auth/base_user.py", line 80, in save
    super(AbstractBaseUser, self).save(*args, **kwargs)
  File "/usr/local/lib/python3.6/site-packages/django/db/models/base.py", line 806, in save
    force_update=force_update, update_fields=update_fields)
  File "/usr/local/lib/python3.6/site-packages/django/db/models/base.py", line 836, in save_base
    updated = self._save_table(raw, cls, force_insert, force_update, using, update_fields)
  File "/usr/local/lib/python3.6/site-packages/django/db/models/base.py", line 922, in _save_table
    result = self._do_insert(cls._base_manager, using, fields, update_pk, raw)
  File "/usr/local/lib/python3.6/site-packages/django/db/models/base.py", line 961, in _do_insert
    using=using, raw=raw)
  File "/usr/local/lib/python3.6/site-packages/django/db/models/manager.py", line 85, in manager_method
    return getattr(self.get_queryset(), name)(*args, **kwargs)
  File "/usr/local/lib/python3.6/site-packages/django/db/models/query.py", line 1063, in _insert
    return query.get_compiler(using=using).execute_sql(return_id)
  File "/usr/local/lib/python3.6/site-packages/django/db/models/sql/compiler.py", line 1099, in execute_sql
    cursor.execute(sql, params)
  File "/usr/local/lib/python3.6/site-packages/django/db/backends/utils.py", line 80, in execute
    return super(CursorDebugWrapper, self).execute(sql, params)
  File "/usr/local/lib/python3.6/site-packages/django/db/backends/utils.py", line 65, in execute
    return self.cursor.execute(sql, params)
  File "/usr/local/lib/python3.6/site-packages/django/db/utils.py", line 94, in __exit__
    six.reraise(dj_exc_type, dj_exc_value, traceback)
  File "/usr/local/lib/python3.6/site-packages/django/utils/six.py", line 685, in reraise
    raise value.with_traceback(tb)
  File "/usr/local/lib/python3.6/site-packages/django/db/backends/utils.py", line 65, in execute
    return self.cursor.execute(sql, params)
django.db.utils.IntegrityError: duplicate key value violates unique constraint "auth_user_username_key"
DETAIL:  Key (username)=(asddeneme) already exists.

WARNING:django.security.csrf:Forbidden (CSRF token missing or incorrect.): /admin/login/
WARNING:django.request:Not Found: /accounts/logput/
WARNING:django.request:Not Found: /accounts/singup/
WARNING:django.request:Not Found: /
WARNING:django.request:Not Found: /favicon.ico
WARNING:django.request:Not Found: /
WARNING:django.request:Not Found: /favicon.ico
ERROR:django.request:Internal Server Error: /games/games/
Traceback (most recent call last):
  File "/usr/local/lib/python3.6/site-packages/django/core/handlers/exception.py", line 41, in inner
    response = get_response(request)
  File "/usr/local/lib/python3.6/site-packages/django/core/handlers/base.py", line 187, in _get_response
    response = self.process_exception_by_middleware(e, request)
  File "/usr/local/lib/python3.6/site-packages/django/core/handlers/base.py", line 185, in _get_response
    response = wrapped_callback(request, *callback_args, **callback_kwargs)
  File "/Users/emirozbir/Desktop/desktop/gamer_trnet-yedek/epin/epinmain/views.py", line 35, in games
    return render_to_response("games.html",{"games":fetch_all_game()})
  File "/Users/emirozbir/Desktop/desktop/gamer_trnet-yedek/epin/epinmain/views.py", line 31, in fetch_all_game
    return games.fechall()
AttributeError: 'NoneType' object has no attribute 'fechall'
ERROR:django.request:Internal Server Error: /games/games/
Traceback (most recent call last):
  File "/usr/local/lib/python3.6/site-packages/django/core/handlers/exception.py", line 41, in inner
    response = get_response(request)
  File "/usr/local/lib/python3.6/site-packages/django/core/handlers/base.py", line 187, in _get_response
    response = self.process_exception_by_middleware(e, request)
  File "/usr/local/lib/python3.6/site-packages/django/core/handlers/base.py", line 185, in _get_response
    response = wrapped_callback(request, *callback_args, **callback_kwargs)
  File "/Users/emirozbir/Desktop/desktop/gamer_trnet-yedek/epin/epinmain/views.py", line 35, in games
    return render_to_response("games.html",{"games":fetch_all_game()})
  File "/Users/emirozbir/Desktop/desktop/gamer_trnet-yedek/epin/epinmain/views.py", line 31, in fetch_all_game
    return games.fetchall()
AttributeError: 'NoneType' object has no attribute 'fetchall'
