DEBUG:root:USER admin FETCHED GAMES
DEBUG:root:USER admin FETCHED GAMES
DEBUG:root:USER admin FETCHED GAMES
DEBUG:root:USER AnonymousUser LOGOUT 
DEBUG:root:USER AnonymousUser CREATED  
DEBUG:root:USER emirozbir FETCHED GAMES
DEBUG:root:USER emirozbir FETCHED GAMES
DEBUG:root:USER emirozbir FETCHED GAMES
DEBUG:root:USER emirozbir FETCHED GAMES
DEBUG:root:USER emirozbir FETCHED GAMES
DEBUG:root:USER emirozbir FETCHED GAMES
WARNING:django.request:Not Found: /account/login/
DEBUG:root:USER AnonymousUser LOGOUT 
DEBUG:root:USER AnonymousUser LOGOUT 
DEBUG:root:USER emirozbir FETCHED GAMES
ERROR:django.request:Internal Server Error: /games/games/
Traceback (most recent call last):
  File "/usr/local/lib/python3.6/site-packages/django/db/backends/utils.py", line 63, in execute
    return self.cursor.execute(sql)
psycopg2.ProgrammingError: relation "game" does not exist
LINE 1: SELECT * FROM game
                      ^


The above exception was the direct cause of the following exception:

Traceback (most recent call last):
  File "/usr/local/lib/python3.6/site-packages/django/core/handlers/exception.py", line 41, in inner
    response = get_response(request)
  File "/usr/local/lib/python3.6/site-packages/django/core/handlers/base.py", line 187, in _get_response
    response = self.process_exception_by_middleware(e, request)
  File "/usr/local/lib/python3.6/site-packages/django/core/handlers/base.py", line 185, in _get_response
    response = wrapped_callback(request, *callback_args, **callback_kwargs)
  File "/Users/emirozbir/Desktop/desktop/gamer_trnet-yedek/epin/epinmain/views.py", line 47, in games
    return render_to_response("tr/oyunlar.html",{"game_data":fetch_all_game()})
  File "/Users/emirozbir/Desktop/desktop/gamer_trnet-yedek/epin/epinmain/views.py", line 35, in fetch_all_game
    games = cursor.execute("SELECT * FROM game")
  File "/usr/local/lib/python3.6/site-packages/django/db/backends/utils.py", line 80, in execute
    return super(CursorDebugWrapper, self).execute(sql, params)
  File "/usr/local/lib/python3.6/site-packages/django/db/backends/utils.py", line 65, in execute
    return self.cursor.execute(sql, params)
  File "/usr/local/lib/python3.6/site-packages/django/db/utils.py", line 94, in __exit__
    six.reraise(dj_exc_type, dj_exc_value, traceback)
  File "/usr/local/lib/python3.6/site-packages/django/utils/six.py", line 685, in reraise
    raise value.with_traceback(tb)
  File "/usr/local/lib/python3.6/site-packages/django/db/backends/utils.py", line 63, in execute
    return self.cursor.execute(sql)
django.db.utils.ProgrammingError: relation "game" does not exist
LINE 1: SELECT * FROM game
                      ^

ERROR:django.request:Internal Server Error: /accounts/login/
Traceback (most recent call last):
  File "/usr/local/lib/python3.6/site-packages/django/core/handlers/exception.py", line 41, in inner
    response = get_response(request)
  File "/usr/local/lib/python3.6/site-packages/django/core/handlers/base.py", line 187, in _get_response
    response = self.process_exception_by_middleware(e, request)
  File "/usr/local/lib/python3.6/site-packages/django/core/handlers/base.py", line 185, in _get_response
    response = wrapped_callback(request, *callback_args, **callback_kwargs)
  File "/Users/emirozbir/Desktop/desktop/gamer_trnet-yedek/epin/epinmain/views.py", line 62, in index
    return render(request,"eng/index.html")
  File "/usr/local/lib/python3.6/site-packages/django/shortcuts.py", line 30, in render
    content = loader.render_to_string(template_name, context, request, using=using)
  File "/usr/local/lib/python3.6/site-packages/django/template/loader.py", line 67, in render_to_string
    template = get_template(template_name, using=using)
  File "/usr/local/lib/python3.6/site-packages/django/template/loader.py", line 25, in get_template
    raise TemplateDoesNotExist(template_name, chain=chain)
django.template.exceptions.TemplateDoesNotExist: eng/index.html
WARNING:django.request:Not Found: /account/login/
ERROR:django.request:Internal Server Error: /accounts/login/
Traceback (most recent call last):
  File "/usr/local/lib/python3.6/site-packages/django/core/handlers/exception.py", line 41, in inner
    response = get_response(request)
  File "/usr/local/lib/python3.6/site-packages/django/core/handlers/base.py", line 187, in _get_response
    response = self.process_exception_by_middleware(e, request)
  File "/usr/local/lib/python3.6/site-packages/django/core/handlers/base.py", line 185, in _get_response
    response = wrapped_callback(request, *callback_args, **callback_kwargs)
  File "/Users/emirozbir/Desktop/desktop/gamer_trnet-yedek/epin/epinmain/views.py", line 62, in index
    return render(request,"eng/index.html")
  File "/usr/local/lib/python3.6/site-packages/django/shortcuts.py", line 30, in render
    content = loader.render_to_string(template_name, context, request, using=using)
  File "/usr/local/lib/python3.6/site-packages/django/template/loader.py", line 67, in render_to_string
    template = get_template(template_name, using=using)
  File "/usr/local/lib/python3.6/site-packages/django/template/loader.py", line 25, in get_template
    raise TemplateDoesNotExist(template_name, chain=chain)
django.template.exceptions.TemplateDoesNotExist: eng/index.html
WARNING:django.request:Not Found: /account/login/
ERROR:django.request:Internal Server Error: /accounts/login/
Traceback (most recent call last):
  File "/usr/local/lib/python3.6/site-packages/django/core/handlers/exception.py", line 41, in inner
    response = get_response(request)
  File "/usr/local/lib/python3.6/site-packages/django/core/handlers/base.py", line 187, in _get_response
    response = self.process_exception_by_middleware(e, request)
  File "/usr/local/lib/python3.6/site-packages/django/core/handlers/base.py", line 185, in _get_response
    response = wrapped_callback(request, *callback_args, **callback_kwargs)
  File "/Users/emirozbir/Desktop/desktop/gamer_trnet-yedek/epin/epinmain/views.py", line 62, in index
    return render(request,"tr/index.html")
  File "/usr/local/lib/python3.6/site-packages/django/shortcuts.py", line 30, in render
    content = loader.render_to_string(template_name, context, request, using=using)
  File "/usr/local/lib/python3.6/site-packages/django/template/loader.py", line 67, in render_to_string
    template = get_template(template_name, using=using)
  File "/usr/local/lib/python3.6/site-packages/django/template/loader.py", line 25, in get_template
    raise TemplateDoesNotExist(template_name, chain=chain)
django.template.exceptions.TemplateDoesNotExist: tr/index.html
WARNING:django.request:Not Found: /favicon.ico
DEBUG:root:USER AnonymousUser LOGOUT 
WARNING:django.request:Not Found: /favicon.ico
DEBUG:root:USER emirozbir FETCHED GAMES
ERROR:django.request:Internal Server Error: /games/games/
Traceback (most recent call last):
  File "/usr/local/lib/python3.6/site-packages/django/db/backends/utils.py", line 63, in execute
    return self.cursor.execute(sql)
psycopg2.ProgrammingError: relation "game" does not exist
LINE 1: SELECT * FROM game
                      ^


The above exception was the direct cause of the following exception:

Traceback (most recent call last):
  File "/usr/local/lib/python3.6/site-packages/django/core/handlers/exception.py", line 41, in inner
    response = get_response(request)
  File "/usr/local/lib/python3.6/site-packages/django/core/handlers/base.py", line 187, in _get_response
    response = self.process_exception_by_middleware(e, request)
  File "/usr/local/lib/python3.6/site-packages/django/core/handlers/base.py", line 185, in _get_response
    response = wrapped_callback(request, *callback_args, **callback_kwargs)
  File "/Users/emirozbir/Desktop/desktop/gamer_trnet-yedek/epin/epinmain/views.py", line 47, in games
    return render_to_response("tr/oyunlar.html",{"game_data":fetch_all_game()})
  File "/Users/emirozbir/Desktop/desktop/gamer_trnet-yedek/epin/epinmain/views.py", line 35, in fetch_all_game
    games = cursor.execute("SELECT * FROM game")
  File "/usr/local/lib/python3.6/site-packages/django/db/backends/utils.py", line 80, in execute
    return super(CursorDebugWrapper, self).execute(sql, params)
  File "/usr/local/lib/python3.6/site-packages/django/db/backends/utils.py", line 65, in execute
    return self.cursor.execute(sql, params)
  File "/usr/local/lib/python3.6/site-packages/django/db/utils.py", line 94, in __exit__
    six.reraise(dj_exc_type, dj_exc_value, traceback)
  File "/usr/local/lib/python3.6/site-packages/django/utils/six.py", line 685, in reraise
    raise value.with_traceback(tb)
  File "/usr/local/lib/python3.6/site-packages/django/db/backends/utils.py", line 63, in execute
    return self.cursor.execute(sql)
django.db.utils.ProgrammingError: relation "game" does not exist
LINE 1: SELECT * FROM game
                      ^

DEBUG:root:USER emirozbir FETCHED GAMES
ERROR:django.request:Internal Server Error: /games/games/
Traceback (most recent call last):
  File "/usr/local/lib/python3.6/site-packages/django/db/backends/utils.py", line 63, in execute
    return self.cursor.execute(sql)
psycopg2.ProgrammingError: relation "game" does not exist
LINE 1: SELECT * FROM game
                      ^


The above exception was the direct cause of the following exception:

Traceback (most recent call last):
  File "/usr/local/lib/python3.6/site-packages/django/core/handlers/exception.py", line 41, in inner
    response = get_response(request)
  File "/usr/local/lib/python3.6/site-packages/django/core/handlers/base.py", line 187, in _get_response
    response = self.process_exception_by_middleware(e, request)
  File "/usr/local/lib/python3.6/site-packages/django/core/handlers/base.py", line 185, in _get_response
    response = wrapped_callback(request, *callback_args, **callback_kwargs)
  File "/Users/emirozbir/Desktop/desktop/gamer_trnet-yedek/epin/epinmain/views.py", line 47, in games
    return render_to_response("tr/oyunlar.html",{"game_data":fetch_all_game()})
  File "/Users/emirozbir/Desktop/desktop/gamer_trnet-yedek/epin/epinmain/views.py", line 35, in fetch_all_game
    games = cursor.execute("SELECT * FROM game")
  File "/usr/local/lib/python3.6/site-packages/django/db/backends/utils.py", line 80, in execute
    return super(CursorDebugWrapper, self).execute(sql, params)
  File "/usr/local/lib/python3.6/site-packages/django/db/backends/utils.py", line 65, in execute
    return self.cursor.execute(sql, params)
  File "/usr/local/lib/python3.6/site-packages/django/db/utils.py", line 94, in __exit__
    six.reraise(dj_exc_type, dj_exc_value, traceback)
  File "/usr/local/lib/python3.6/site-packages/django/utils/six.py", line 685, in reraise
    raise value.with_traceback(tb)
  File "/usr/local/lib/python3.6/site-packages/django/db/backends/utils.py", line 63, in execute
    return self.cursor.execute(sql)
django.db.utils.ProgrammingError: relation "game" does not exist
LINE 1: SELECT * FROM game
                      ^

DEBUG:root:USER AnonymousUser LOGOUT 
DEBUG:root:USER emirozbir FETCHED GAMES
ERROR:django.request:Internal Server Error: /games/games/
Traceback (most recent call last):
  File "/usr/local/lib/python3.6/site-packages/django/db/backends/utils.py", line 63, in execute
    return self.cursor.execute(sql)
psycopg2.ProgrammingError: relation "game" does not exist
LINE 1: SELECT * FROM game
                      ^


The above exception was the direct cause of the following exception:

Traceback (most recent call last):
  File "/usr/local/lib/python3.6/site-packages/django/core/handlers/exception.py", line 41, in inner
    response = get_response(request)
  File "/usr/local/lib/python3.6/site-packages/django/core/handlers/base.py", line 187, in _get_response
    response = self.process_exception_by_middleware(e, request)
  File "/usr/local/lib/python3.6/site-packages/django/core/handlers/base.py", line 185, in _get_response
    response = wrapped_callback(request, *callback_args, **callback_kwargs)
  File "/Users/emirozbir/Desktop/desktop/gamer_trnet-yedek/epin/epinmain/views.py", line 47, in games
    return render_to_response("tr/oyunlar.html",{"game_data":fetch_all_game()})
  File "/Users/emirozbir/Desktop/desktop/gamer_trnet-yedek/epin/epinmain/views.py", line 35, in fetch_all_game
    games = cursor.execute("SELECT * FROM game")
  File "/usr/local/lib/python3.6/site-packages/django/db/backends/utils.py", line 80, in execute
    return super(CursorDebugWrapper, self).execute(sql, params)
  File "/usr/local/lib/python3.6/site-packages/django/db/backends/utils.py", line 65, in execute
    return self.cursor.execute(sql, params)
  File "/usr/local/lib/python3.6/site-packages/django/db/utils.py", line 94, in __exit__
    six.reraise(dj_exc_type, dj_exc_value, traceback)
  File "/usr/local/lib/python3.6/site-packages/django/utils/six.py", line 685, in reraise
    raise value.with_traceback(tb)
  File "/usr/local/lib/python3.6/site-packages/django/db/backends/utils.py", line 63, in execute
    return self.cursor.execute(sql)
django.db.utils.ProgrammingError: relation "game" does not exist
LINE 1: SELECT * FROM game
                      ^

DEBUG:root:USER emirozbir FETCHED GAMES
ERROR:django.request:Internal Server Error: /games/games/
Traceback (most recent call last):
  File "/usr/local/lib/python3.6/site-packages/django/db/backends/utils.py", line 63, in execute
    return self.cursor.execute(sql)
psycopg2.ProgrammingError: relation "game" does not exist
LINE 1: SELECT * FROM game
                      ^


The above exception was the direct cause of the following exception:

Traceback (most recent call last):
  File "/usr/local/lib/python3.6/site-packages/django/core/handlers/exception.py", line 41, in inner
    response = get_response(request)
  File "/usr/local/lib/python3.6/site-packages/django/core/handlers/base.py", line 187, in _get_response
    response = self.process_exception_by_middleware(e, request)
  File "/usr/local/lib/python3.6/site-packages/django/core/handlers/base.py", line 185, in _get_response
    response = wrapped_callback(request, *callback_args, **callback_kwargs)
  File "/Users/emirozbir/Desktop/desktop/gamer_trnet-yedek/epin/epinmain/views.py", line 47, in games
    return render_to_response("tr/oyunlar.html",{"game_data":fetch_all_game()})
  File "/Users/emirozbir/Desktop/desktop/gamer_trnet-yedek/epin/epinmain/views.py", line 35, in fetch_all_game
    games = cursor.execute("SELECT * FROM game")
  File "/usr/local/lib/python3.6/site-packages/django/db/backends/utils.py", line 80, in execute
    return super(CursorDebugWrapper, self).execute(sql, params)
  File "/usr/local/lib/python3.6/site-packages/django/db/backends/utils.py", line 65, in execute
    return self.cursor.execute(sql, params)
  File "/usr/local/lib/python3.6/site-packages/django/db/utils.py", line 94, in __exit__
    six.reraise(dj_exc_type, dj_exc_value, traceback)
  File "/usr/local/lib/python3.6/site-packages/django/utils/six.py", line 685, in reraise
    raise value.with_traceback(tb)
  File "/usr/local/lib/python3.6/site-packages/django/db/backends/utils.py", line 63, in execute
    return self.cursor.execute(sql)
django.db.utils.ProgrammingError: relation "game" does not exist
LINE 1: SELECT * FROM game
                      ^

DEBUG:root:USER emirozbir FETCHED GAMES
ERROR:django.request:Internal Server Error: /games/games/
Traceback (most recent call last):
  File "/usr/local/lib/python3.6/site-packages/django/db/backends/utils.py", line 63, in execute
    return self.cursor.execute(sql)
psycopg2.ProgrammingError: relation "game" does not exist
LINE 1: SELECT * FROM game
                      ^


The above exception was the direct cause of the following exception:

Traceback (most recent call last):
  File "/usr/local/lib/python3.6/site-packages/django/core/handlers/exception.py", line 41, in inner
    response = get_response(request)
  File "/usr/local/lib/python3.6/site-packages/django/core/handlers/base.py", line 187, in _get_response
    response = self.process_exception_by_middleware(e, request)
  File "/usr/local/lib/python3.6/site-packages/django/core/handlers/base.py", line 185, in _get_response
    response = wrapped_callback(request, *callback_args, **callback_kwargs)
  File "/Users/emirozbir/Desktop/desktop/gamer_trnet-yedek/epin/epinmain/views.py", line 47, in games
    return render_to_response("tr/oyunlar.html",{"game_data":fetch_all_game()})
  File "/Users/emirozbir/Desktop/desktop/gamer_trnet-yedek/epin/epinmain/views.py", line 35, in fetch_all_game
    games = cursor.execute("SELECT * FROM game")
  File "/usr/local/lib/python3.6/site-packages/django/db/backends/utils.py", line 80, in execute
    return super(CursorDebugWrapper, self).execute(sql, params)
  File "/usr/local/lib/python3.6/site-packages/django/db/backends/utils.py", line 65, in execute
    return self.cursor.execute(sql, params)
  File "/usr/local/lib/python3.6/site-packages/django/db/utils.py", line 94, in __exit__
    six.reraise(dj_exc_type, dj_exc_value, traceback)
  File "/usr/local/lib/python3.6/site-packages/django/utils/six.py", line 685, in reraise
    raise value.with_traceback(tb)
  File "/usr/local/lib/python3.6/site-packages/django/db/backends/utils.py", line 63, in execute
    return self.cursor.execute(sql)
django.db.utils.ProgrammingError: relation "game" does not exist
LINE 1: SELECT * FROM game
                      ^

DEBUG:root:USER emirozbir FETCHED GAMES
ERROR:django.request:Internal Server Error: /games/games/
Traceback (most recent call last):
  File "/usr/local/lib/python3.6/site-packages/django/db/backends/utils.py", line 63, in execute
    return self.cursor.execute(sql)
psycopg2.ProgrammingError: relation "game" does not exist
LINE 1: SELECT * FROM game
                      ^


The above exception was the direct cause of the following exception:

Traceback (most recent call last):
  File "/usr/local/lib/python3.6/site-packages/django/core/handlers/exception.py", line 41, in inner
    response = get_response(request)
  File "/usr/local/lib/python3.6/site-packages/django/core/handlers/base.py", line 187, in _get_response
    response = self.process_exception_by_middleware(e, request)
  File "/usr/local/lib/python3.6/site-packages/django/core/handlers/base.py", line 185, in _get_response
    response = wrapped_callback(request, *callback_args, **callback_kwargs)
  File "/Users/emirozbir/Desktop/desktop/gamer_trnet-yedek/epin/epinmain/views.py", line 47, in games
    return render_to_response("tr/oyunlar.html",{"game_data":fetch_all_game()})
  File "/Users/emirozbir/Desktop/desktop/gamer_trnet-yedek/epin/epinmain/views.py", line 35, in fetch_all_game
    games = cursor.execute("SELECT * FROM game")
  File "/usr/local/lib/python3.6/site-packages/django/db/backends/utils.py", line 80, in execute
    return super(CursorDebugWrapper, self).execute(sql, params)
  File "/usr/local/lib/python3.6/site-packages/django/db/backends/utils.py", line 65, in execute
    return self.cursor.execute(sql, params)
  File "/usr/local/lib/python3.6/site-packages/django/db/utils.py", line 94, in __exit__
    six.reraise(dj_exc_type, dj_exc_value, traceback)
  File "/usr/local/lib/python3.6/site-packages/django/utils/six.py", line 685, in reraise
    raise value.with_traceback(tb)
  File "/usr/local/lib/python3.6/site-packages/django/db/backends/utils.py", line 63, in execute
    return self.cursor.execute(sql)
django.db.utils.ProgrammingError: relation "game" does not exist
LINE 1: SELECT * FROM game
                      ^

WARNING:django.request:Not Found: /games/game/
DEBUG:root:USER emirozbir FETCHED GAMES
ERROR:django.request:Internal Server Error: /games/games/
Traceback (most recent call last):
  File "/usr/local/lib/python3.6/site-packages/django/db/backends/utils.py", line 63, in execute
    return self.cursor.execute(sql)
psycopg2.ProgrammingError: relation "game" does not exist
LINE 1: SELECT * FROM game
                      ^


The above exception was the direct cause of the following exception:

Traceback (most recent call last):
  File "/usr/local/lib/python3.6/site-packages/django/core/handlers/exception.py", line 41, in inner
    response = get_response(request)
  File "/usr/local/lib/python3.6/site-packages/django/core/handlers/base.py", line 187, in _get_response
    response = self.process_exception_by_middleware(e, request)
  File "/usr/local/lib/python3.6/site-packages/django/core/handlers/base.py", line 185, in _get_response
    response = wrapped_callback(request, *callback_args, **callback_kwargs)
  File "/Users/emirozbir/Desktop/desktop/gamer_trnet-yedek/epin/epinmain/views.py", line 47, in games
    return render_to_response("tr/oyunlar.html",{"game_data":fetch_all_game()})
  File "/Users/emirozbir/Desktop/desktop/gamer_trnet-yedek/epin/epinmain/views.py", line 35, in fetch_all_game
    games = cursor.execute("SELECT * FROM game")
  File "/usr/local/lib/python3.6/site-packages/django/db/backends/utils.py", line 80, in execute
    return super(CursorDebugWrapper, self).execute(sql, params)
  File "/usr/local/lib/python3.6/site-packages/django/db/backends/utils.py", line 65, in execute
    return self.cursor.execute(sql, params)
  File "/usr/local/lib/python3.6/site-packages/django/db/utils.py", line 94, in __exit__
    six.reraise(dj_exc_type, dj_exc_value, traceback)
  File "/usr/local/lib/python3.6/site-packages/django/utils/six.py", line 685, in reraise
    raise value.with_traceback(tb)
  File "/usr/local/lib/python3.6/site-packages/django/db/backends/utils.py", line 63, in execute
    return self.cursor.execute(sql)
django.db.utils.ProgrammingError: relation "game" does not exist
LINE 1: SELECT * FROM game
                      ^

DEBUG:root:USER emirozbir FETCHED GAMES
ERROR:django.request:Internal Server Error: /games/games/
Traceback (most recent call last):
  File "/usr/local/lib/python3.6/site-packages/django/db/backends/utils.py", line 63, in execute
    return self.cursor.execute(sql)
psycopg2.ProgrammingError: relation "game" does not exist
LINE 1: SELECT * FROM game
                      ^


The above exception was the direct cause of the following exception:

Traceback (most recent call last):
  File "/usr/local/lib/python3.6/site-packages/django/core/handlers/exception.py", line 41, in inner
    response = get_response(request)
  File "/usr/local/lib/python3.6/site-packages/django/core/handlers/base.py", line 187, in _get_response
    response = self.process_exception_by_middleware(e, request)
  File "/usr/local/lib/python3.6/site-packages/django/core/handlers/base.py", line 185, in _get_response
    response = wrapped_callback(request, *callback_args, **callback_kwargs)
  File "/Users/emirozbir/Desktop/desktop/gamer_trnet-yedek/epin/epinmain/views.py", line 51, in games
    return render_to_response("eng/games.html", {"game_data": fetch_all_game()})
  File "/Users/emirozbir/Desktop/desktop/gamer_trnet-yedek/epin/epinmain/views.py", line 35, in fetch_all_game
    games = cursor.execute("SELECT * FROM game")
  File "/usr/local/lib/python3.6/site-packages/django/db/backends/utils.py", line 80, in execute
    return super(CursorDebugWrapper, self).execute(sql, params)
  File "/usr/local/lib/python3.6/site-packages/django/db/backends/utils.py", line 65, in execute
    return self.cursor.execute(sql, params)
  File "/usr/local/lib/python3.6/site-packages/django/db/utils.py", line 94, in __exit__
    six.reraise(dj_exc_type, dj_exc_value, traceback)
  File "/usr/local/lib/python3.6/site-packages/django/utils/six.py", line 685, in reraise
    raise value.with_traceback(tb)
  File "/usr/local/lib/python3.6/site-packages/django/db/backends/utils.py", line 63, in execute
    return self.cursor.execute(sql)
django.db.utils.ProgrammingError: relation "game" does not exist
LINE 1: SELECT * FROM game
                      ^

DEBUG:root:USER emirozbir FETCHED GAMES
ERROR:django.request:Internal Server Error: /games/games/
Traceback (most recent call last):
  File "/usr/local/lib/python3.6/site-packages/django/core/handlers/exception.py", line 41, in inner
    response = get_response(request)
  File "/usr/local/lib/python3.6/site-packages/django/core/handlers/base.py", line 187, in _get_response
    response = self.process_exception_by_middleware(e, request)
  File "/usr/local/lib/python3.6/site-packages/django/core/handlers/base.py", line 185, in _get_response
    response = wrapped_callback(request, *callback_args, **callback_kwargs)
  File "/Users/emirozbir/Desktop/desktop/gamer_trnet-yedek/epin/epinmain/views.py", line 51, in games
    return render_to_response("eng/games.html", {"game_data": fetch_all_game()})
  File "/usr/local/lib/python3.6/site-packages/django/shortcuts.py", line 21, in render_to_response
    content = loader.render_to_string(template_name, context, using=using)
  File "/usr/local/lib/python3.6/site-packages/django/template/loader.py", line 68, in render_to_string
    return template.render(context, request)
  File "/usr/local/lib/python3.6/site-packages/django/template/backends/django.py", line 66, in render
    return self.template.render(context)
  File "/usr/local/lib/python3.6/site-packages/django/template/base.py", line 207, in render
    return self._render(context)
  File "/usr/local/lib/python3.6/site-packages/django/template/base.py", line 199, in _render
    return self.nodelist.render(context)
  File "/usr/local/lib/python3.6/site-packages/django/template/base.py", line 990, in render
    bit = node.render_annotated(context)
  File "/usr/local/lib/python3.6/site-packages/django/template/base.py", line 957, in render_annotated
    return self.render(context)
  File "/usr/local/lib/python3.6/site-packages/django/template/defaulttags.py", line 207, in render
    .format(num_loopvars, len_item),
ValueError: Need 2 values to unpack in for loop; got 0. 
DEBUG:root:USER emirozbir FETCHED GAMES
DEBUG:root:USER emirozbir FETCHED GAMES
DEBUG:root:USER emirozbir FETCHED GAMES
DEBUG:root:USER emirozbir FETCHED GAMES
DEBUG:root:USER emirozbir FETCHED GAMES
DEBUG:root:USER emirozbir FETCHED GAMES
DEBUG:root:USER emirozbir FETCHED GAMES
DEBUG:root:USER AnonymousUser LOGOUT 
DEBUG:root:USER emirozbir FETCHED GAMES
ERROR:django.request:Internal Server Error: /games/games/
Traceback (most recent call last):
  File "/usr/local/lib/python3.6/site-packages/django/core/handlers/exception.py", line 41, in inner
    response = get_response(request)
  File "/usr/local/lib/python3.6/site-packages/django/core/handlers/base.py", line 187, in _get_response
    response = self.process_exception_by_middleware(e, request)
  File "/usr/local/lib/python3.6/site-packages/django/core/handlers/base.py", line 185, in _get_response
    response = wrapped_callback(request, *callback_args, **callback_kwargs)
  File "/Users/emirozbir/Desktop/desktop/gamer_trnet-yedek/epin/epinmain/views.py", line 48, in games
    return render_to_response("tr/oyunlar.html",{"game_data":fetch_all_game()})
  File "/usr/local/lib/python3.6/site-packages/django/shortcuts.py", line 21, in render_to_response
    content = loader.render_to_string(template_name, context, using=using)
  File "/usr/local/lib/python3.6/site-packages/django/template/loader.py", line 68, in render_to_string
    return template.render(context, request)
  File "/usr/local/lib/python3.6/site-packages/django/template/backends/django.py", line 66, in render
    return self.template.render(context)
  File "/usr/local/lib/python3.6/site-packages/django/template/base.py", line 207, in render
    return self._render(context)
  File "/usr/local/lib/python3.6/site-packages/django/template/base.py", line 199, in _render
    return self.nodelist.render(context)
  File "/usr/local/lib/python3.6/site-packages/django/template/base.py", line 990, in render
    bit = node.render_annotated(context)
  File "/usr/local/lib/python3.6/site-packages/django/template/base.py", line 957, in render_annotated
    return self.render(context)
  File "/usr/local/lib/python3.6/site-packages/django/template/defaulttags.py", line 207, in render
    .format(num_loopvars, len_item),
ValueError: Need 2 values to unpack in for loop; got 0. 
DEBUG:root:USER emirozbir FETCHED GAMES
WARNING:django.request:Not Found: /accounts/logout
WARNING:django.request:Not Found: /accounts/login
ERROR:django.request:Internal Server Error: /accounts/search/
Traceback (most recent call last):
  File "/home/yagmursato/.local/lib/python3.5/site-packages/django/db/backends/utils.py", line 63, in execute
    return self.cursor.execute(sql)
psycopg2.ProgrammingError: column "dada" does not exist
LINE 1: Select * from game Where name ILIKE dada;
                                            ^


The above exception was the direct cause of the following exception:

Traceback (most recent call last):
  File "/home/yagmursato/.local/lib/python3.5/site-packages/django/core/handlers/exception.py", line 41, in inner
    response = get_response(request)
  File "/home/yagmursato/.local/lib/python3.5/site-packages/django/core/handlers/base.py", line 187, in _get_response
    response = self.process_exception_by_middleware(e, request)
  File "/home/yagmursato/.local/lib/python3.5/site-packages/django/core/handlers/base.py", line 185, in _get_response
    response = wrapped_callback(request, *callback_args, **callback_kwargs)
  File "/home/yagmursato/gamer_trnet/epin/epinmain/views.py", line 143, in search
    find=cursor.execute("Select * from game Where name ILIKE "+searching_word+";")
  File "/home/yagmursato/.local/lib/python3.5/site-packages/django/db/backends/utils.py", line 80, in execute
    return super(CursorDebugWrapper, self).execute(sql, params)
  File "/home/yagmursato/.local/lib/python3.5/site-packages/django/db/backends/utils.py", line 65, in execute
    return self.cursor.execute(sql, params)
  File "/home/yagmursato/.local/lib/python3.5/site-packages/django/db/utils.py", line 94, in __exit__
    six.reraise(dj_exc_type, dj_exc_value, traceback)
  File "/home/yagmursato/.local/lib/python3.5/site-packages/django/utils/six.py", line 685, in reraise
    raise value.with_traceback(tb)
  File "/home/yagmursato/.local/lib/python3.5/site-packages/django/db/backends/utils.py", line 63, in execute
    return self.cursor.execute(sql)
django.db.utils.ProgrammingError: column "dada" does not exist
LINE 1: Select * from game Where name ILIKE dada;
                                            ^

ERROR:django.request:Internal Server Error: /accounts/search/
Traceback (most recent call last):
  File "/home/yagmursato/.local/lib/python3.5/site-packages/django/core/handlers/exception.py", line 41, in inner
    response = get_response(request)
  File "/home/yagmursato/.local/lib/python3.5/site-packages/django/core/handlers/base.py", line 187, in _get_response
    response = self.process_exception_by_middleware(e, request)
  File "/home/yagmursato/.local/lib/python3.5/site-packages/django/core/handlers/base.py", line 185, in _get_response
    response = wrapped_callback(request, *callback_args, **callback_kwargs)
  File "/home/yagmursato/gamer_trnet/epin/epinmain/views.py", line 145, in search
    return render(request, "search.html", {"Search":find})
  File "/home/yagmursato/.local/lib/python3.5/site-packages/django/shortcuts.py", line 30, in render
    content = loader.render_to_string(template_name, context, request, using=using)
  File "/home/yagmursato/.local/lib/python3.5/site-packages/django/template/loader.py", line 67, in render_to_string
    template = get_template(template_name, using=using)
  File "/home/yagmursato/.local/lib/python3.5/site-packages/django/template/loader.py", line 25, in get_template
    raise TemplateDoesNotExist(template_name, chain=chain)
django.template.exceptions.TemplateDoesNotExist: search.html
ERROR:django.request:Internal Server Error: /accounts/auth/
Traceback (most recent call last):
  File "/home/yagmursato/.local/lib/python3.5/site-packages/django/db/backends/utils.py", line 65, in execute
    return self.cursor.execute(sql, params)
psycopg2.ProgrammingError: permission denied for relation auth_user


The above exception was the direct cause of the following exception:

Traceback (most recent call last):
  File "/home/yagmursato/.local/lib/python3.5/site-packages/django/core/handlers/exception.py", line 41, in inner
    response = get_response(request)
  File "/home/yagmursato/.local/lib/python3.5/site-packages/django/core/handlers/base.py", line 187, in _get_response
    response = self.process_exception_by_middleware(e, request)
  File "/home/yagmursato/.local/lib/python3.5/site-packages/django/core/handlers/base.py", line 185, in _get_response
    response = wrapped_callback(request, *callback_args, **callback_kwargs)
  File "/home/yagmursato/gamer_trnet/epin/epinmain/views.py", line 79, in auth_detection
    user = auth.authenticate(username=username,password=password)
  File "/home/yagmursato/.local/lib/python3.5/site-packages/django/contrib/auth/__init__.py", line 70, in authenticate
    user = _authenticate_with_backend(backend, backend_path, request, credentials)
  File "/home/yagmursato/.local/lib/python3.5/site-packages/django/contrib/auth/__init__.py", line 115, in _authenticate_with_backend
    return backend.authenticate(*args, **credentials)
  File "/home/yagmursato/.local/lib/python3.5/site-packages/django/contrib/auth/backends.py", line 18, in authenticate
    user = UserModel._default_manager.get_by_natural_key(username)
  File "/home/yagmursato/.local/lib/python3.5/site-packages/django/contrib/auth/base_user.py", line 48, in get_by_natural_key
    return self.get(**{self.model.USERNAME_FIELD: username})
  File "/home/yagmursato/.local/lib/python3.5/site-packages/django/db/models/manager.py", line 85, in manager_method
    return getattr(self.get_queryset(), name)(*args, **kwargs)
  File "/home/yagmursato/.local/lib/python3.5/site-packages/django/db/models/query.py", line 374, in get
    num = len(clone)
  File "/home/yagmursato/.local/lib/python3.5/site-packages/django/db/models/query.py", line 232, in __len__
    self._fetch_all()
  File "/home/yagmursato/.local/lib/python3.5/site-packages/django/db/models/query.py", line 1118, in _fetch_all
    self._result_cache = list(self._iterable_class(self))
  File "/home/yagmursato/.local/lib/python3.5/site-packages/django/db/models/query.py", line 53, in __iter__
    results = compiler.execute_sql(chunked_fetch=self.chunked_fetch)
  File "/home/yagmursato/.local/lib/python3.5/site-packages/django/db/models/sql/compiler.py", line 886, in execute_sql
    raise original_exception
  File "/home/yagmursato/.local/lib/python3.5/site-packages/django/db/models/sql/compiler.py", line 876, in execute_sql
    cursor.execute(sql, params)
  File "/home/yagmursato/.local/lib/python3.5/site-packages/django/db/backends/utils.py", line 80, in execute
    return super(CursorDebugWrapper, self).execute(sql, params)
  File "/home/yagmursato/.local/lib/python3.5/site-packages/django/db/backends/utils.py", line 65, in execute
    return self.cursor.execute(sql, params)
  File "/home/yagmursato/.local/lib/python3.5/site-packages/django/db/utils.py", line 94, in __exit__
    six.reraise(dj_exc_type, dj_exc_value, traceback)
  File "/home/yagmursato/.local/lib/python3.5/site-packages/django/utils/six.py", line 685, in reraise
    raise value.with_traceback(tb)
  File "/home/yagmursato/.local/lib/python3.5/site-packages/django/db/backends/utils.py", line 65, in execute
    return self.cursor.execute(sql, params)
django.db.utils.ProgrammingError: permission denied for relation auth_user

ERROR:django.request:Internal Server Error: /accounts/auth/
Traceback (most recent call last):
  File "/home/yagmursato/.local/lib/python3.5/site-packages/django/db/backends/utils.py", line 65, in execute
    return self.cursor.execute(sql, params)
psycopg2.ProgrammingError: permission denied for relation auth_user


The above exception was the direct cause of the following exception:

Traceback (most recent call last):
  File "/home/yagmursato/.local/lib/python3.5/site-packages/django/core/handlers/exception.py", line 41, in inner
    response = get_response(request)
  File "/home/yagmursato/.local/lib/python3.5/site-packages/django/core/handlers/base.py", line 187, in _get_response
    response = self.process_exception_by_middleware(e, request)
  File "/home/yagmursato/.local/lib/python3.5/site-packages/django/core/handlers/base.py", line 185, in _get_response
    response = wrapped_callback(request, *callback_args, **callback_kwargs)
  File "/home/yagmursato/gamer_trnet/epin/epinmain/views.py", line 79, in auth_detection
    user = auth.authenticate(username=username,password=password)
  File "/home/yagmursato/.local/lib/python3.5/site-packages/django/contrib/auth/__init__.py", line 70, in authenticate
    user = _authenticate_with_backend(backend, backend_path, request, credentials)
  File "/home/yagmursato/.local/lib/python3.5/site-packages/django/contrib/auth/__init__.py", line 115, in _authenticate_with_backend
    return backend.authenticate(*args, **credentials)
  File "/home/yagmursato/.local/lib/python3.5/site-packages/django/contrib/auth/backends.py", line 18, in authenticate
    user = UserModel._default_manager.get_by_natural_key(username)
  File "/home/yagmursato/.local/lib/python3.5/site-packages/django/contrib/auth/base_user.py", line 48, in get_by_natural_key
    return self.get(**{self.model.USERNAME_FIELD: username})
  File "/home/yagmursato/.local/lib/python3.5/site-packages/django/db/models/manager.py", line 85, in manager_method
    return getattr(self.get_queryset(), name)(*args, **kwargs)
  File "/home/yagmursato/.local/lib/python3.5/site-packages/django/db/models/query.py", line 374, in get
    num = len(clone)
  File "/home/yagmursato/.local/lib/python3.5/site-packages/django/db/models/query.py", line 232, in __len__
    self._fetch_all()
  File "/home/yagmursato/.local/lib/python3.5/site-packages/django/db/models/query.py", line 1118, in _fetch_all
    self._result_cache = list(self._iterable_class(self))
  File "/home/yagmursato/.local/lib/python3.5/site-packages/django/db/models/query.py", line 53, in __iter__
    results = compiler.execute_sql(chunked_fetch=self.chunked_fetch)
  File "/home/yagmursato/.local/lib/python3.5/site-packages/django/db/models/sql/compiler.py", line 886, in execute_sql
    raise original_exception
  File "/home/yagmursato/.local/lib/python3.5/site-packages/django/db/models/sql/compiler.py", line 876, in execute_sql
    cursor.execute(sql, params)
  File "/home/yagmursato/.local/lib/python3.5/site-packages/django/db/backends/utils.py", line 80, in execute
    return super(CursorDebugWrapper, self).execute(sql, params)
  File "/home/yagmursato/.local/lib/python3.5/site-packages/django/db/backends/utils.py", line 65, in execute
    return self.cursor.execute(sql, params)
  File "/home/yagmursato/.local/lib/python3.5/site-packages/django/db/utils.py", line 94, in __exit__
    six.reraise(dj_exc_type, dj_exc_value, traceback)
  File "/home/yagmursato/.local/lib/python3.5/site-packages/django/utils/six.py", line 685, in reraise
    raise value.with_traceback(tb)
  File "/home/yagmursato/.local/lib/python3.5/site-packages/django/db/backends/utils.py", line 65, in execute
    return self.cursor.execute(sql, params)
django.db.utils.ProgrammingError: permission denied for relation auth_user

